<?xml version="1.0" ?>
<robot name="mycobot320_4_4" xmlns:xacro="http://www.ros.org/wiki/xacro">

<xacro:include filename="$(find mycobot320_4_4_description)/urdf/materials.xacro" />
<xacro:include filename="$(find mycobot320_4_4_description)/urdf/mycobot320_4_4.trans" />
<xacro:include filename="$(find mycobot320_4_4_description)/urdf/mycobot320_4_4.gazebo" />
<link name="base_link">
  <inertial>
    <origin xyz="-1.3994637957346424e-08 0.046320428630226694 0.053625500753973876" rpy="0 0 0"/>
    <mass value="12.899764355948896"/>
    <inertia ixx="0.033823" iyy="0.028162" izz="0.035033" ixy="0.0" iyz="-0.000755" ixz="0.0"/>
  </inertial>
  <visual>
    <origin xyz="0 0 0" rpy="0 0 0"/>
    <geometry>
      <mesh filename="file://$(find mycobot320_4_4_description)/meshes/base_link.stl" scale="0.001 0.001 0.001"/>
    </geometry>
    <material name="silver"/>
  </visual>
  <collision>
    <origin xyz="0 0 0" rpy="0 0 0"/>
    <geometry>
      <mesh filename="file://$(find mycobot320_4_4_description)/meshes/base_link.stl" scale="0.001 0.001 0.001"/>
    </geometry>
  </collision>
</link>

<link name="link1_1">
  <inertial>
    <origin xyz="0.006894482331010262 0.00017712892998957702 0.055490142550686156" rpy="0 0 0"/>
    <mass value="3.4735206294395446"/>
    <inertia ixx="0.004461" iyy="0.004757" izz="0.002424" ixy="-8e-06" iyz="-2e-05" ixz="-0.000777"/>
  </inertial>
  <visual>
    <origin xyz="0.0 -0.060072 -0.114761" rpy="0 0 0"/>
    <geometry>
      <mesh filename="file://$(find mycobot320_4_4_description)/meshes/link1_1.stl" scale="0.001 0.001 0.001"/>
    </geometry>
    <material name="silver"/>
  </visual>
  <collision>
    <origin xyz="0.0 -0.060072 -0.114761" rpy="0 0 0"/>
    <geometry>
      <mesh filename="file://$(find mycobot320_4_4_description)/meshes/link1_1.stl" scale="0.001 0.001 0.001"/>
    </geometry>
  </collision>
</link>

<link name="link2_1">
  <inertial>
    <origin xyz="0.036837500623841266 0.00316217625421885 0.06796391862996645" rpy="0 0 0"/>
    <mass value="5.91988968680626"/>
    <inertia ixx="0.0188" iyy="0.019319" izz="0.004177" ixy="-1.3e-05" iyz="-0.000494" ixz="1.3e-05"/>
  </inertial>
  <visual>
    <origin xyz="-0.044985 -0.06123 -0.199761" rpy="0 0 0"/>
    <geometry>
      <mesh filename="file://$(find mycobot320_4_4_description)/meshes/link2_1.stl" scale="0.001 0.001 0.001"/>
    </geometry>
    <material name="silver"/>
  </visual>
  <collision>
    <origin xyz="-0.044985 -0.06123 -0.199761" rpy="0 0 0"/>
    <geometry>
      <mesh filename="file://$(find mycobot320_4_4_description)/meshes/link2_1.stl" scale="0.001 0.001 0.001"/>
    </geometry>
  </collision>
</link>

<link name="link3_1">
  <inertial>
    <origin xyz="-0.035053164367318285 0.0007402802945343234 0.04947264616599745" rpy="0 0 0"/>
    <mass value="4.802107093668197"/>
    <inertia ixx="0.01014" iyy="0.010576" izz="0.003394" ixy="-1.1e-05" iyz="-0.000239" ixz="6e-06"/>
  </inertial>
  <visual>
    <origin xyz="-0.044871 -0.065655 -0.335689" rpy="0 0 0"/>
    <geometry>
      <mesh filename="file://$(find mycobot320_4_4_description)/meshes/link3_1.stl" scale="0.001 0.001 0.001"/>
    </geometry>
    <material name="silver"/>
  </visual>
  <collision>
    <origin xyz="-0.044871 -0.065655 -0.335689" rpy="0 0 0"/>
    <geometry>
      <mesh filename="file://$(find mycobot320_4_4_description)/meshes/link3_1.stl" scale="0.001 0.001 0.001"/>
    </geometry>
  </collision>
</link>

<link name="link4_1">
  <inertial>
    <origin xyz="0.03443819780244397 -0.00012625243718576706 0.010527987134175576" rpy="0 0 0"/>
    <mass value="2.265107015236222"/>
    <inertia ixx="0.001594" iyy="0.001803" izz="0.001597" ixy="2.6e-05" iyz="1.2e-05" ixz="-0.000322"/>
  </inertial>
  <visual>
    <origin xyz="-0.044787 -0.068938 -0.434634" rpy="0 0 0"/>
    <geometry>
      <mesh filename="file://$(find mycobot320_4_4_description)/meshes/link4_1.stl" scale="0.001 0.001 0.001"/>
    </geometry>
    <material name="silver"/>
  </visual>
  <collision>
    <origin xyz="-0.044787 -0.068938 -0.434634" rpy="0 0 0"/>
    <geometry>
      <mesh filename="file://$(find mycobot320_4_4_description)/meshes/link4_1.stl" scale="0.001 0.001 0.001"/>
    </geometry>
  </collision>
</link>

<link name="link5_1">
  <inertial>
    <origin xyz="0.00010333354821902285 -0.004029254098592533 0.04192318950838286" rpy="0 0 0"/>
    <mass value="3.029827579494103"/>
    <inertia ixx="0.0025" iyy="0.002971" izz="0.002446" ixy="0.0" iyz="5.1e-05" ixz="-0.0"/>
  </inertial>
  <visual>
    <origin xyz="-0.089883 -0.06579 -0.479428" rpy="0 0 0"/>
    <geometry>
      <mesh filename="file://$(find mycobot320_4_4_description)/meshes/link5_1.stl" scale="0.001 0.001 0.001"/>
    </geometry>
    <material name="silver"/>
  </visual>
  <collision>
    <origin xyz="-0.089883 -0.06579 -0.479428" rpy="0 0 0"/>
    <geometry>
      <mesh filename="file://$(find mycobot320_4_4_description)/meshes/link5_1.stl" scale="0.001 0.001 0.001"/>
    </geometry>
  </collision>
</link>

<link name="link6_1">
  <inertial>
    <origin xyz="0.00999958715963864 -3.8937722489085225e-06 -2.536791209295508e-05" rpy="0 0 0"/>
    <mass value="0.6042068071016569"/>
    <inertia ixx="0.00037" iyy="0.000205" izz="0.000205" ixy="-0.0" iyz="0.0" ixz="-0.0"/>
  </inertial>
  <visual>
    <origin xyz="-0.130006 -0.06099 -0.529098" rpy="0 0 0"/>
    <geometry>
      <mesh filename="file://$(find mycobot320_4_4_description)/meshes/link6_1.stl" scale="0.001 0.001 0.001"/>
    </geometry>
    <material name="silver"/>
  </visual>
  <collision>
    <origin xyz="-0.130006 -0.06099 -0.529098" rpy="0 0 0"/>
    <geometry>
      <mesh filename="file://$(find mycobot320_4_4_description)/meshes/link6_1.stl" scale="0.001 0.001 0.001"/>
    </geometry>
  </collision>
</link>

<link name="gripper_base_1">
  <inertial>
    <origin xyz="0.04130515061115911 0.010013488596629185 -4.428984489124321e-05" rpy="0 0 0"/>
    <mass value="1.169410692896674"/>
    <inertia ixx="0.000963" iyy="0.001227" izz="0.000961" ixy="-6.1e-05" iyz="0.0" ixz="1e-06"/>
  </inertial>
  <visual>
    <origin xyz="-0.150006 -0.060982 -0.529047" rpy="0 0 0"/>
    <geometry>
      <mesh filename="file://$(find mycobot320_4_4_description)/meshes/gripper_base_1.stl" scale="0.001 0.001 0.001"/>
    </geometry>
    <material name="silver"/>
  </visual>
  <collision>
    <origin xyz="-0.150006 -0.060982 -0.529047" rpy="0 0 0"/>
    <geometry>
      <mesh filename="file://$(find mycobot320_4_4_description)/meshes/gripper_base_1.stl" scale="0.001 0.001 0.001"/>
    </geometry>
  </collision>
</link>

<link name="gripper_right3_1">
  <inertial>
    <origin xyz="0.019897445301458705 0.003328334846588371 -0.0008618172580169281" rpy="0 0 0"/>
    <mass value="0.08843428994279921"/>
    <inertia ixx="7e-06" iyy="4.8e-05" izz="4.2e-05" ixy="0.0" iyz="-0.0" ixz="6e-06"/>
  </inertial>
  <visual>
    <origin xyz="-0.210547 -0.050521 -0.547218" rpy="0 0 0"/>
    <geometry>
      <mesh filename="file://$(find mycobot320_4_4_description)/meshes/gripper_right3_1.stl" scale="0.001 0.001 0.001"/>
    </geometry>
    <material name="silver"/>
  </visual>
  <collision>
    <origin xyz="-0.210547 -0.050521 -0.547218" rpy="0 0 0"/>
    <geometry>
      <mesh filename="file://$(find mycobot320_4_4_description)/meshes/gripper_right3_1.stl" scale="0.001 0.001 0.001"/>
    </geometry>
  </collision>
</link>

<link name="gripper_right1_1">
  <inertial>
    <origin xyz="0.011640592022952256 0.003586474602388895 0.005141940843472637" rpy="0 0 0"/>
    <mass value="0.09086983402456465"/>
    <inertia ixx="1e-05" iyy="4e-05" izz="3.3e-05" ixy="-0.0" iyz="0.0" ixz="1.2e-05"/>
  </inertial>
  <visual>
    <origin xyz="-0.269552 -0.050353 -0.537954" rpy="0 0 0"/>
    <geometry>
      <mesh filename="file://$(find mycobot320_4_4_description)/meshes/gripper_right1_1.stl" scale="0.001 0.001 0.001"/>
    </geometry>
    <material name="silver"/>
  </visual>
  <collision>
    <origin xyz="-0.269552 -0.050353 -0.537954" rpy="0 0 0"/>
    <geometry>
      <mesh filename="file://$(find mycobot320_4_4_description)/meshes/gripper_right1_1.stl" scale="0.001 0.001 0.001"/>
    </geometry>
  </collision>
</link>

<link name="gripper_right2_1">
  <inertial>
    <origin xyz="0.03925299992062914 -0.00016291284697944608 -0.004528228586364702" rpy="0 0 0"/>
    <mass value="0.056773956967290366"/>
    <inertia ixx="3e-06" iyy="2e-05" izz="1.9e-05" ixy="2e-06" iyz="-0.0" ixz="4e-06"/>
  </inertial>
  <visual>
    <origin xyz="-0.188253 -0.063338 -0.573343" rpy="0 0 0"/>
    <geometry>
      <mesh filename="file://$(find mycobot320_4_4_description)/meshes/gripper_right2_1.stl" scale="0.001 0.001 0.001"/>
    </geometry>
    <material name="silver"/>
  </visual>
  <collision>
    <origin xyz="-0.188253 -0.063338 -0.573343" rpy="0 0 0"/>
    <geometry>
      <mesh filename="file://$(find mycobot320_4_4_description)/meshes/gripper_right2_1.stl" scale="0.001 0.001 0.001"/>
    </geometry>
  </collision>
</link>

<link name="gripper_left3_1">
  <inertial>
    <origin xyz="0.019874922365214237 0.0032052020362376143 0.0010863693067071356" rpy="0 0 0"/>
    <mass value="0.08829596207620959"/>
    <inertia ixx="7e-06" iyy="4.8e-05" izz="4.2e-05" ixy="-0.0" iyz="-0.0" ixz="-6e-06"/>
  </inertial>
  <visual>
    <origin xyz="-0.210455 -0.05051 -0.510579" rpy="0 0 0"/>
    <geometry>
      <mesh filename="file://$(find mycobot320_4_4_description)/meshes/gripper_left3_1.stl" scale="0.001 0.001 0.001"/>
    </geometry>
    <material name="silver"/>
  </visual>
  <collision>
    <origin xyz="-0.210455 -0.05051 -0.510579" rpy="0 0 0"/>
    <geometry>
      <mesh filename="file://$(find mycobot320_4_4_description)/meshes/gripper_left3_1.stl" scale="0.001 0.001 0.001"/>
    </geometry>
  </collision>
</link>

<link name="gripper_left1_1">
  <inertial>
    <origin xyz="0.011318703873776703 -0.00011099534135503714 -0.005362441033911036" rpy="0 0 0"/>
    <mass value="0.09176098538318564"/>
    <inertia ixx="1e-05" iyy="4.1e-05" izz="3.4e-05" ixy="0.0" iyz="0.0" ixz="-1.3e-05"/>
  </inertial>
  <visual>
    <origin xyz="-0.269342 -0.05398 -0.520575" rpy="0 0 0"/>
    <geometry>
      <mesh filename="file://$(find mycobot320_4_4_description)/meshes/gripper_left1_1.stl" scale="0.001 0.001 0.001"/>
    </geometry>
    <material name="silver"/>
  </visual>
  <collision>
    <origin xyz="-0.269342 -0.05398 -0.520575" rpy="0 0 0"/>
    <geometry>
      <mesh filename="file://$(find mycobot320_4_4_description)/meshes/gripper_left1_1.stl" scale="0.001 0.001 0.001"/>
    </geometry>
  </collision>
</link>

<link name="gripper_left2_1">
  <inertial>
    <origin xyz="0.0393560688408493 -0.002016390424043224 0.004164600103849281" rpy="0 0 0"/>
    <mass value="0.05599028709000548"/>
    <inertia ixx="3e-06" iyy="2e-05" izz="1.9e-05" ixy="2e-06" iyz="0.0" ixz="-4e-06"/>
  </inertial>
  <visual>
    <origin xyz="-0.18803 -0.065811 -0.484558" rpy="0 0 0"/>
    <geometry>
      <mesh filename="file://$(find mycobot320_4_4_description)/meshes/gripper_left2_1.stl" scale="0.001 0.001 0.001"/>
    </geometry>
    <material name="silver"/>
  </visual>
  <collision>
    <origin xyz="-0.18803 -0.065811 -0.484558" rpy="0 0 0"/>
    <geometry>
      <mesh filename="file://$(find mycobot320_4_4_description)/meshes/gripper_left2_1.stl" scale="0.001 0.001 0.001"/>
    </geometry>
  </collision>
</link>

<joint name="joint2_to_joint1" type="continuous">
  <origin xyz="0.0 0.060072 0.114761" rpy="0 0 0"/>
  <parent link="base_link"/>
  <child link="link1_1"/>
  <axis xyz="-0.0 0.0 1.0"/>
</joint>

<joint name="joint3_to_joint2" type="continuous">
  <origin xyz="0.044985 0.001158 0.085" rpy="0 0 0"/>
  <parent link="link1_1"/>
  <child link="link2_1"/>
  <axis xyz="0.999669 0.025733 0.0"/>
</joint>

<joint name="joint4_to_joint3" type="continuous">
  <origin xyz="-0.000114 0.004425 0.135928" rpy="0 0 0"/>
  <parent link="link2_1"/>
  <child link="link3_1"/>
  <axis xyz="-0.999669 -0.025733 0.0"/>
</joint>

<joint name="joint5_to_joint4" type="continuous">
  <origin xyz="-8.4e-05 0.003283 0.098945" rpy="0 0 0"/>
  <parent link="link3_1"/>
  <child link="link4_1"/>
  <axis xyz="0.999669 0.025733 0.0"/>
</joint>

<joint name="joint6_to_joint5" type="continuous">
  <origin xyz="0.045096 -0.003148 0.044794" rpy="0 0 0"/>
  <parent link="link4_1"/>
  <child link="link5_1"/>
  <axis xyz="0.002463 -0.095677 0.995409"/>
</joint>

<joint name="joint6output_to_joint6" type="continuous">
  <origin xyz="0.040123 -0.0048 0.04967" rpy="0 0 0"/>
  <parent link="link5_1"/>
  <child link="link6_1"/>
  <axis xyz="0.999997 -0.000408 -0.002513"/>
</joint>

<joint name="joint6output_to_gripper_base" type="fixed">
  <origin xyz="0.02 -8e-06 -5.1e-05" rpy="0 0 0"/>
  <parent link="link6_1"/>
  <child link="gripper_base_1"/>
</joint>

<joint name="gripper_controller" type="revolute">
  <origin xyz="0.060541 -0.010461 0.018171" rpy="0 0 0"/>
  <parent link="gripper_base_1"/>
  <child link="gripper_right3_1"/>
  <axis xyz="-0.000407 -1.0 0.000299"/>
  <limit upper="0.698132" lower="0.0" effort="100" velocity="100"/>
</joint>

<joint name="gripper_right3_to_gripper_right1" type="revolute">
  <origin xyz="0.059005 -0.000168 -0.009264" rpy="0 0 0"/>
  <parent link="gripper_right3_1"/>
  <child link="gripper_right1_1"/>
  <axis xyz="-0.000407 -1.0 0.000299"/>
  <limit upper="0.261799" lower="-0.698132" effort="100" velocity="100"/>
</joint>

<joint name="gripper_base_to_gripper_right2" type="revolute">
  <origin xyz="0.038247 0.002356 0.044296" rpy="0 0 0"/>
  <parent link="gripper_base_1"/>
  <child link="gripper_right2_1"/>
  <axis xyz="0.000407 1.0 -0.000299"/>
  <limit upper="0.0" lower="-0.698132" effort="100" velocity="100"/>
</joint>

<joint name="gripper_base_to_gripper_left3" type="revolute">
  <origin xyz="0.060449 -0.010472 -0.018468" rpy="0 0 0"/>
  <parent link="gripper_base_1"/>
  <child link="gripper_left3_1"/>
  <axis xyz="-0.000407 -1.0 0.000299"/>
  <limit upper="0.0" lower="-0.698132" effort="100" velocity="100"/>
</joint>

<joint name="gripper_left3_to_gripper_left1" type="revolute">
  <origin xyz="0.058887 0.00347 0.009996" rpy="0 0 0"/>
  <parent link="gripper_left3_1"/>
  <child link="gripper_left1_1"/>
  <axis xyz="0.000407 1.0 -0.000299"/>
  <limit upper="0.0" lower="-0.698132" effort="100" velocity="100"/>
</joint>

<joint name="gripper_base_to_gripper_left2" type="revolute">
  <origin xyz="0.038024 0.004829 -0.044489" rpy="0 0 0"/>
  <parent link="gripper_base_1"/>
  <child link="gripper_left2_1"/>
  <axis xyz="-0.000407 -1.0 0.000299"/>
  <limit upper="0.0" lower="-0.698132" effort="100" velocity="100"/>
</joint>

</robot>
