<?xml version="1.0" ?>
<robot name="moiro" xmlns:xacro="http://www.ros.org/wiki/xacro">

<xacro:include filename="$(find moiro_description)/urdf/materials.xacro" />
<xacro:include filename="$(find moiro_description)/urdf/moiro.trans" />
<xacro:include filename="$(find moiro_description)/urdf/moiro.gazebo" />
<link name="base_link">
  <inertial>
    <origin xyz="0.005355263561054088 -0.0009743746798552673 0.2595502059875776" rpy="0 0 0"/>
    <mass value="9.51274328475089"/>
    <inertia ixx="0.485755" iyy="0.519524" izz="0.426856" ixy="0.002055" iyz="0.002374" ixz="-0.012946"/>
  </inertial>
  <visual>
    <origin xyz="0 0 0" rpy="0 0 0"/>
    <geometry>
      <mesh filename="file://$(find moiro_description)/meshes/base_link.stl" scale="0.001 0.001 0.001"/>
    </geometry>
    <material name="silver"/>
  </visual>
  <collision>
    <origin xyz="0 0 0" rpy="0 0 0"/>
    <geometry>
      <mesh filename="file://$(find moiro_description)/meshes/base_link.stl" scale="0.001 0.001 0.001"/>
    </geometry>
  </collision>
</link>

<link name="basearm">
  <inertial>
    <origin xyz="0.006896766224728663 -2.0858239854097905e-15 0.05549018686904683" rpy="0 0 0"/>
    <mass value="3.4735206294395446"/>
    <inertia ixx="0.004461" iyy="0.004757" izz="0.002424" ixy="0.0" iyz="0.0" ixz="-0.000777"/>
  </inertial>
  <visual>
    <origin xyz="0.0 0.0 -0.609" rpy="0 0 0"/>
    <geometry>
      <mesh filename="file://$(find moiro_description)/meshes/basearm.stl" scale="0.001 0.001 0.001"/>
    </geometry>
    <material name="silver"/>
  </visual>
  <collision>
    <origin xyz="0.0 0.0 -0.609" rpy="0 0 0"/>
    <geometry>
      <mesh filename="file://$(find moiro_description)/meshes/basearm.stl" scale="0.001 0.001 0.001"/>
    </geometry>
  </collision>
</link>

<link name="lowerarm">
  <inertial>
    <origin xyz="0.036906585755669324 -2.1012286881994426e-15 0.06799999999999129" rpy="0 0 0"/>
    <mass value="5.91988968680626"/>
    <inertia ixx="0.0188" iyy="0.019335" izz="0.004161" ixy="-0.0" iyz="0.0" ixz="0.0"/>
  </inertial>
  <visual>
    <origin xyz="-0.045 0.0 -0.694" rpy="0 0 0"/>
    <geometry>
      <mesh filename="file://$(find moiro_description)/meshes/lowerarm.stl" scale="0.001 0.001 0.001"/>
    </geometry>
    <material name="silver"/>
  </visual>
  <collision>
    <origin xyz="-0.045 0.0 -0.694" rpy="0 0 0"/>
    <geometry>
      <mesh filename="file://$(find moiro_description)/meshes/lowerarm.stl" scale="0.001 0.001 0.001"/>
    </geometry>
  </collision>
</link>

<link name="upperarm">
  <inertial>
    <origin xyz="-0.03502268825299596 1.5066088373264134e-15 0.04949999999999122" rpy="0 0 0"/>
    <mass value="4.802107093668197"/>
    <inertia ixx="0.01014" iyy="0.010584" izz="0.003386" ixy="-0.0" iyz="-0.0" ixz="0.0"/>
  </inertial>
  <visual>
    <origin xyz="-0.045 0.0 -0.83" rpy="0 0 0"/>
    <geometry>
      <mesh filename="file://$(find moiro_description)/meshes/upperarm.stl" scale="0.001 0.001 0.001"/>
    </geometry>
    <material name="silver"/>
  </visual>
  <collision>
    <origin xyz="-0.045 0.0 -0.83" rpy="0 0 0"/>
    <geometry>
      <mesh filename="file://$(find moiro_description)/meshes/upperarm.stl" scale="0.001 0.001 0.001"/>
    </geometry>
  </collision>
</link>

<link name="pitcharm">
  <inertial>
    <origin xyz="0.034423872869188424 5.2920035523095135e-15 0.010576127130799362" rpy="0 0 0"/>
    <mass value="2.265107015236222"/>
    <inertia ixx="0.001595" iyy="0.001803" izz="0.001595" ixy="-0.0" iyz="-0.0" ixz="-0.000324"/>
  </inertial>
  <visual>
    <origin xyz="-0.045 -0.0 -0.929" rpy="0 0 0"/>
    <geometry>
      <mesh filename="file://$(find moiro_description)/meshes/pitcharm.stl" scale="0.001 0.001 0.001"/>
    </geometry>
    <material name="silver"/>
  </visual>
  <collision>
    <origin xyz="-0.045 -0.0 -0.929" rpy="0 0 0"/>
    <geometry>
      <mesh filename="file://$(find moiro_description)/meshes/pitcharm.stl" scale="0.001 0.001 0.001"/>
    </geometry>
  </collision>
</link>

<link name="rollarm">
  <inertial>
    <origin xyz="-3.802513859341161e-15 6.3512715451656364e-15 0.042116696506125484" rpy="0 0 0"/>
    <mass value="3.029827579494103"/>
    <inertia ixx="0.0025" iyy="0.002976" izz="0.002441" ixy="-0.0" iyz="-0.0" ixz="0.0"/>
  </inertial>
  <visual>
    <origin xyz="-0.09 -0.0 -0.974" rpy="0 0 0"/>
    <geometry>
      <mesh filename="file://$(find moiro_description)/meshes/rollarm.stl" scale="0.001 0.001 0.001"/>
    </geometry>
    <material name="silver"/>
  </visual>
  <collision>
    <origin xyz="-0.09 -0.0 -0.974" rpy="0 0 0"/>
    <geometry>
      <mesh filename="file://$(find moiro_description)/meshes/rollarm.stl" scale="0.001 0.001 0.001"/>
    </geometry>
  </collision>
</link>

<link name="gripperarm">
  <inertial>
    <origin xyz="0.00999999999999615 6.341593916658894e-15 -9.103828801926284e-15" rpy="0 0 0"/>
    <mass value="0.6042068071016569"/>
    <inertia ixx="0.00037" iyy="0.000205" izz="0.000205" ixy="-0.0" iyz="0.0" ixz="-0.0"/>
  </inertial>
  <visual>
    <origin xyz="-0.13 -0.0 -1.024" rpy="0 0 0"/>
    <geometry>
      <mesh filename="file://$(find moiro_description)/meshes/gripperarm.stl" scale="0.001 0.001 0.001"/>
    </geometry>
    <material name="silver"/>
  </visual>
  <collision>
    <origin xyz="-0.13 -0.0 -1.024" rpy="0 0 0"/>
    <geometry>
      <mesh filename="file://$(find moiro_description)/meshes/gripperarm.stl" scale="0.001 0.001 0.001"/>
    </geometry>
  </collision>
</link>

<link name="cobot_camera">
  <inertial>
    <origin xyz="0.004999999999996174 6.363947604904578e-15 0.023457816688226885" rpy="0 0 0"/>
    <mass value="0.07891648050356126"/>
    <inertia ixx="0.000101" iyy="7.2e-05" izz="3.1e-05" ixy="-0.0" iyz="-0.0" ixz="0.0"/>
  </inertial>
  <visual>
    <origin xyz="-0.15 -0.0 -1.024" rpy="0 0 0"/>
    <geometry>
      <mesh filename="file://$(find moiro_description)/meshes/cobot_camera.stl" scale="0.001 0.001 0.001"/>
    </geometry>
    <material name="silver"/>
  </visual>
  <collision>
    <origin xyz="-0.15 -0.0 -1.024" rpy="0 0 0"/>
    <geometry>
      <mesh filename="file://$(find moiro_description)/meshes/cobot_camera.stl" scale="0.001 0.001 0.001"/>
    </geometry>
  </collision>
</link>

<link name="gripper_base">
  <inertial>
    <origin xyz="0.035566484314994956 -0.00017560554919991735 0.008326821944580676" rpy="0 0 0"/>
    <mass value="0.0772232533904796"/>
    <inertia ixx="7.1e-05" iyy="6.9e-05" izz="9.8e-05" ixy="0.0" iyz="0.0" ixz="-1.5e-05"/>
  </inertial>
  <visual>
    <origin xyz="-0.16 -0.0 -1.024" rpy="0 0 0"/>
    <geometry>
      <mesh filename="file://$(find moiro_description)/meshes/gripper_base.stl" scale="0.001 0.001 0.001"/>
    </geometry>
    <material name="silver"/>
  </visual>
  <collision>
    <origin xyz="-0.16 -0.0 -1.024" rpy="0 0 0"/>
    <geometry>
      <mesh filename="file://$(find moiro_description)/meshes/gripper_base.stl" scale="0.001 0.001 0.001"/>
    </geometry>
  </collision>
</link>

<link name="gripper_left3">
  <inertial>
    <origin xyz="0.015990426629758026 -0.012967523057101044 0.0034753903195707814" rpy="0 0 0"/>
    <mass value="0.012694878221619885"/>
    <inertia ixx="2e-06" iyy="5e-06" izz="7e-06" ixy="3e-06" iyz="0.0" ixz="-0.0"/>
  </inertial>
  <visual>
    <origin xyz="-0.22039 0.01846 -1.027642" rpy="0 0 0"/>
    <geometry>
      <mesh filename="file://$(find moiro_description)/meshes/gripper_left3.stl" scale="0.001 0.001 0.001"/>
    </geometry>
    <material name="silver"/>
  </visual>
  <collision>
    <origin xyz="-0.22039 0.01846 -1.027642" rpy="0 0 0"/>
    <geometry>
      <mesh filename="file://$(find moiro_description)/meshes/gripper_left3.stl" scale="0.001 0.001 0.001"/>
    </geometry>
  </collision>
</link>

<link name="gripper_left1">
  <inertial>
    <origin xyz="0.011053309239173859 -0.005253691764351268 0.0001366080392810609" rpy="0 0 0"/>
    <mass value="0.013042175257524559"/>
    <inertia ixx="1e-06" iyy="5e-06" izz="6e-06" ixy="-2e-06" iyz="0.0" ixz="0.0"/>
  </inertial>
  <visual>
    <origin xyz="-0.271438 0.051465 -1.031142" rpy="0 0 0"/>
    <geometry>
      <mesh filename="file://$(find moiro_description)/meshes/gripper_left1.stl" scale="0.001 0.001 0.001"/>
    </geometry>
    <material name="silver"/>
  </visual>
  <collision>
    <origin xyz="-0.271438 0.051465 -1.031142" rpy="0 0 0"/>
    <geometry>
      <mesh filename="file://$(find moiro_description)/meshes/gripper_left1.stl" scale="0.001 0.001 0.001"/>
    </geometry>
  </collision>
</link>

<link name="gripper_right3">
  <inertial>
    <origin xyz="0.01599042559398811 0.012967524435816866 0.0035248809278745075" rpy="0 0 0"/>
    <mass value="0.012694878221619885"/>
    <inertia ixx="2e-06" iyy="5e-06" izz="7e-06" ixy="-3e-06" iyz="0.0" ixz="0.0"/>
  </inertial>
  <visual>
    <origin xyz="-0.22039 -0.01822 -1.027642" rpy="0 0 0"/>
    <geometry>
      <mesh filename="file://$(find moiro_description)/meshes/gripper_right3.stl" scale="0.001 0.001 0.001"/>
    </geometry>
    <material name="silver"/>
  </visual>
  <collision>
    <origin xyz="-0.22039 -0.01822 -1.027642" rpy="0 0 0"/>
    <geometry>
      <mesh filename="file://$(find moiro_description)/meshes/gripper_right3.stl" scale="0.001 0.001 0.001"/>
    </geometry>
  </collision>
</link>

<link name="gripper_right1">
  <inertial>
    <origin xyz="0.011053308203403722 0.0052536931430675685 -0.00013633679183122638" rpy="0 0 0"/>
    <mass value="0.013042175257524559"/>
    <inertia ixx="1e-06" iyy="5e-06" izz="6e-06" ixy="2e-06" iyz="0.0" ixz="-0.0"/>
  </inertial>
  <visual>
    <origin xyz="-0.271438 -0.051225 -1.031142" rpy="0 0 0"/>
    <geometry>
      <mesh filename="file://$(find moiro_description)/meshes/gripper_right1.stl" scale="0.001 0.001 0.001"/>
    </geometry>
    <material name="silver"/>
  </visual>
  <collision>
    <origin xyz="-0.271438 -0.051225 -1.031142" rpy="0 0 0"/>
    <geometry>
      <mesh filename="file://$(find moiro_description)/meshes/gripper_right1.stl" scale="0.001 0.001 0.001"/>
    </geometry>
  </collision>
</link>

<link name="cobot_body">
  <inertial>
    <origin xyz="-2.1294138884612695e-08 -0.012465741614899743 0.0436047733772541" rpy="0 0 0"/>
    <mass value="9.352590646947165"/>
    <inertia ixx="0.020014" iyy="0.013492" izz="0.021572" ixy="-0.0" iyz="-0.000111" ixz="-0.0"/>
  </inertial>
  <visual>
    <origin xyz="0.0 0.0 -0.519" rpy="0 0 0"/>
    <geometry>
      <mesh filename="file://$(find moiro_description)/meshes/cobot_body.stl" scale="0.001 0.001 0.001"/>
    </geometry>
    <material name="silver"/>
  </visual>
  <collision>
    <origin xyz="0.0 0.0 -0.519" rpy="0 0 0"/>
    <geometry>
      <mesh filename="file://$(find moiro_description)/meshes/cobot_body.stl" scale="0.001 0.001 0.001"/>
    </geometry>
  </collision>
</link>

<link name="wheel_right">
  <inertial>
    <origin xyz="7.185686845753172e-07 -0.013441732021015451 6.740004032668168e-08" rpy="0 0 0"/>
    <mass value="0.6403675217821955"/>
    <inertia ixx="0.00197" iyy="0.003862" izz="0.00197" ixy="0.0" iyz="0.0" ixz="-0.0"/>
  </inertial>
  <visual>
    <origin xyz="-0.000298 0.2233 -0.1055" rpy="0 0 0"/>
    <geometry>
      <mesh filename="file://$(find moiro_description)/meshes/wheel_right.stl" scale="0.001 0.001 0.001"/>
    </geometry>
    <material name="silver"/>
  </visual>
  <collision>
    <origin xyz="-0.000298 0.2233 -0.1055" rpy="0 0 0"/>
    <geometry>
      <mesh filename="file://$(find moiro_description)/meshes/wheel_right.stl" scale="0.001 0.001 0.001"/>
    </geometry>
  </collision>
</link>

<link name="wheel_left">
  <inertial>
    <origin xyz="5.370332256415832e-07 0.013441732021011232 2.8938916790677283e-08" rpy="0 0 0"/>
    <mass value="0.6403675217821955"/>
    <inertia ixx="0.00197" iyy="0.003862" izz="0.00197" ixy="-0.0" iyz="0.0" ixz="0.0"/>
  </inertial>
  <visual>
    <origin xyz="-0.000298 -0.2233 -0.1055" rpy="0 0 0"/>
    <geometry>
      <mesh filename="file://$(find moiro_description)/meshes/wheel_left.stl" scale="0.001 0.001 0.001"/>
    </geometry>
    <material name="silver"/>
  </visual>
  <collision>
    <origin xyz="-0.000298 -0.2233 -0.1055" rpy="0 0 0"/>
    <geometry>
      <mesh filename="file://$(find moiro_description)/meshes/wheel_left.stl" scale="0.001 0.001 0.001"/>
    </geometry>
  </collision>
</link>

<link name="caster_4">
  <inertial>
    <origin xyz="-0.020672705075060666 -0.0093964574939722 -0.02565460037687653" rpy="0 0 0"/>
    <mass value="0.14564908217460187"/>
    <inertia ixx="4.1e-05" iyy="5.4e-05" izz="2.2e-05" ixy="0.0" iyz="0.0" ixz="0.0"/>
  </inertial>
  <visual>
    <origin xyz="-0.238132 0.037118 -0.058" rpy="0 0 0"/>
    <geometry>
      <mesh filename="file://$(find moiro_description)/meshes/caster_4.stl" scale="0.001 0.001 0.001"/>
    </geometry>
    <material name="silver"/>
  </visual>
  <collision>
    <origin xyz="-0.238132 0.037118 -0.058" rpy="0 0 0"/>
    <geometry>
      <mesh filename="file://$(find moiro_description)/meshes/caster_4.stl" scale="0.001 0.001 0.001"/>
    </geometry>
  </collision>
</link>

<link name="caster_3">
  <inertial>
    <origin xyz="-0.02067270507506075 0.006390241409318889 -0.02565460037687651" rpy="0 0 0"/>
    <mass value="0.14564908217460187"/>
    <inertia ixx="4.1e-05" iyy="5.4e-05" izz="2.2e-05" ixy="0.0" iyz="0.0" ixz="0.0"/>
  </inertial>
  <visual>
    <origin xyz="-0.238132 -0.040529 -0.058" rpy="0 0 0"/>
    <geometry>
      <mesh filename="file://$(find moiro_description)/meshes/caster_3.stl" scale="0.001 0.001 0.001"/>
    </geometry>
    <material name="silver"/>
  </visual>
  <collision>
    <origin xyz="-0.238132 -0.040529 -0.058" rpy="0 0 0"/>
    <geometry>
      <mesh filename="file://$(find moiro_description)/meshes/caster_3.stl" scale="0.001 0.001 0.001"/>
    </geometry>
  </collision>
</link>

<link name="caster_6">
  <inertial>
    <origin xyz="0.02067255115624625 0.009396455766248653 -0.02565460037687644" rpy="0 0 0"/>
    <mass value="0.14564908217460187"/>
    <inertia ixx="4.1e-05" iyy="5.4e-05" izz="2.2e-05" ixy="0.0" iyz="0.0" ixz="0.0"/>
  </inertial>
  <visual>
    <origin xyz="0.238132 -0.037118 -0.058" rpy="0 0 0"/>
    <geometry>
      <mesh filename="file://$(find moiro_description)/meshes/caster_6.stl" scale="0.001 0.001 0.001"/>
    </geometry>
    <material name="silver"/>
  </visual>
  <collision>
    <origin xyz="0.238132 -0.037118 -0.058" rpy="0 0 0"/>
    <geometry>
      <mesh filename="file://$(find moiro_description)/meshes/caster_6.stl" scale="0.001 0.001 0.001"/>
    </geometry>
  </collision>
</link>

<link name="caster_5">
  <inertial>
    <origin xyz="0.02067255115624622 -0.006390243137041694 -0.025654600376876474" rpy="0 0 0"/>
    <mass value="0.14564908217460187"/>
    <inertia ixx="4.1e-05" iyy="5.4e-05" izz="2.2e-05" ixy="0.0" iyz="0.0" ixz="0.0"/>
  </inertial>
  <visual>
    <origin xyz="0.238132 0.040529 -0.058" rpy="0 0 0"/>
    <geometry>
      <mesh filename="file://$(find moiro_description)/meshes/caster_5.stl" scale="0.001 0.001 0.001"/>
    </geometry>
    <material name="silver"/>
  </visual>
  <collision>
    <origin xyz="0.238132 0.040529 -0.058" rpy="0 0 0"/>
    <geometry>
      <mesh filename="file://$(find moiro_description)/meshes/caster_5.stl" scale="0.001 0.001 0.001"/>
    </geometry>
  </collision>
</link>

<link name="motor_right">
  <inertial>
    <origin xyz="-0.00788584475935802 -0.006913170455323303 0.01448421113192662" rpy="0 0 0"/>
    <mass value="0.055170345827871496"/>
    <inertia ixx="9e-06" iyy="1.3e-05" izz="1.5e-05" ixy="0.0" iyz="0.0" ixz="-0.0"/>
  </inertial>
  <visual>
    <origin xyz="0.004 0.198 -0.091" rpy="0 0 0"/>
    <geometry>
      <mesh filename="file://$(find moiro_description)/meshes/motor_right.stl" scale="0.001 0.001 0.001"/>
    </geometry>
    <material name="silver"/>
  </visual>
  <collision>
    <origin xyz="0.004 0.198 -0.091" rpy="0 0 0"/>
    <geometry>
      <mesh filename="file://$(find moiro_description)/meshes/motor_right.stl" scale="0.001 0.001 0.001"/>
    </geometry>
  </collision>
</link>

<link name="motor_left">
  <inertial>
    <origin xyz="-0.007885844759358442 0.006913170455319695 0.014515788868055518" rpy="0 0 0"/>
    <mass value="0.05517034582787142"/>
    <inertia ixx="9e-06" iyy="1.3e-05" izz="1.5e-05" ixy="-0.0" iyz="0.0" ixz="0.0"/>
  </inertial>
  <visual>
    <origin xyz="0.004 -0.198 -0.091" rpy="0 0 0"/>
    <geometry>
      <mesh filename="file://$(find moiro_description)/meshes/motor_left.stl" scale="0.001 0.001 0.001"/>
    </geometry>
    <material name="silver"/>
  </visual>
  <collision>
    <origin xyz="0.004 -0.198 -0.091" rpy="0 0 0"/>
    <geometry>
      <mesh filename="file://$(find moiro_description)/meshes/motor_left.stl" scale="0.001 0.001 0.001"/>
    </geometry>
  </collision>
</link>

<link name="camera_zig">
  <inertial>
    <origin xyz="0.01453009991903656 0.044049338752250145 0.028344157098708522" rpy="0 0 0"/>
    <mass value="0.059863707592883605"/>
    <inertia ixx="9.5e-05" iyy="4.8e-05" izz="4.9e-05" ixy="-3e-06" iyz="-5e-06" ixz="-2e-06"/>
  </inertial>
  <visual>
    <origin xyz="-0.24875 0.045 -0.523" rpy="0 0 0"/>
    <geometry>
      <mesh filename="file://$(find moiro_description)/meshes/camera_zig.stl" scale="0.001 0.001 0.001"/>
    </geometry>
    <material name="silver"/>
  </visual>
  <collision>
    <origin xyz="-0.24875 0.045 -0.523" rpy="0 0 0"/>
    <geometry>
      <mesh filename="file://$(find moiro_description)/meshes/camera_zig.stl" scale="0.001 0.001 0.001"/>
    </geometry>
  </collision>
</link>

<link name="camera_link">
  <inertial>
    <origin xyz="0.012171542279409253 -5.299843283462433e-07 -4.8580261040487294e-05" rpy="0 0 0"/>
    <mass value="0.37833297071846606"/>
    <inertia ixx="0.000238" iyy="3.5e-05" izz="0.00024" ixy="-0.0" iyz="0.0" ixz="0.0"/>
  </inertial>
  <visual>
    <origin xyz="-0.26675 -0.00175 -0.561285" rpy="0 0 0"/>
    <geometry>
      <mesh filename="file://$(find moiro_description)/meshes/camera_link.stl" scale="0.001 0.001 0.001"/>
    </geometry>
    <material name="silver"/>
  </visual>
  <collision>
    <origin xyz="-0.26675 -0.00175 -0.561285" rpy="0 0 0"/>
    <geometry>
      <mesh filename="file://$(find moiro_description)/meshes/camera_link.stl" scale="0.001 0.001 0.001"/>
    </geometry>
  </collision>
</link>

<link name="base_plate">
  <inertial>
    <origin xyz="3.024732238173218e-08 -0.020354187478525226 0.008984617763925118" rpy="0 0 0"/>
    <mass value="0.5585010585602752"/>
    <inertia ixx="0.001441" iyy="0.000926" izz="0.002337" ixy="-0.0" iyz="0.0" ixz="-0.0"/>
  </inertial>
  <visual>
    <origin xyz="-0.0 0.0 -0.501" rpy="0 0 0"/>
    <geometry>
      <mesh filename="file://$(find moiro_description)/meshes/base_plate.stl" scale="0.001 0.001 0.001"/>
    </geometry>
    <material name="silver"/>
  </visual>
  <collision>
    <origin xyz="-0.0 0.0 -0.501" rpy="0 0 0"/>
    <geometry>
      <mesh filename="file://$(find moiro_description)/meshes/base_plate.stl" scale="0.001 0.001 0.001"/>
    </geometry>
  </collision>
</link>

<joint name="Revolute 1" type="revolute">
  <origin xyz="0.0 0.0 0.09" rpy="0 0 0"/>
  <parent link="cobot_body"/>
  <child link="basearm"/>
  <axis xyz="-0.0 0.0 1.0"/>
  <limit upper="2.792527" lower="-2.792527" effort="100" velocity="100"/>
</joint>

<joint name="Revolute 2" type="revolute">
  <origin xyz="0.045 0.0 0.085" rpy="0 0 0"/>
  <parent link="basearm"/>
  <child link="lowerarm"/>
  <axis xyz="1.0 0.0 0.0"/>
  <limit upper="2.792527" lower="-2.792527" effort="100" velocity="100"/>
</joint>

<joint name="Revolute 3" type="revolute">
  <origin xyz="0.0 0.0 0.136" rpy="0 0 0"/>
  <parent link="lowerarm"/>
  <child link="upperarm"/>
  <axis xyz="-1.0 -0.0 -0.0"/>
  <limit upper="2.792527" lower="-2.792527" effort="100" velocity="100"/>
</joint>

<joint name="Revolute 4" type="revolute">
  <origin xyz="0.0 0.0 0.099" rpy="0 0 0"/>
  <parent link="upperarm"/>
  <child link="pitcharm"/>
  <axis xyz="1.0 -0.0 0.0"/>
  <limit upper="2.792527" lower="-2.792527" effort="100" velocity="100"/>
</joint>

<joint name="Revolute 5" type="revolute">
  <origin xyz="0.045 0.0 0.045" rpy="0 0 0"/>
  <parent link="pitcharm"/>
  <child link="rollarm"/>
  <axis xyz="0.0 0.0 1.0"/>
  <limit upper="2.792527" lower="-2.792527" effort="100" velocity="100"/>
</joint>

<joint name="Revolute 6" type="revolute">
  <origin xyz="0.04 0.0 0.05" rpy="0 0 0"/>
  <parent link="rollarm"/>
  <child link="gripperarm"/>
  <axis xyz="1.0 -0.0 0.0"/>
  <limit upper="2.792527" lower="-2.792527" effort="100" velocity="100"/>
</joint>

<joint name="Rigid 30" type="fixed">
  <origin xyz="0.02 0.0 0.0" rpy="0 0 0"/>
  <parent link="gripperarm"/>
  <child link="cobot_camera"/>
</joint>

<joint name="Rigid 31" type="fixed">
  <origin xyz="0.01 0.0 0.0" rpy="0 0 0"/>
  <parent link="cobot_camera"/>
  <child link="gripper_base"/>
</joint>

<joint name="gripper_joint1" type="revolute">
  <origin xyz="0.06039 -0.01846 0.003642" rpy="0 0 0"/>
  <parent link="gripper_base"/>
  <child link="gripper_left3"/>
  <axis xyz="-0.0 -0.0 -1.0"/>
  <limit upper="0.0" lower="-0.698132" effort="100" velocity="100"/>
</joint>

<joint name="gripper_joint2" type="revolute">
  <origin xyz="0.051048 -0.033005 0.0035" rpy="0 0 0"/>
  <parent link="gripper_left3"/>
  <child link="gripper_left1"/>
  <axis xyz="0.0 0.0 1.0"/>
  <limit upper="0.0" lower="-0.698132" effort="100" velocity="100"/>
</joint>

<joint name="gripper_controller" type="revolute">
  <origin xyz="0.06039 0.01822 0.003642" rpy="0 0 0"/>
  <parent link="gripper_base"/>
  <child link="gripper_right3"/>
  <axis xyz="-0.0 -0.0 -1.0"/>
  <limit upper="0.698132" lower="0.0" effort="100" velocity="100"/>
</joint>

<joint name="gripper_joint3" type="revolute">
  <origin xyz="0.051048 0.033005 0.0035" rpy="0 0 0"/>
  <parent link="gripper_right3"/>
  <child link="gripper_right1"/>
  <axis xyz="0.0 -0.0 1.0"/>
  <limit upper="0.698132" lower="0.0" effort="100" velocity="100"/>
</joint>

<joint name="Rigid 48" type="fixed">
  <origin xyz="-0.0 0.0 0.018" rpy="0 0 0"/>
  <parent link="base_plate"/>
  <child link="cobot_body"/>
</joint>

<joint name="joint_wheel_right" type="continuous">
  <origin xyz="0.004298 -0.0253 0.0145" rpy="0 0 0"/>
  <parent link="motor_right"/>
  <child link="wheel_right"/>
  <axis xyz="-0.0 -1.0 0.0"/>
</joint>

<joint name="joint_wheel_left" type="continuous">
  <origin xyz="0.004298 0.0253 0.0145" rpy="0 0 0"/>
  <parent link="motor_left"/>
  <child link="wheel_left"/>
  <axis xyz="0.0 1.0 -0.0"/>
</joint>

<joint name="Rigid 62" type="fixed">
  <origin xyz="0.238132 -0.037118 0.058" rpy="0 0 0"/>
  <parent link="base_link"/>
  <child link="caster_4"/>
</joint>

<joint name="Rigid 63" type="fixed">
  <origin xyz="0.238132 0.040529 0.058" rpy="0 0 0"/>
  <parent link="base_link"/>
  <child link="caster_3"/>
</joint>

<joint name="Rigid 64" type="fixed">
  <origin xyz="-0.238132 0.037118 0.058" rpy="0 0 0"/>
  <parent link="base_link"/>
  <child link="caster_6"/>
</joint>

<joint name="Rigid 65" type="fixed">
  <origin xyz="-0.238132 -0.040529 0.058" rpy="0 0 0"/>
  <parent link="base_link"/>
  <child link="caster_5"/>
</joint>

<joint name="Rigid 67" type="fixed">
  <origin xyz="-0.004 -0.198 0.091" rpy="0 0 0"/>
  <parent link="base_link"/>
  <child link="motor_right"/>
</joint>

<joint name="Rigid 68" type="fixed">
  <origin xyz="-0.004 0.198 0.091" rpy="0 0 0"/>
  <parent link="base_link"/>
  <child link="motor_left"/>
</joint>

<joint name="joint_camera" type="fixed">
  <origin xyz="0.24875 -0.045 0.523" rpy="0 -0.575959 0"/>
  <parent link="base_link"/>
  <child link="camera_zig"/>
</joint>

<joint name="Rigid 70" type="fixed">
  <origin xyz="0.018 0.04675 0.038285" rpy="0 0 0"/>
  <parent link="camera_zig"/>
  <child link="camera_link"/>
</joint>

<joint name="Rigid 71" type="fixed">
  <origin xyz="0.0 0.0 0.501" rpy="0 0 0"/>
  <parent link="base_link"/>
  <child link="base_plate"/>
</joint>

</robot>
