<?xml version="1.0" ?>
<robot name="moiro" xmlns:xacro="http://www.ros.org/wiki/xacro">

<xacro:include filename="$(find moiro_description)/urdf/materials.xacro" />
<xacro:include filename="$(find moiro_description)/urdf/moiro.trans" />
<xacro:include filename="$(find moiro_description)/urdf/moiro.gazebo" />

<!-- 240529 오후 12시 수정 
1. mycobot에 부착하는 카메라 링크, 브라켓 추가, 
2. imu_link 추가
3. base_link 위치 수정 -->

<link name="base_link">
  <inertial>
    <origin xyz="0.004418404192394108 -0.0009320583420061628 0.2493907147199333" rpy="0 0 0"/>
    <mass value="10.314151582114752"/>
    <inertia ixx="0.498632" iyy="0.533352" izz="0.429421" ixy="0.002003" iyz="0.002378" ixz="-0.014194"/>
  </inertial>
  <visual>
    <origin xyz="0 0 0" rpy="0 0 0"/>
    <geometry>
      <mesh filename="file://$(find moiro_description)/meshes/base_link.stl" scale="0.001 0.001 0.001"/>
    </geometry>
    <material name="silver"/>
  </visual>
  <collision>
    <origin xyz="0 0 0" rpy="0 0 0"/>
    <geometry>
      <mesh filename="file://$(find moiro_description)/meshes/base_link.stl" scale="0.001 0.001 0.001"/>
    </geometry>
  </collision>
</link>

<link name="basearm">
  <inertial>
    <origin xyz="0.006896766224728663 -2.0863790969221033e-15 0.05549018686904683" rpy="0 0 0"/>
    <mass value="3.4735206294395446"/>
    <inertia ixx="0.004461" iyy="0.004757" izz="0.002424" ixy="0.0" iyz="0.0" ixz="-0.000777"/>
  </inertial>
  <visual>
    <origin xyz="0.0 0.0 -0.606" rpy="0 0 0"/>
    <geometry>
      <mesh filename="file://$(find moiro_description)/meshes/basearm.stl" scale="0.001 0.001 0.001"/>
    </geometry>
    <material name="silver"/>
  </visual>
  <collision>
    <origin xyz="0.0 0.0 -0.606" rpy="0 0 0"/>
    <geometry>
      <mesh filename="file://$(find moiro_description)/meshes/basearm.stl" scale="0.001 0.001 0.001"/>
    </geometry>
  </collision>
</link>

<link name="lowerarm">
  <inertial>
    <origin xyz="0.036906585755669324 -2.1017837997117547e-15 0.06799999999999129" rpy="0 0 0"/>
    <mass value="5.91988968680626"/>
    <inertia ixx="0.0188" iyy="0.019335" izz="0.004161" ixy="-0.0" iyz="0.0" ixz="0.0"/>
  </inertial>
  <visual>
    <origin xyz="-0.045 0.0 -0.691" rpy="0 0 0"/>
    <geometry>
      <mesh filename="file://$(find moiro_description)/meshes/lowerarm.stl" scale="0.001 0.001 0.001"/>
    </geometry>
    <material name="silver"/>
  </visual>
  <collision>
    <origin xyz="-0.045 0.0 -0.691" rpy="0 0 0"/>
    <geometry>
      <mesh filename="file://$(find moiro_description)/meshes/lowerarm.stl" scale="0.001 0.001 0.001"/>
    </geometry>
  </collision>
</link>

<link name="upperarm">
  <inertial>
    <origin xyz="-0.03502268825299596 1.5060537258141013e-15 0.04949999999999133" rpy="0 0 0"/>
    <mass value="4.802107093668197"/>
    <inertia ixx="0.01014" iyy="0.010584" izz="0.003386" ixy="-0.0" iyz="-0.0" ixz="-0.0"/>
  </inertial>
  <visual>
    <origin xyz="-0.045 0.0 -0.827" rpy="0 0 0"/>
    <geometry>
      <mesh filename="file://$(find moiro_description)/meshes/upperarm.stl" scale="0.001 0.001 0.001"/>
    </geometry>
    <material name="silver"/>
  </visual>
  <collision>
    <origin xyz="-0.045 0.0 -0.827" rpy="0 0 0"/>
    <geometry>
      <mesh filename="file://$(find moiro_description)/meshes/upperarm.stl" scale="0.001 0.001 0.001"/>
    </geometry>
  </collision>
</link>

<link name="pitcharm">
  <inertial>
    <origin xyz="0.034423872869188424 5.291448440797201e-15 0.010576127130799362" rpy="0 0 0"/>
    <mass value="2.265107015236222"/>
    <inertia ixx="0.001595" iyy="0.001803" izz="0.001595" ixy="-0.0" iyz="-0.0" ixz="-0.000324"/>
  </inertial>
  <visual>
    <origin xyz="-0.045 -0.0 -0.926" rpy="0 0 0"/>
    <geometry>
      <mesh filename="file://$(find moiro_description)/meshes/pitcharm.stl" scale="0.001 0.001 0.001"/>
    </geometry>
    <material name="silver"/>
  </visual>
  <collision>
    <origin xyz="-0.045 -0.0 -0.926" rpy="0 0 0"/>
    <geometry>
      <mesh filename="file://$(find moiro_description)/meshes/pitcharm.stl" scale="0.001 0.001 0.001"/>
    </geometry>
  </collision>
</link>

<link name="rollarm">
  <inertial>
    <origin xyz="-3.816391647148976e-15 6.350716433653324e-15 0.042116696506125595" rpy="0 0 0"/>
    <mass value="3.029827579494103"/>
    <inertia ixx="0.0025" iyy="0.002976" izz="0.002441" ixy="-0.0" iyz="-0.0" ixz="0.0"/>
  </inertial>
  <visual>
    <origin xyz="-0.09 -0.0 -0.971" rpy="0 0 0"/>
    <geometry>
      <mesh filename="file://$(find moiro_description)/meshes/rollarm.stl" scale="0.001 0.001 0.001"/>
    </geometry>
    <material name="silver"/>
  </visual>
  <collision>
    <origin xyz="-0.09 -0.0 -0.971" rpy="0 0 0"/>
    <geometry>
      <mesh filename="file://$(find moiro_description)/meshes/rollarm.stl" scale="0.001 0.001 0.001"/>
    </geometry>
  </collision>
</link>

<link name="gripperarm">
  <inertial>
    <origin xyz="0.00999999999999615 6.341038805146582e-15 -9.103828801926284e-15" rpy="0 0 0"/>
    <mass value="0.6042068071016569"/>
    <inertia ixx="0.00037" iyy="0.000205" izz="0.000205" ixy="-0.0" iyz="0.0" ixz="-0.0"/>
  </inertial>
  <visual>
    <origin xyz="-0.13 -0.0 -1.021" rpy="0 0 0"/>
    <geometry>
      <mesh filename="file://$(find moiro_description)/meshes/gripperarm.stl" scale="0.001 0.001 0.001"/>
    </geometry>
    <material name="silver"/>
  </visual>
  <collision>
    <origin xyz="-0.13 -0.0 -1.021" rpy="0 0 0"/>
    <geometry>
      <mesh filename="file://$(find moiro_description)/meshes/gripperarm.stl" scale="0.001 0.001 0.001"/>
    </geometry>
  </collision>
</link>

<link name="cobot_camera">
  <inertial>
    <origin xyz="0.017423960091247193 0.003253426631193808 0.005819385718719872" rpy="0 0 0"/>
    <mass value="0.21027144182469326"/>
    <inertia ixx="0.000387" iyy="0.000194" izz="0.000246" ixy="-5e-06" iyz="2e-06" ixz="1.9e-05"/>
  </inertial>
  <visual>
    <origin xyz="-0.15 -0.0 -1.021" rpy="0 0 0"/>
    <geometry>
      <mesh filename="file://$(find moiro_description)/meshes/cobot_camera.stl" scale="0.001 0.001 0.001"/>
    </geometry>
    <material name="silver"/>
  </visual>
  <collision>
    <origin xyz="-0.15 -0.0 -1.021" rpy="0 0 0"/>
    <geometry>
      <mesh filename="file://$(find moiro_description)/meshes/cobot_camera.stl" scale="0.001 0.001 0.001"/>
    </geometry>
  </collision>
</link>

<link name="cobot_body">
  <inertial>
    <origin xyz="-2.1294138884612695e-08 -0.012465741614899743 0.04360477337725388" rpy="0 0 0"/>
    <mass value="9.352590646947165"/>
    <inertia ixx="0.020014" iyy="0.013492" izz="0.021572" ixy="-0.0" iyz="-0.000111" ixz="-0.0"/>
  </inertial>
  <visual>
    <origin xyz="0.0 0.0 -0.516" rpy="0 0 0"/>
    <geometry>
      <mesh filename="file://$(find moiro_description)/meshes/cobot_body.stl" scale="0.001 0.001 0.001"/>
    </geometry>
    <material name="silver"/>
  </visual>
  <collision>
    <origin xyz="0.0 0.0 -0.516" rpy="0 0 0"/>
    <geometry>
      <mesh filename="file://$(find moiro_description)/meshes/cobot_body.stl" scale="0.001 0.001 0.001"/>
    </geometry>
  </collision>
</link>

<link name="wheel_right">
  <inertial>
    <origin xyz="7.185686845753172e-07 -0.013441732021015451 6.740004027117052e-08" rpy="0 0 0"/>
    <mass value="0.6403675217821955"/>
    <inertia ixx="0.00197" iyy="0.003862" izz="0.00197" ixy="0.0" iyz="0.0" ixz="-0.0"/>
  </inertial>
  <visual>
    <origin xyz="-0.000298 0.2233 -0.1025" rpy="0 0 0"/>
    <geometry>
      <mesh filename="file://$(find moiro_description)/meshes/wheel_right.stl" scale="0.001 0.001 0.001"/>
    </geometry>
    <material name="silver"/>
  </visual>
  <collision>
    <origin xyz="-0.000298 0.2233 -0.1025" rpy="0 0 0"/>
    <geometry>
      <mesh filename="file://$(find moiro_description)/meshes/wheel_right.stl" scale="0.001 0.001 0.001"/>
    </geometry>
  </collision>
</link>

<link name="wheel_left">
  <inertial>
    <origin xyz="5.370332256415832e-07 0.013441732021011232 2.8938916707410556e-08" rpy="0 0 0"/>
    <mass value="0.6403675217821955"/>
    <inertia ixx="0.00197" iyy="0.003862" izz="0.00197" ixy="-0.0" iyz="0.0" ixz="0.0"/>
  </inertial>
  <visual>
    <origin xyz="-0.000298 -0.2233 -0.1025" rpy="0 0 0"/>
    <geometry>
      <mesh filename="file://$(find moiro_description)/meshes/wheel_left.stl" scale="0.001 0.001 0.001"/>
    </geometry>
    <material name="silver"/>
  </visual>
  <collision>
    <origin xyz="-0.000298 -0.2233 -0.1025" rpy="0 0 0"/>
    <geometry>
      <mesh filename="file://$(find moiro_description)/meshes/wheel_left.stl" scale="0.001 0.001 0.001"/>
    </geometry>
  </collision>
</link>

<link name="caster_4">
  <inertial>
    <origin xyz="-0.02067270507506061 -0.009396457493972207 -0.11565460037687654" rpy="0 0 0"/>
    <mass value="0.14564908217460187"/>
    <inertia ixx="4.1e-05" iyy="5.4e-05" izz="2.2e-05" ixy="0.0" iyz="0.0" ixz="0.0"/>
  </inertial>
  <visual>
    <origin xyz="-0.238132 0.037118 -0.145" rpy="0 0 0"/>
    <geometry>
      <mesh filename="file://$(find moiro_description)/meshes/caster_4.stl" scale="0.001 0.001 0.001"/>
    </geometry>
    <material name="silver"/>
  </visual>
  <collision>
    <origin xyz="-0.238132 0.037118 -0.145" rpy="0 0 0"/>
    <geometry>
      <mesh filename="file://$(find moiro_description)/meshes/caster_4.stl" scale="0.001 0.001 0.001"/>
    </geometry>
  </collision>
</link>

<link name="caster_3">
  <inertial>
    <origin xyz="-0.02067270507506072 0.006390241409318889 -0.025654600376876516" rpy="0 0 0"/>
    <mass value="0.14564908217460187"/>
    <inertia ixx="4.1e-05" iyy="5.4e-05" izz="2.2e-05" ixy="0.0" iyz="0.0" ixz="0.0"/>
  </inertial>
  <visual>
    <origin xyz="-0.238132 -0.040529 -0.055" rpy="0 0 0"/>
    <geometry>
      <mesh filename="file://$(find moiro_description)/meshes/caster_3.stl" scale="0.001 0.001 0.001"/>
    </geometry>
    <material name="silver"/>
  </visual>
  <collision>
    <origin xyz="-0.238132 -0.040529 -0.055" rpy="0 0 0"/>
    <geometry>
      <mesh filename="file://$(find moiro_description)/meshes/caster_3.stl" scale="0.001 0.001 0.001"/>
    </geometry>
  </collision>
</link>

<link name="caster_6">
  <inertial>
    <origin xyz="0.020672551156246277 0.009396455766248653 -0.11565460037687647" rpy="0 0 0"/>
    <mass value="0.14564908217460187"/>
    <inertia ixx="4.1e-05" iyy="5.4e-05" izz="2.2e-05" ixy="0.0" iyz="0.0" ixz="0.0"/>
  </inertial>
  <visual>
    <origin xyz="0.238132 -0.037118 -0.145" rpy="0 0 0"/>
    <geometry>
      <mesh filename="file://$(find moiro_description)/meshes/caster_6.stl" scale="0.001 0.001 0.001"/>
    </geometry>
    <material name="silver"/>
  </visual>
  <collision>
    <origin xyz="0.238132 -0.037118 -0.145" rpy="0 0 0"/>
    <geometry>
      <mesh filename="file://$(find moiro_description)/meshes/caster_6.stl" scale="0.001 0.001 0.001"/>
    </geometry>
  </collision>
</link>

<link name="caster_5">
  <inertial>
    <origin xyz="0.02067255115624625 -0.006390243137041701 -0.1156546003768765" rpy="0 0 0"/>
    <mass value="0.14564908217460187"/>
    <inertia ixx="4.1e-05" iyy="5.4e-05" izz="2.2e-05" ixy="0.0" iyz="0.0" ixz="0.0"/>
  </inertial>
  <visual>
    <origin xyz="0.238132 0.040529 -0.145" rpy="0 0 0"/>
    <geometry>
      <mesh filename="file://$(find moiro_description)/meshes/caster_5.stl" scale="0.001 0.001 0.001"/>
    </geometry>
    <material name="silver"/>
  </visual>
  <collision>
    <origin xyz="0.238132 0.040529 -0.145" rpy="0 0 0"/>
    <geometry>
      <mesh filename="file://$(find moiro_description)/meshes/caster_5.stl" scale="0.001 0.001 0.001"/>
    </geometry>
  </collision>
</link>

<link name="motor_right">
  <inertial>
    <origin xyz="-0.00788584475935802 -0.006913170455323331 0.014484211131926578" rpy="0 0 0"/>
    <mass value="0.055170345827871496"/>
    <inertia ixx="9e-06" iyy="1.3e-05" izz="1.5e-05" ixy="0.0" iyz="0.0" ixz="-0.0"/>
  </inertial>
  <visual>
    <origin xyz="0.004 0.198 -0.088" rpy="0 0 0"/>
    <geometry>
      <mesh filename="file://$(find moiro_description)/meshes/motor_right.stl" scale="0.001 0.001 0.001"/>
    </geometry>
    <material name="silver"/>
  </visual>
  <collision>
    <origin xyz="0.004 0.198 -0.088" rpy="0 0 0"/>
    <geometry>
      <mesh filename="file://$(find moiro_description)/meshes/motor_right.stl" scale="0.001 0.001 0.001"/>
    </geometry>
  </collision>
</link>

<link name="motor_left">
  <inertial>
    <origin xyz="-0.007885844759358442 0.006913170455319778 0.014515788868055449" rpy="0 0 0"/>
    <mass value="0.05517034582787142"/>
    <inertia ixx="9e-06" iyy="1.3e-05" izz="1.5e-05" ixy="-0.0" iyz="0.0" ixz="0.0"/>
  </inertial>
  <visual>
    <origin xyz="0.004 -0.198 -0.088" rpy="0 0 0"/>
    <geometry>
      <mesh filename="file://$(find moiro_description)/meshes/motor_left.stl" scale="0.001 0.001 0.001"/>
    </geometry>
    <material name="silver"/>
  </visual>
  <collision>
    <origin xyz="0.004 -0.198 -0.088" rpy="0 0 0"/>
    <geometry>
      <mesh filename="file://$(find moiro_description)/meshes/motor_left.stl" scale="0.001 0.001 0.001"/>
    </geometry>
  </collision>
</link>

<link name="camera_zig">
  <inertial>
    <origin xyz="0.014530099919036615 0.044049338752250145 0.028344157098708633" rpy="0 0 0"/>
    <mass value="0.059863707592883605"/>
    <inertia ixx="9.5e-05" iyy="4.8e-05" izz="4.9e-05" ixy="-3e-06" iyz="-5e-06" ixz="-2e-06"/>
  </inertial>
  <visual>
    <origin xyz="-0.24875 0.045 -0.52" rpy="0 0 0"/>
    <geometry>
      <mesh filename="file://$(find moiro_description)/meshes/camera_zig.stl" scale="0.001 0.001 0.001"/>
    </geometry>
    <material name="silver"/>
  </visual>
  <collision>
    <origin xyz="-0.24875 0.045 -0.52" rpy="0 0 0"/>
    <geometry>
      <mesh filename="file://$(find moiro_description)/meshes/camera_zig.stl" scale="0.001 0.001 0.001"/>
    </geometry>
  </collision>
</link>

<link name="base_plate">
  <inertial>
    <origin xyz="3.024732238173218e-08 -0.020354187478525226 0.008984617763925118" rpy="0 0 0"/>
    <mass value="0.5585010585602752"/>
    <inertia ixx="0.001441" iyy="0.000926" izz="0.002337" ixy="-0.0" iyz="0.0" ixz="-0.0"/>
  </inertial>
  <visual>
    <origin xyz="-0.0 0.0 -0.498" rpy="0 0 0"/>
    <geometry>
      <mesh filename="file://$(find moiro_description)/meshes/base_plate.stl" scale="0.001 0.001 0.001"/>
    </geometry>
    <material name="silver"/>
  </visual>
  <collision>
    <origin xyz="-0.0 0.0 -0.498" rpy="0 0 0"/>
    <geometry>
      <mesh filename="file://$(find moiro_description)/meshes/base_plate.stl" scale="0.001 0.001 0.001"/>
    </geometry>
  </collision>
</link>

<link name="base_scan">
  <inertial>
    <origin xyz="1.4890131030027799e-05 -0.008617362464656688 0.011145262430183378" rpy="0 0 0"/>
    <mass value="0.4177280575470181"/>
    <inertia ixx="0.000281" iyy="0.000143" izz="0.000351" ixy="-0.0" iyz="-3.9e-05" ixz="-0.0"/>
  </inertial>
  <visual>
    <origin xyz="0.000412 -0.003127 -0.268745" rpy="0 0 0"/>
    <geometry>
      <mesh filename="file://$(find moiro_description)/meshes/base_scan.stl" scale="0.001 0.001 0.001"/>
    </geometry>
    <material name="silver"/>
  </visual>
  <collision>
    <origin xyz="0.000412 -0.003127 -0.268745" rpy="0 0 0"/>
    <geometry>
      <mesh filename="file://$(find moiro_description)/meshes/base_scan.stl" scale="0.001 0.001 0.001"/>
    </geometry>
  </collision>
</link>

<link name="imu_link">
  <inertial>
    <origin xyz="-0.04153434985377516 -0.031630029317067154 0.002586806247330431" rpy="0 0 0"/>
    <mass value="0.030287554797551564"/>
    <inertia ixx="1.3e-05" iyy="2.9e-05" izz="4.2e-05" ixy="-1e-06" iyz="-0.0" ixz="-1e-06"/>
  </inertial>
  <visual>
    <origin xyz="-0.048037 -0.045 -0.1" rpy="0 0 0"/>
    <geometry>
      <mesh filename="file://$(find moiro_description)/meshes/imu_link.stl" scale="0.001 0.001 0.001"/>
    </geometry>
    <material name="silver"/>
  </visual>
  <collision>
    <origin xyz="-0.048037 -0.045 -0.1" rpy="0 0 0"/>
    <geometry>
      <mesh filename="file://$(find moiro_description)/meshes/imu_link.stl" scale="0.001 0.001 0.001"/>
    </geometry>
  </collision>
</link>

<link name="camera_link">
  <inertial>
    <origin xyz="0.012171550992974123 1.5521819222250478e-06 -4.879803335111621e-05" rpy="0 0 0"/>
    <mass value="0.3783329537916638"/>
    <inertia ixx="0.000238" iyy="3.5e-05" izz="0.00024" ixy="0.0" iyz="0.0" ixz="0.0"/>
  </inertial>
  <visual>
    <origin xyz="-0.26675 -0.00175 -0.558285" rpy="0 0 0"/>
    <geometry>
      <mesh filename="file://$(find moiro_description)/meshes/camera_link.stl" scale="0.001 0.001 0.001"/>
    </geometry>
    <material name="silver"/>
  </visual>
  <collision>
    <origin xyz="-0.26675 -0.00175 -0.558285" rpy="0 0 0"/>
    <geometry>
      <mesh filename="file://$(find moiro_description)/meshes/camera_link.stl" scale="0.001 0.001 0.001"/>
    </geometry>
  </collision>
</link>

<!-- joint -->

<joint name="mycobot_joint" type="revolute">
  <origin xyz="0.0 0.0 0.09" rpy="0 0 0"/>
  <parent link="cobot_body"/>
  <child link="basearm"/>
  <axis xyz="-0.0 0.0 1.0"/>
  <limit upper="2.792527" lower="-2.792527" effort="100" velocity="100"/>
</joint>

<joint name="mycobot_joint_2" type="revolute">
  <origin xyz="0.045 0.0 0.085" rpy="0 0 0"/>
  <parent link="basearm"/>
  <child link="lowerarm"/>
  <axis xyz="1.0 0.0 0.0"/>
  <limit upper="2.792527" lower="-2.792527" effort="100" velocity="100"/>
</joint>

<joint name="mycobot_joint_3" type="revolute">
  <origin xyz="0.0 0.0 0.136" rpy="0 0 0"/>
  <parent link="lowerarm"/>
  <child link="upperarm"/>
  <axis xyz="-1.0 -0.0 -0.0"/>
  <limit upper="2.792527" lower="-2.792527" effort="100" velocity="100"/>
</joint>

<joint name="mycobot_joint_4" type="revolute">
  <origin xyz="0.0 0.0 0.099" rpy="0 0 0"/>
  <parent link="upperarm"/>
  <child link="pitcharm"/>
  <axis xyz="1.0 -0.0 0.0"/>
  <limit upper="2.792527" lower="-2.792527" effort="100" velocity="100"/>
</joint>

<joint name="mycobot_joint_5" type="revolute">
  <origin xyz="0.045 0.0 0.045" rpy="0 0 0"/>
  <parent link="pitcharm"/>
  <child link="rollarm"/>
  <axis xyz="0.0 0.0 1.0"/>
  <limit upper="2.792527" lower="-2.792527" effort="100" velocity="100"/>
</joint>

<joint name="mycobot_joint_6" type="revolute">
  <origin xyz="0.04 0.0 0.05" rpy="0 0 0"/>
  <parent link="rollarm"/>
  <child link="gripperarm"/>
  <axis xyz="1.0 -0.0 0.0"/>
  <limit upper="2.792527" lower="-2.792527" effort="100" velocity="100"/>
</joint>

<joint name="cobot_camera_joint" type="fixed">
  <origin xyz="0.02 0.0 0.0" rpy="0 0 0"/>
  <parent link="gripperarm"/>
  <child link="cobot_camera"/>
</joint>

<joint name="mycobot_joint" type="fixed">
  <origin xyz="-0.0 0.0 0.018" rpy="0 0 0"/>
  <parent link="base_plate"/>
  <child link="cobot_body"/>
</joint>

<joint name="joint_wheel_right" type="continuous">
  <origin xyz="0.004298 -0.0253 0.0145" rpy="0 0 0"/>
  <parent link="motor_right"/>
  <child link="wheel_right"/>
  <axis xyz="-0.0 -1.0 0.0"/>
</joint>

<joint name="joint_wheel_left" type="continuous">
  <origin xyz="0.004298 0.0253 0.0145" rpy="0 0 0"/>
  <parent link="motor_left"/>
  <child link="wheel_left"/>
  <axis xyz="0.0 1.0 -0.0"/>
</joint>

<joint name="caster4_joint" type="fixed">
  <origin xyz="0.238132 -0.037118 0.145" rpy="0 0 0"/>
  <parent link="base_link"/>
  <child link="caster_4"/>
</joint>

<joint name="caster3_joint" type="fixed">
  <origin xyz="0.238132 0.040529 0.055" rpy="0 0 0"/>
  <parent link="base_link"/>
  <child link="caster_3"/>
</joint>

<joint name="caster6_joint" type="fixed">
  <origin xyz="-0.238132 0.037118 0.145" rpy="0 0 0"/>
  <parent link="base_link"/>
  <child link="caster_6"/>
</joint>

<joint name="caster5_joint" type="fixed">
  <origin xyz="-0.238132 -0.040529 0.145" rpy="0 0 0"/>
  <parent link="base_link"/>
  <child link="caster_5"/>
</joint>

<joint name="motor_right_joint" type="fixed">
  <origin xyz="-0.004 -0.198 0.088" rpy="0 0 0"/>
  <parent link="base_link"/>
  <child link="motor_right"/>
</joint>

<joint name="motor_left_joint" type="fixed">
  <origin xyz="-0.004 0.198 0.088" rpy="0 0 0"/>
  <parent link="base_link"/>
  <child link="motor_left"/>
</joint>

<joint name="joint_camera" type="fixed">
  <origin xyz="0.24875 -0.045 0.52" rpy="0 0 0"/>
  <parent link="base_link"/>
  <child link="camera_zig"/>
</joint>

<joint name="plate_joint" type="fixed">
  <origin xyz="0.0 0.0 0.498" rpy="0 0 0"/>
  <parent link="base_link"/>
  <child link="base_plate"/>
</joint>

<joint name="scan_joint" type="fixed">
  <origin xyz="-0.000412 0.003127 0.268745" rpy="0 0 0"/>
  <parent link="base_link"/>
  <child link="base_scan"/>
</joint>

<joint name="imu_joint" type="fixed">
  <origin xyz="0.048037 0.045 0.1" rpy="0 0 0"/>
  <parent link="base_link"/>
  <child link="imu_link"/>
</joint>

<joint name="camera_zig_joint" type="fixed">
  <origin xyz="0.018 0.04675 0.038285" rpy="0 0 0"/>
  <parent link="camera_zig"/>
  <child link="camera_link"/>
</joint>

</robot>
