<?xml version="1.0" ?>
<robot name="moi_arm" xmlns:xacro="http://www.ros.org/wiki/xacro">

<xacro:include filename="$(find moi_arm_description)/urdf/materials.xacro" />
<xacro:include filename="$(find moi_arm_description)/urdf/moi_arm.trans" />
<xacro:include filename="$(find moi_arm_description)/urdf/moi_arm.gazebo" />
<link name="base_link">
  <inertial>
    <origin xyz="-2.3204052621237496e-08 -9.341746626578682e-05 0.007097721551323412" rpy="0 0 0"/>
    <mass value="1.1963019403514967"/>
    <inertia ixx="0.003058" iyy="0.003068" izz="0.005691" ixy="0.0" iyz="-1e-06" ixz="-0.0"/>
  </inertial>
  <visual>
    <origin xyz="0 0 0" rpy="0 0 0"/>
    <geometry>
      <mesh filename="file://$(find moi_arm_description)/meshes/base_link.stl" scale="0.001 0.001 0.001"/>
    </geometry>
    <material name="silver"/>
  </visual>
  <collision>
    <origin xyz="0 0 0" rpy="0 0 0"/>
    <geometry>
      <mesh filename="file://$(find moi_arm_description)/meshes/base_link.stl" scale="0.001 0.001 0.001"/>
    </geometry>
  </collision>
</link>

<link name="Component2_1">
  <inertial>
    <origin xyz="-1.723794702839714e-07 -0.0006862862107224133 0.0014991079387778813" rpy="0 0 0"/>
    <mass value="0.2779523828869321"/>
    <inertia ixx="0.000265" iyy="0.000272" izz="0.000536" ixy="0.0" iyz="0.0" ixz="0.0"/>
  </inertial>
  <visual>
    <origin xyz="-0.0 -0.0 -0.043" rpy="0 0 0"/>
    <geometry>
      <mesh filename="file://$(find moi_arm_description)/meshes/Component2_1.stl" scale="0.001 0.001 0.001"/>
    </geometry>
    <material name="silver"/>
  </visual>
  <collision>
    <origin xyz="-0.0 -0.0 -0.043" rpy="0 0 0"/>
    <geometry>
      <mesh filename="file://$(find moi_arm_description)/meshes/Component2_1.stl" scale="0.001 0.001 0.001"/>
    </geometry>
  </collision>
</link>

<link name="Component3_1">
  <inertial>
    <origin xyz="-5.108764106198649e-11 -0.007982482847528932 0.002397358752411101" rpy="0 0 0"/>
    <mass value="0.02516998505835531"/>
    <inertia ixx="2e-06" iyy="4e-06" izz="5e-06" ixy="0.0" iyz="-0.0" ixz="0.0"/>
  </inertial>
  <visual>
    <origin xyz="0.0318 -0.008 -0.046" rpy="0 0 0"/>
    <geometry>
      <mesh filename="file://$(find moi_arm_description)/meshes/Component3_1.stl" scale="0.001 0.001 0.001"/>
    </geometry>
    <material name="silver"/>
  </visual>
  <collision>
    <origin xyz="0.0318 -0.008 -0.046" rpy="0 0 0"/>
    <geometry>
      <mesh filename="file://$(find moi_arm_description)/meshes/Component3_1.stl" scale="0.001 0.001 0.001"/>
    </geometry>
  </collision>
</link>

<link name="Component4_1">
  <inertial>
    <origin xyz="-5.108793249553045e-11 -0.007982482441365773 0.0023973587524110662" rpy="0 0 0"/>
    <mass value="0.02516998505835531"/>
    <inertia ixx="2e-06" iyy="4e-06" izz="5e-06" ixy="0.0" iyz="-0.0" ixz="0.0"/>
  </inertial>
  <visual>
    <origin xyz="-0.0318 -0.008 -0.046" rpy="0 0 0"/>
    <geometry>
      <mesh filename="file://$(find moi_arm_description)/meshes/Component4_1.stl" scale="0.001 0.001 0.001"/>
    </geometry>
    <material name="silver"/>
  </visual>
  <collision>
    <origin xyz="-0.0318 -0.008 -0.046" rpy="0 0 0"/>
    <geometry>
      <mesh filename="file://$(find moi_arm_description)/meshes/Component4_1.stl" scale="0.001 0.001 0.001"/>
    </geometry>
  </collision>
</link>

<link name="Component5_1">
  <inertial>
    <origin xyz="0.0005767749991517357 2.0306988590679254e-10 5.249550794061975e-13" rpy="0 0 0"/>
    <mass value="0.013145620261468437"/>
    <inertia ixx="1e-06" iyy="0.0" izz="0.0" ixy="-0.0" iyz="-0.0" ixz="0.0"/>
  </inertial>
  <visual>
    <origin xyz="-0.04975 -0.0 -0.0875" rpy="0 0 0"/>
    <geometry>
      <mesh filename="file://$(find moi_arm_description)/meshes/Component5_1.stl" scale="0.001 0.001 0.001"/>
    </geometry>
    <material name="silver"/>
  </visual>
  <collision>
    <origin xyz="-0.04975 -0.0 -0.0875" rpy="0 0 0"/>
    <geometry>
      <mesh filename="file://$(find moi_arm_description)/meshes/Component5_1.stl" scale="0.001 0.001 0.001"/>
    </geometry>
  </collision>
</link>

<link name="Component7_1">
  <inertial>
    <origin xyz="-0.001811963186310439 -0.00800002657181841 0.02115293589470097" rpy="0 0 0"/>
    <mass value="0.061219272040330903"/>
    <inertia ixx="1.4e-05" iyy="1e-05" izz="4e-06" ixy="0.0" iyz="0.0" ixz="0.0"/>
  </inertial>
  <visual>
    <origin xyz="-0.0478 -0.008 -0.0515" rpy="0 0 0"/>
    <geometry>
      <mesh filename="file://$(find moi_arm_description)/meshes/Component7_1.stl" scale="0.001 0.001 0.001"/>
    </geometry>
    <material name="silver"/>
  </visual>
  <collision>
    <origin xyz="-0.0478 -0.008 -0.0515" rpy="0 0 0"/>
    <geometry>
      <mesh filename="file://$(find moi_arm_description)/meshes/Component7_1.stl" scale="0.001 0.001 0.001"/>
    </geometry>
  </collision>
</link>

<link name="Component8_1">
  <inertial>
    <origin xyz="-0.002777924827504729 -0.009249999796888161 -0.022456634580485635" rpy="0 0 0"/>
    <mass value="0.051461187075064724"/>
    <inertia ixx="1.4e-05" iyy="1e-05" izz="4e-06" ixy="0.0" iyz="-0.0" ixz="-0.0"/>
  </inertial>
  <visual>
    <origin xyz="-0.0208 -0.00925 -0.0965" rpy="0 0 0"/>
    <geometry>
      <mesh filename="file://$(find moi_arm_description)/meshes/Component8_1.stl" scale="0.001 0.001 0.001"/>
    </geometry>
    <material name="silver"/>
  </visual>
  <collision>
    <origin xyz="-0.0208 -0.00925 -0.0965" rpy="0 0 0"/>
    <geometry>
      <mesh filename="file://$(find moi_arm_description)/meshes/Component8_1.stl" scale="0.001 0.001 0.001"/>
    </geometry>
  </collision>
</link>

<link name="Component6_1">
  <inertial>
    <origin xyz="-0.011000000051089809 0.009250000203081518 -0.021533510873839742" rpy="0 0 0"/>
    <mass value="0.20992105246147483"/>
    <inertia ixx="5e-05" iyy="4.7e-05" izz="2e-05" ixy="0.0" iyz="-0.0" ixz="0.0"/>
  </inertial>
  <visual>
    <origin xyz="-0.0428 0.00925 -0.0965" rpy="0 0 0"/>
    <geometry>
      <mesh filename="file://$(find moi_arm_description)/meshes/Component6_1.stl" scale="0.001 0.001 0.001"/>
    </geometry>
    <material name="silver"/>
  </visual>
  <collision>
    <origin xyz="-0.0428 0.00925 -0.0965" rpy="0 0 0"/>
    <geometry>
      <mesh filename="file://$(find moi_arm_description)/meshes/Component6_1.stl" scale="0.001 0.001 0.001"/>
    </geometry>
  </collision>
</link>

<link name="Component5_2">
  <inertial>
    <origin xyz="-0.000576775101334262 -2.0306992198904084e-10 5.230954558399503e-13" rpy="0 0 0"/>
    <mass value="0.013145620261468437"/>
    <inertia ixx="1e-06" iyy="0.0" izz="0.0" ixy="-0.0" iyz="0.0" ixz="-0.0"/>
  </inertial>
  <visual>
    <origin xyz="0.04975 0.0 -0.0875" rpy="0 0 0"/>
    <geometry>
      <mesh filename="file://$(find moi_arm_description)/meshes/Component5_2.stl" scale="0.001 0.001 0.001"/>
    </geometry>
    <material name="silver"/>
  </visual>
  <collision>
    <origin xyz="0.04975 0.0 -0.0875" rpy="0 0 0"/>
    <geometry>
      <mesh filename="file://$(find moi_arm_description)/meshes/Component5_2.stl" scale="0.001 0.001 0.001"/>
    </geometry>
  </collision>
</link>

<link name="Component6_2">
  <inertial>
    <origin xyz="0.010999999948906665 0.009249999796918516 -0.021533510873841685" rpy="0 0 0"/>
    <mass value="0.20992105246147483"/>
    <inertia ixx="5e-05" iyy="4.7e-05" izz="2e-05" ixy="-0.0" iyz="0.0" ixz="0.0"/>
  </inertial>
  <visual>
    <origin xyz="0.0428 0.00925 -0.0965" rpy="0 0 0"/>
    <geometry>
      <mesh filename="file://$(find moi_arm_description)/meshes/Component6_2.stl" scale="0.001 0.001 0.001"/>
    </geometry>
    <material name="silver"/>
  </visual>
  <collision>
    <origin xyz="0.0428 0.00925 -0.0965" rpy="0 0 0"/>
    <geometry>
      <mesh filename="file://$(find moi_arm_description)/meshes/Component6_2.stl" scale="0.001 0.001 0.001"/>
    </geometry>
  </collision>
</link>

<link name="Component8_2">
  <inertial>
    <origin xyz="0.0027779247253222235 0.009249999796888243 -0.022456634580487425" rpy="0 0 0"/>
    <mass value="0.051461187075064724"/>
    <inertia ixx="1.4e-05" iyy="1e-05" izz="4e-06" ixy="0.0" iyz="0.0" ixz="0.0"/>
  </inertial>
  <visual>
    <origin xyz="0.0208 0.00925 -0.0965" rpy="0 0 0"/>
    <geometry>
      <mesh filename="file://$(find moi_arm_description)/meshes/Component8_2.stl" scale="0.001 0.001 0.001"/>
    </geometry>
    <material name="silver"/>
  </visual>
  <collision>
    <origin xyz="0.0208 0.00925 -0.0965" rpy="0 0 0"/>
    <geometry>
      <mesh filename="file://$(find moi_arm_description)/meshes/Component8_2.stl" scale="0.001 0.001 0.001"/>
    </geometry>
  </collision>
</link>

<link name="Component7_2">
  <inertial>
    <origin xyz="0.0018119630841314932 0.00800002657181839 0.021152935894701345" rpy="0 0 0"/>
    <mass value="0.061219272040330903"/>
    <inertia ixx="1.4e-05" iyy="1e-05" izz="4e-06" ixy="0.0" iyz="-0.0" ixz="-0.0"/>
  </inertial>
  <visual>
    <origin xyz="0.0478 0.008 -0.0515" rpy="0 0 0"/>
    <geometry>
      <mesh filename="file://$(find moi_arm_description)/meshes/Component7_2.stl" scale="0.001 0.001 0.001"/>
    </geometry>
    <material name="silver"/>
  </visual>
  <collision>
    <origin xyz="0.0478 0.008 -0.0515" rpy="0 0 0"/>
    <geometry>
      <mesh filename="file://$(find moi_arm_description)/meshes/Component7_2.stl" scale="0.001 0.001 0.001"/>
    </geometry>
  </collision>
</link>

<link name="Component9_1">
  <inertial>
    <origin xyz="-0.05300000011434975 6.865823318272569e-07 0.03104840421136143" rpy="0 0 0"/>
    <mass value="0.7282309507071387"/>
    <inertia ixx="0.000224" iyy="0.000822" izz="0.000727" ixy="-0.0" iyz="-0.0" ixz="0.0"/>
  </inertial>
  <visual>
    <origin xyz="-0.05275 -0.0 -0.0875" rpy="0 0 0"/>
    <geometry>
      <mesh filename="file://$(find moi_arm_description)/meshes/Component9_1.stl" scale="0.001 0.001 0.001"/>
    </geometry>
    <material name="silver"/>
  </visual>
  <collision>
    <origin xyz="-0.05275 -0.0 -0.0875" rpy="0 0 0"/>
    <geometry>
      <mesh filename="file://$(find moi_arm_description)/meshes/Component9_1.stl" scale="0.001 0.001 0.001"/>
    </geometry>
  </collision>
</link>

<link name="Component10_1">
  <inertial>
    <origin xyz="0.011999883043338091 0.009500621991842925 0.052942045256373" rpy="0 0 0"/>
    <mass value="1.0029838563695943"/>
    <inertia ixx="0.001903" iyy="0.002087" izz="0.000249" ixy="-0.0" iyz="0.0" ixz="-0.0"/>
  </inertial>
  <visual>
    <origin xyz="0.01225 0.0105 -0.140471" rpy="0 0 0"/>
    <geometry>
      <mesh filename="file://$(find moi_arm_description)/meshes/Component10_1.stl" scale="0.001 0.001 0.001"/>
    </geometry>
    <material name="silver"/>
  </visual>
  <collision>
    <origin xyz="0.01225 0.0105 -0.140471" rpy="0 0 0"/>
    <geometry>
      <mesh filename="file://$(find moi_arm_description)/meshes/Component10_1.stl" scale="0.001 0.001 0.001"/>
    </geometry>
  </collision>
</link>

<link name="Component11_1">
  <inertial>
    <origin xyz="-0.025499995615561606 -0.010489850015523317 0.024038190431412254" rpy="0 0 0"/>
    <mass value="1.3070276306401278"/>
    <inertia ixx="0.00073" iyy="0.000996" izz="0.000968" ixy="0.0" iyz="0.000122" ixz="-0.0"/>
  </inertial>
  <visual>
    <origin xyz="-0.02425 0.001 -0.264471" rpy="0 0 0"/>
    <geometry>
      <mesh filename="file://$(find moi_arm_description)/meshes/Component11_1.stl" scale="0.001 0.001 0.001"/>
    </geometry>
    <material name="silver"/>
  </visual>
  <collision>
    <origin xyz="-0.02425 0.001 -0.264471" rpy="0 0 0"/>
    <geometry>
      <mesh filename="file://$(find moi_arm_description)/meshes/Component11_1.stl" scale="0.001 0.001 0.001"/>
    </geometry>
  </collision>
</link>

<link name="Component3_2">
  <inertial>
    <origin xyz="-0.008000000795058925 -0.0023971512709183643 -0.007982236953474553" rpy="0 0 0"/>
    <mass value="0.02516998505835531"/>
    <inertia ixx="2e-06" iyy="5e-06" izz="4e-06" ixy="0.0" iyz="0.0" ixz="0.0"/>
  </inertial>
  <visual>
    <origin xyz="-0.03855 0.041981 -0.305442" rpy="0 0 0"/>
    <geometry>
      <mesh filename="file://$(find moi_arm_description)/meshes/Component3_2.stl" scale="0.001 0.001 0.001"/>
    </geometry>
    <material name="silver"/>
  </visual>
  <collision>
    <origin xyz="-0.03855 0.041981 -0.305442" rpy="0 0 0"/>
    <geometry>
      <mesh filename="file://$(find moi_arm_description)/meshes/Component3_2.stl" scale="0.001 0.001 0.001"/>
    </geometry>
  </collision>
</link>

<link name="Component3_3">
  <inertial>
    <origin xyz="-0.00800000079505896 -0.002397151270918392 -0.007982236936011355" rpy="0 0 0"/>
    <mass value="0.02516998505835531"/>
    <inertia ixx="2e-06" iyy="5e-06" izz="4e-06" ixy="0.0" iyz="0.0" ixz="0.0"/>
  </inertial>
  <visual>
    <origin xyz="0.02505 0.041981 -0.305442" rpy="0 0 0"/>
    <geometry>
      <mesh filename="file://$(find moi_arm_description)/meshes/Component3_3.stl" scale="0.001 0.001 0.001"/>
    </geometry>
    <material name="silver"/>
  </visual>
  <collision>
    <origin xyz="0.02505 0.041981 -0.305442" rpy="0 0 0"/>
    <geometry>
      <mesh filename="file://$(find moi_arm_description)/meshes/Component3_3.stl" scale="0.001 0.001 0.001"/>
    </geometry>
  </collision>
</link>

<link name="Component5_3">
  <inertial>
    <origin xyz="0.0005767742551684579 2.0749790605179008e-07 2.0905367620338566e-07" rpy="0 0 0"/>
    <mass value="0.013145620261468437"/>
    <inertia ixx="1e-06" iyy="0.0" izz="0.0" ixy="-0.0" iyz="-0.0" ixz="0.0"/>
  </inertial>
  <visual>
    <origin xyz="-0.0485 0.083481 -0.297442" rpy="0 0 0"/>
    <geometry>
      <mesh filename="file://$(find moi_arm_description)/meshes/Component5_3.stl" scale="0.001 0.001 0.001"/>
    </geometry>
    <material name="silver"/>
  </visual>
  <collision>
    <origin xyz="-0.0485 0.083481 -0.297442" rpy="0 0 0"/>
    <geometry>
      <mesh filename="file://$(find moi_arm_description)/meshes/Component5_3.stl" scale="0.001 0.001 0.001"/>
    </geometry>
  </collision>
</link>

<link name="Component6_3">
  <inertial>
    <origin xyz="-0.011000000795072289 0.02153371837175154 -0.009249779194856811" rpy="0 0 0"/>
    <mass value="0.20992105246147483"/>
    <inertia ixx="5e-05" iyy="2e-05" izz="4.7e-05" ixy="0.0" iyz="-0.0" ixz="-0.0"/>
  </inertial>
  <visual>
    <origin xyz="-0.04155 0.092481 -0.306692" rpy="0 0 0"/>
    <geometry>
      <mesh filename="file://$(find moi_arm_description)/meshes/Component6_3.stl" scale="0.001 0.001 0.001"/>
    </geometry>
    <material name="silver"/>
  </visual>
  <collision>
    <origin xyz="-0.04155 0.092481 -0.306692" rpy="0 0 0"/>
    <geometry>
      <mesh filename="file://$(find moi_arm_description)/meshes/Component6_3.stl" scale="0.001 0.001 0.001"/>
    </geometry>
  </collision>
</link>

<link name="Component8_3">
  <inertial>
    <origin xyz="-0.0027779255714870943 0.02245684207839692 -0.009249778320855717" rpy="0 0 0"/>
    <mass value="0.051461187075064724"/>
    <inertia ixx="1.4e-05" iyy="4e-06" izz="1e-05" ixy="0.0" iyz="-0.0" ixz="0.0"/>
  </inertial>
  <visual>
    <origin xyz="-0.01955 0.092481 -0.306692" rpy="0 0 0"/>
    <geometry>
      <mesh filename="file://$(find moi_arm_description)/meshes/Component8_3.stl" scale="0.001 0.001 0.001"/>
    </geometry>
    <material name="silver"/>
  </visual>
  <collision>
    <origin xyz="-0.01955 0.092481 -0.306692" rpy="0 0 0"/>
    <geometry>
      <mesh filename="file://$(find moi_arm_description)/meshes/Component8_3.stl" scale="0.001 0.001 0.001"/>
    </geometry>
  </collision>
</link>

<link name="Component7_3">
  <inertial>
    <origin xyz="-0.0018119639302930923 -0.02115272839676497 -0.007999803812389517" rpy="0 0 0"/>
    <mass value="0.061219272040330903"/>
    <inertia ixx="1.4e-05" iyy="4e-06" izz="1e-05" ixy="-0.0" iyz="-0.0" ixz="0.0"/>
  </inertial>
  <visual>
    <origin xyz="-0.04655 0.047481 -0.305442" rpy="0 0 0"/>
    <geometry>
      <mesh filename="file://$(find moi_arm_description)/meshes/Component7_3.stl" scale="0.001 0.001 0.001"/>
    </geometry>
    <material name="silver"/>
  </visual>
  <collision>
    <origin xyz="-0.04655 0.047481 -0.305442" rpy="0 0 0"/>
    <geometry>
      <mesh filename="file://$(find moi_arm_description)/meshes/Component7_3.stl" scale="0.001 0.001 0.001"/>
    </geometry>
  </collision>
</link>

<link name="Component5_4">
  <inertial>
    <origin xyz="-0.0005767758453047722 2.074973926846635e-07 2.0909572706617752e-07" rpy="0 0 0"/>
    <mass value="0.013145620261468437"/>
    <inertia ixx="1e-06" iyy="0.0" izz="0.0" ixy="0.0" iyz="-0.0" ixz="-0.0"/>
  </inertial>
  <visual>
    <origin xyz="0.051 0.083481 -0.297442" rpy="0 0 0"/>
    <geometry>
      <mesh filename="file://$(find moi_arm_description)/meshes/Component5_4.stl" scale="0.001 0.001 0.001"/>
    </geometry>
    <material name="silver"/>
  </visual>
  <collision>
    <origin xyz="0.051 0.083481 -0.297442" rpy="0 0 0"/>
    <geometry>
      <mesh filename="file://$(find moi_arm_description)/meshes/Component5_4.stl" scale="0.001 0.001 0.001"/>
    </geometry>
  </collision>
</link>

<link name="Component6_4">
  <inertial>
    <origin xyz="0.010999999204936745 0.021533718371751512 -0.009249779177389783" rpy="0 0 0"/>
    <mass value="0.20992105246147483"/>
    <inertia ixx="5e-05" iyy="2e-05" izz="4.7e-05" ixy="-0.0" iyz="-0.0" ixz="-0.0"/>
  </inertial>
  <visual>
    <origin xyz="0.04405 0.092481 -0.306692" rpy="0 0 0"/>
    <geometry>
      <mesh filename="file://$(find moi_arm_description)/meshes/Component6_4.stl" scale="0.001 0.001 0.001"/>
    </geometry>
    <material name="silver"/>
  </visual>
  <collision>
    <origin xyz="0.04405 0.092481 -0.306692" rpy="0 0 0"/>
    <geometry>
      <mesh filename="file://$(find moi_arm_description)/meshes/Component6_4.stl" scale="0.001 0.001 0.001"/>
    </geometry>
  </collision>
</link>

<link name="Component8_4">
  <inertial>
    <origin xyz="0.0027779239813514357 0.02245684207839671 -0.009249778322113822" rpy="0 0 0"/>
    <mass value="0.051461187075064724"/>
    <inertia ixx="1.4e-05" iyy="4e-06" izz="1e-05" ixy="-0.0" iyz="-0.0" ixz="-0.0"/>
  </inertial>
  <visual>
    <origin xyz="0.02205 0.092481 -0.306692" rpy="0 0 0"/>
    <geometry>
      <mesh filename="file://$(find moi_arm_description)/meshes/Component8_4.stl" scale="0.001 0.001 0.001"/>
    </geometry>
    <material name="silver"/>
  </visual>
  <collision>
    <origin xyz="0.02205 0.092481 -0.306692" rpy="0 0 0"/>
    <geometry>
      <mesh filename="file://$(find moi_arm_description)/meshes/Component8_4.stl" scale="0.001 0.001 0.001"/>
    </geometry>
  </collision>
</link>

<link name="Component7_4">
  <inertial>
    <origin xyz="0.0018119623401476256 -0.021152728396815167 -0.007999750225906876" rpy="0 0 0"/>
    <mass value="0.061219272040330903"/>
    <inertia ixx="1.4e-05" iyy="4e-06" izz="1e-05" ixy="0.0" iyz="0.0" ixz="0.0"/>
  </inertial>
  <visual>
    <origin xyz="0.04905 0.047481 -0.305442" rpy="0 0 0"/>
    <geometry>
      <mesh filename="file://$(find moi_arm_description)/meshes/Component7_4.stl" scale="0.001 0.001 0.001"/>
    </geometry>
    <material name="silver"/>
  </visual>
  <collision>
    <origin xyz="0.04905 0.047481 -0.305442" rpy="0 0 0"/>
    <geometry>
      <mesh filename="file://$(find moi_arm_description)/meshes/Component7_4.stl" scale="0.001 0.001 0.001"/>
    </geometry>
  </collision>
</link>

<link name="Component9_2">
  <inertial>
    <origin xyz="-0.053000000837303475 8.647958510688003e-07 0.031048613299398786" rpy="0 0 0"/>
    <mass value="0.7282309507071387"/>
    <inertia ixx="0.000224" iyy="0.000822" izz="0.000727" ixy="-0.0" iyz="-0.0" ixz="0.0"/>
  </inertial>
  <visual>
    <origin xyz="-0.0515 0.083481 -0.297442" rpy="0 0 0"/>
    <geometry>
      <mesh filename="file://$(find moi_arm_description)/meshes/Component9_2.stl" scale="0.001 0.001 0.001"/>
    </geometry>
    <material name="silver"/>
  </visual>
  <collision>
    <origin xyz="-0.0515 0.083481 -0.297442" rpy="0 0 0"/>
    <geometry>
      <mesh filename="file://$(find moi_arm_description)/meshes/Component9_2.stl" scale="0.001 0.001 0.001"/>
    </geometry>
  </collision>
</link>

<link name="Component10_2">
  <inertial>
    <origin xyz="-0.012000117657645493 -0.009499269916191766 0.05294225526470597" rpy="0 0 0"/>
    <mass value="1.0029838563695943"/>
    <inertia ixx="0.001903" iyy="0.002087" izz="0.000249" ixy="-0.0" iyz="0.0" ixz="-0.0"/>
  </inertial>
  <visual>
    <origin xyz="-0.0105 0.072981 -0.350413" rpy="0 0 0"/>
    <geometry>
      <mesh filename="file://$(find moi_arm_description)/meshes/Component10_2.stl" scale="0.001 0.001 0.001"/>
    </geometry>
    <material name="silver"/>
  </visual>
  <collision>
    <origin xyz="-0.0105 0.072981 -0.350413" rpy="0 0 0"/>
    <geometry>
      <mesh filename="file://$(find moi_arm_description)/meshes/Component10_2.stl" scale="0.001 0.001 0.001"/>
    </geometry>
  </collision>
</link>

<link name="Component12_1">
  <inertial>
    <origin xyz="-0.025500001764371456 3.338235568528525e-08 0.003609738501345827" rpy="0 0 0"/>
    <mass value="0.35698450055073755"/>
    <inertia ixx="9.9e-05" iyy="0.000177" izz="0.000181" ixy="0.0" iyz="0.0" ixz="0.0"/>
  </inertial>
  <visual>
    <origin xyz="-0.023 0.082481 -0.474413" rpy="0 0 0"/>
    <geometry>
      <mesh filename="file://$(find moi_arm_description)/meshes/Component12_1.stl" scale="0.001 0.001 0.001"/>
    </geometry>
    <material name="silver"/>
  </visual>
  <collision>
    <origin xyz="-0.023 0.082481 -0.474413" rpy="0 0 0"/>
    <geometry>
      <mesh filename="file://$(find moi_arm_description)/meshes/Component12_1.stl" scale="0.001 0.001 0.001"/>
    </geometry>
  </collision>
</link>

<link name="Component4_2">
  <inertial>
    <origin xyz="-0.008000000670917414 -0.007982460039636222 0.0023970220537695708" rpy="0 0 0"/>
    <mass value="0.02516998505835531"/>
    <inertia ixx="2e-06" iyy="4e-06" izz="5e-06" ixy="0.0" iyz="-0.0" ixz="0.0"/>
  </inertial>
  <visual>
    <origin xyz="-0.0055 0.074481 -0.492806" rpy="0 0 0"/>
    <geometry>
      <mesh filename="file://$(find moi_arm_description)/meshes/Component4_2.stl" scale="0.001 0.001 0.001"/>
    </geometry>
    <material name="silver"/>
  </visual>
  <collision>
    <origin xyz="-0.0055 0.074481 -0.492806" rpy="0 0 0"/>
    <geometry>
      <mesh filename="file://$(find moi_arm_description)/meshes/Component4_2.stl" scale="0.001 0.001 0.001"/>
    </geometry>
  </collision>
</link>

<link name="Component5_5">
  <inertial>
    <origin xyz="0.0005767744058065068 -1.4019937155662632e-08 -3.3672760357816856e-07" rpy="0 0 0"/>
    <mass value="0.013145620261468437"/>
    <inertia ixx="1e-06" iyy="0.0" izz="0.0" ixy="0.0" iyz="0.0" ixz="-0.0"/>
  </inertial>
  <visual>
    <origin xyz="-0.01545 0.082481 -0.534306" rpy="0 0 0"/>
    <geometry>
      <mesh filename="file://$(find moi_arm_description)/meshes/Component5_5.stl" scale="0.001 0.001 0.001"/>
    </geometry>
    <material name="silver"/>
  </visual>
  <collision>
    <origin xyz="-0.01545 0.082481 -0.534306" rpy="0 0 0"/>
    <geometry>
      <mesh filename="file://$(find moi_arm_description)/meshes/Component5_5.stl" scale="0.001 0.001 0.001"/>
    </geometry>
  </collision>
</link>

<link name="Component8_5">
  <inertial>
    <origin xyz="-0.002777925429963366 0.009249998583650346 -0.0224569712862136" rpy="0 0 0"/>
    <mass value="0.051461187075064724"/>
    <inertia ixx="1.4e-05" iyy="1e-05" izz="4e-06" ixy="0.0" iyz="0.0" ixz="-0.0"/>
  </inertial>
  <visual>
    <origin xyz="0.0135 0.091731 -0.543306" rpy="0 0 0"/>
    <geometry>
      <mesh filename="file://$(find moi_arm_description)/meshes/Component8_5.stl" scale="0.001 0.001 0.001"/>
    </geometry>
    <material name="silver"/>
  </visual>
  <collision>
    <origin xyz="0.0135 0.091731 -0.543306" rpy="0 0 0"/>
    <geometry>
      <mesh filename="file://$(find moi_arm_description)/meshes/Component8_5.stl" scale="0.001 0.001 0.001"/>
    </geometry>
  </collision>
</link>

<link name="Component6_5">
  <inertial>
    <origin xyz="-0.011000000652923338 0.009249997718981523 -0.021533847588900423" rpy="0 0 0"/>
    <mass value="0.20992105246147483"/>
    <inertia ixx="5e-05" iyy="4.7e-05" izz="2e-05" ixy="-0.0" iyz="0.0" ixz="-0.0"/>
  </inertial>
  <visual>
    <origin xyz="-0.0085 0.091731 -0.543306" rpy="0 0 0"/>
    <geometry>
      <mesh filename="file://$(find moi_arm_description)/meshes/Component6_5.stl" scale="0.001 0.001 0.001"/>
    </geometry>
    <material name="silver"/>
  </visual>
  <collision>
    <origin xyz="-0.0085 0.091731 -0.543306" rpy="0 0 0"/>
    <geometry>
      <mesh filename="file://$(find moi_arm_description)/meshes/Component6_5.stl" scale="0.001 0.001 0.001"/>
    </geometry>
  </collision>
</link>

<link name="Component7_5">
  <inertial>
    <origin xyz="-0.0018119637897111365 -0.008000026888941511 0.021152599170006336" rpy="0 0 0"/>
    <mass value="0.061219272040330903"/>
    <inertia ixx="1.4e-05" iyy="1e-05" izz="4e-06" ixy="0.0" iyz="0.0" ixz="0.0"/>
  </inertial>
  <visual>
    <origin xyz="-0.0135 0.074481 -0.498306" rpy="0 0 0"/>
    <geometry>
      <mesh filename="file://$(find moi_arm_description)/meshes/Component7_5.stl" scale="0.001 0.001 0.001"/>
    </geometry>
    <material name="silver"/>
  </visual>
  <collision>
    <origin xyz="-0.0135 0.074481 -0.498306" rpy="0 0 0"/>
    <geometry>
      <mesh filename="file://$(find moi_arm_description)/meshes/Component7_5.stl" scale="0.001 0.001 0.001"/>
    </geometry>
  </collision>
</link>

<link name="Component13_1">
  <inertial>
    <origin xyz="-0.15211825499488402 0.018784043229143926 -0.4776890566257409" rpy="0 0 0"/>
    <mass value="1.0315085930732382"/>
    <inertia ixx="0.017798" iyy="0.019327" izz="0.004867" ixy="4.7e-05" iyz="0.000171" ixz="-0.004447"/>
  </inertial>
  <visual>
    <origin xyz="-0.01845 0.082481 -0.534306" rpy="0 0 0"/>
    <geometry>
      <mesh filename="file://$(find moi_arm_description)/meshes/Component13_1.stl" scale="0.001 0.001 0.001"/>
    </geometry>
    <material name="silver"/>
  </visual>
  <collision>
    <origin xyz="-0.01845 0.082481 -0.534306" rpy="0 0 0"/>
    <geometry>
      <mesh filename="file://$(find moi_arm_description)/meshes/Component13_1.stl" scale="0.001 0.001 0.001"/>
    </geometry>
  </collision>
</link>

<link name="Component5_6">
  <inertial>
    <origin xyz="-1.681908239634447e-09 0.0005767607955906827 -2.8295855780680057e-07" rpy="0 0 0"/>
    <mass value="0.013145620261468437"/>
    <inertia ixx="0.0" iyy="1e-06" izz="0.0" ixy="-0.0" iyz="0.0" ixz="-0.0"/>
  </inertial>
  <visual>
    <origin xyz="0.00165 0.026031 -0.534556" rpy="0 0 0"/>
    <geometry>
      <mesh filename="file://$(find moi_arm_description)/meshes/Component5_6.stl" scale="0.001 0.001 0.001"/>
    </geometry>
    <material name="silver"/>
  </visual>
  <collision>
    <origin xyz="0.00165 0.026031 -0.534556" rpy="0 0 0"/>
    <geometry>
      <mesh filename="file://$(find moi_arm_description)/meshes/Component5_6.stl" scale="0.001 0.001 0.001"/>
    </geometry>
  </collision>
</link>

<link name="Component7_6">
  <inertial>
    <origin xyz="0.009250025083460886 0.003188036516552001 -0.02384735112771652" rpy="0 0 0"/>
    <mass value="0.061219272040330903"/>
    <inertia ixx="1e-05" iyy="1.4e-05" izz="4e-06" ixy="-0.0" iyz="0.0" ixz="-0.0"/>
  </inertial>
  <visual>
    <origin xyz="0.0109 0.032981 -0.543556" rpy="0 0 0"/>
    <geometry>
      <mesh filename="file://$(find moi_arm_description)/meshes/Component7_6.stl" scale="0.001 0.001 0.001"/>
    </geometry>
    <material name="silver"/>
  </visual>
  <collision>
    <origin xyz="0.0109 0.032981 -0.543556" rpy="0 0 0"/>
    <geometry>
      <mesh filename="file://$(find moi_arm_description)/meshes/Component7_6.stl" scale="0.001 0.001 0.001"/>
    </geometry>
  </collision>
</link>

<link name="Component6_6">
  <inertial>
    <origin xyz="0.00924999831012794 0.010999997484802126 -0.021533811185405094" rpy="0 0 0"/>
    <mass value="0.20992105246147483"/>
    <inertia ixx="4.7e-05" iyy="5e-05" izz="2e-05" ixy="0.0" iyz="0.0" ixz="-0.0"/>
  </inertial>
  <visual>
    <origin xyz="0.0109 0.054981 -0.543556" rpy="0 0 0"/>
    <geometry>
      <mesh filename="file://$(find moi_arm_description)/meshes/Component6_6.stl" scale="0.001 0.001 0.001"/>
    </geometry>
    <material name="silver"/>
  </visual>
  <collision>
    <origin xyz="0.0109 0.054981 -0.543556" rpy="0 0 0"/>
    <geometry>
      <mesh filename="file://$(find moi_arm_description)/meshes/Component6_6.stl" scale="0.001 0.001 0.001"/>
    </geometry>
  </collision>
</link>

<link name="Component8_6">
  <inertial>
    <origin xyz="0.013499998309469474 0.0022220735730321753 -0.006706947797067597" rpy="0 0 0"/>
    <mass value="0.051461187075064724"/>
    <inertia ixx="1e-05" iyy="1.4e-05" izz="4e-06" ixy="-0.0" iyz="-0.0" ixz="-0.0"/>
  </inertial>
  <visual>
    <origin xyz="0.01515 0.059981 -0.527806" rpy="0 0 0"/>
    <geometry>
      <mesh filename="file://$(find moi_arm_description)/meshes/Component8_6.stl" scale="0.001 0.001 0.001"/>
    </geometry>
    <material name="silver"/>
  </visual>
  <collision>
    <origin xyz="0.01515 0.059981 -0.527806" rpy="0 0 0"/>
    <geometry>
      <mesh filename="file://$(find moi_arm_description)/meshes/Component8_6.stl" scale="0.001 0.001 0.001"/>
    </geometry>
  </collision>
</link>

<joint name="Revolute 1" type="continuous">
  <origin xyz="0.0 0.0 0.043" rpy="0 0 0"/>
  <parent link="base_link"/>
  <child link="Component2_1"/>
  <axis xyz="0.0 0.0 1.0"/>
</joint>

<joint name="Rigid 2" type="fixed">
  <origin xyz="-0.0318 0.008 0.003" rpy="0 0 0"/>
  <parent link="Component2_1"/>
  <child link="Component3_1"/>
</joint>

<joint name="Rigid 3" type="fixed">
  <origin xyz="0.0318 0.008 0.003" rpy="0 0 0"/>
  <parent link="Component2_1"/>
  <child link="Component4_1"/>
</joint>

<joint name="Revolute 6" type="continuous">
  <origin xyz="0.00195 -0.008 0.036" rpy="0 0 0"/>
  <parent link="Component7_1"/>
  <child link="Component5_1"/>
  <axis xyz="1.0 -0.0 0.0"/>
</joint>

<joint name="Rigid 7" type="fixed">
  <origin xyz="0.016 0.0 0.0055" rpy="0 0 0"/>
  <parent link="Component4_1"/>
  <child link="Component7_1"/>
</joint>

<joint name="Rigid 8" type="fixed">
  <origin xyz="-0.022 0.0185 0.0" rpy="0 0 0"/>
  <parent link="Component6_1"/>
  <child link="Component8_1"/>
</joint>

<joint name="Rigid 9" type="fixed">
  <origin xyz="-0.005 -0.01725 0.045" rpy="0 0 0"/>
  <parent link="Component7_1"/>
  <child link="Component6_1"/>
</joint>

<joint name="Revolute 10" type="continuous">
  <origin xyz="-0.00195 0.008 0.036" rpy="0 0 0"/>
  <parent link="Component7_2"/>
  <child link="Component5_2"/>
  <axis xyz="-1.0 -0.0 0.0"/>
</joint>

<joint name="Rigid 11" type="fixed">
  <origin xyz="0.005 -0.00125 0.045" rpy="0 0 0"/>
  <parent link="Component7_2"/>
  <child link="Component6_2"/>
</joint>

<joint name="Rigid 12" type="fixed">
  <origin xyz="0.022 0.0 0.0" rpy="0 0 0"/>
  <parent link="Component6_2"/>
  <child link="Component8_2"/>
</joint>

<joint name="Rigid 13" type="fixed">
  <origin xyz="-0.016 -0.016 0.0055" rpy="0 0 0"/>
  <parent link="Component3_1"/>
  <child link="Component7_2"/>
</joint>

<joint name="Rigid 14" type="fixed">
  <origin xyz="0.003 0.0 0.0" rpy="0 0 0"/>
  <parent link="Component5_1"/>
  <child link="Component9_1"/>
</joint>

<joint name="Rigid 15" type="fixed">
  <origin xyz="-0.065 -0.0105 0.052971" rpy="0 0 0"/>
  <parent link="Component9_1"/>
  <child link="Component10_1"/>
</joint>

<joint name="Rigid 16" type="fixed">
  <origin xyz="0.0365 0.0095 0.124" rpy="0 0 0"/>
  <parent link="Component10_1"/>
  <child link="Component11_1"/>
</joint>

<joint name="Rigid 17" type="fixed">
  <origin xyz="0.0143 -0.040981 0.040971" rpy="0 0 0"/>
  <parent link="Component11_1"/>
  <child link="Component3_2"/>
</joint>

<joint name="Rigid 18" type="fixed">
  <origin xyz="-0.0493 -0.040981 0.040971" rpy="0 0 0"/>
  <parent link="Component11_1"/>
  <child link="Component3_3"/>
</joint>

<joint name="Revolute 19" type="continuous">
  <origin xyz="0.00195 -0.036 -0.008" rpy="0 0 0"/>
  <parent link="Component7_3"/>
  <child link="Component5_3"/>
  <axis xyz="1.0 0.0 -0.0"/>
</joint>

<joint name="Rigid 20" type="fixed">
  <origin xyz="-0.005 -0.045 0.00125" rpy="0 0 0"/>
  <parent link="Component7_3"/>
  <child link="Component6_3"/>
</joint>

<joint name="Rigid 21" type="fixed">
  <origin xyz="-0.022 0.0 0.0" rpy="0 0 0"/>
  <parent link="Component6_3"/>
  <child link="Component8_3"/>
</joint>

<joint name="Rigid 22" type="fixed">
  <origin xyz="0.008 -0.0055 0.0" rpy="0 0 0"/>
  <parent link="Component3_2"/>
  <child link="Component7_3"/>
</joint>

<joint name="Rigid 23" type="fixed">
  <origin xyz="-0.00195 -0.036 -0.008" rpy="0 0 0"/>
  <parent link="Component7_4"/>
  <child link="Component5_4"/>
</joint>

<joint name="Rigid 24" type="fixed">
  <origin xyz="0.005 -0.045 0.00125" rpy="0 0 0"/>
  <parent link="Component7_4"/>
  <child link="Component6_4"/>
</joint>

<joint name="Rigid 25" type="fixed">
  <origin xyz="0.022 0.0 0.0" rpy="0 0 0"/>
  <parent link="Component6_4"/>
  <child link="Component8_4"/>
</joint>

<joint name="Rigid 26" type="fixed">
  <origin xyz="-0.024 -0.0055 0.0" rpy="0 0 0"/>
  <parent link="Component3_3"/>
  <child link="Component7_4"/>
</joint>

<joint name="Rigid 27" type="fixed">
  <origin xyz="0.003 0.0 0.0" rpy="0 0 0"/>
  <parent link="Component5_3"/>
  <child link="Component9_2"/>
</joint>

<joint name="Rigid 28" type="fixed">
  <origin xyz="-0.041 0.0105 0.052971" rpy="0 0 0"/>
  <parent link="Component9_2"/>
  <child link="Component10_2"/>
</joint>

<joint name="Rigid 29" type="fixed">
  <origin xyz="0.0125 -0.0095 0.124" rpy="0 0 0"/>
  <parent link="Component10_2"/>
  <child link="Component12_1"/>
</joint>

<joint name="Rigid 30" type="fixed">
  <origin xyz="-0.0175 0.008 0.018393" rpy="0 0 0"/>
  <parent link="Component12_1"/>
  <child link="Component4_2"/>
</joint>

<joint name="Revolute 31" type="continuous">
  <origin xyz="0.00195 -0.008 0.036" rpy="0 0 0"/>
  <parent link="Component7_5"/>
  <child link="Component5_5"/>
  <axis xyz="1.0 -0.0 -0.0"/>
</joint>

<joint name="Rigid 32" type="fixed">
  <origin xyz="-0.022 0.0 0.0" rpy="0 0 0"/>
  <parent link="Component6_5"/>
  <child link="Component8_5"/>
</joint>

<joint name="Rigid 33" type="fixed">
  <origin xyz="-0.005 -0.01725 0.045" rpy="0 0 0"/>
  <parent link="Component7_5"/>
  <child link="Component6_5"/>
</joint>

<joint name="Rigid 34" type="fixed">
  <origin xyz="0.008 0.0 0.0055" rpy="0 0 0"/>
  <parent link="Component4_2"/>
  <child link="Component7_5"/>
</joint>

<joint name="Rigid 35" type="fixed">
  <origin xyz="0.003 0.0 0.0" rpy="0 0 0"/>
  <parent link="Component5_5"/>
  <child link="Component13_1"/>
</joint>

<joint name="Revolute 36" type="continuous">
  <origin xyz="0.00925 0.00695 -0.009" rpy="0 0 0"/>
  <parent link="Component7_6"/>
  <child link="Component5_6"/>
  <axis xyz="0.0 1.0 1e-06"/>
</joint>

<joint name="Rigid 37" type="fixed">
  <origin xyz="0.0 0.022 0.0" rpy="0 0 0"/>
  <parent link="Component6_6"/>
  <child link="Component7_6"/>
</joint>

<joint name="Rigid 38" type="fixed">
  <origin xyz="0.00425 0.005 0.01575" rpy="0 0 0"/>
  <parent link="Component8_6"/>
  <child link="Component6_6"/>
</joint>

<joint name="Rigid 39" type="fixed">
  <origin xyz="-0.0336 0.0225 -0.0065" rpy="0 0 0"/>
  <parent link="Component13_1"/>
  <child link="Component8_6"/>
</joint>

</robot>
