<?xml version="1.0" ?>
<robot name="moi_arm" xmlns:xacro="http://www.ros.org/wiki/xacro">

<xacro:include filename="$(find moi_arm_description)/urdf/materials.xacro" />
<xacro:include filename="$(find moi_arm_description)/urdf/moi_arm.trans" />
<xacro:include filename="$(find moi_arm_description)/urdf/moi_arm.gazebo" />
<link name="base_link">
  <inertial>
    <origin xyz="-2.3204052621237496e-08 -9.341746626578682e-05 0.007097721551323412" rpy="0 0 0"/>
    <mass value="1.1963019403514967"/>
    <inertia ixx="0.003058" iyy="0.003068" izz="0.005691" ixy="0.0" iyz="-1e-06" ixz="-0.0"/>
  </inertial>
  <visual>
    <origin xyz="0 0 0" rpy="0 0 0"/>
    <geometry>
      <mesh filename="file://$(find moi_arm_description)/meshes/base_link.stl" scale="0.001 0.001 0.001"/>
    </geometry>
    <material name="silver"/>
  </visual>
  <collision>
    <origin xyz="0 0 0" rpy="0 0 0"/>
    <geometry>
      <mesh filename="file://$(find moi_arm_description)/meshes/base_link.stl" scale="0.001 0.001 0.001"/>
    </geometry>
  </collision>
</link>

<link name="Component2_1">
  <inertial>
    <origin xyz="-1.723794702839714e-07 -0.0006862862107224133 0.0014991079387778813" rpy="0 0 0"/>
    <mass value="0.2779523828869321"/>
    <inertia ixx="0.000265" iyy="0.000272" izz="0.000536" ixy="0.0" iyz="0.0" ixz="0.0"/>
  </inertial>
  <visual>
    <origin xyz="-0.0 -0.0 -0.043" rpy="0 0 0"/>
    <geometry>
      <mesh filename="file://$(find moi_arm_description)/meshes/Component2_1.stl" scale="0.001 0.001 0.001"/>
    </geometry>
    <material name="silver"/>
  </visual>
  <collision>
    <origin xyz="-0.0 -0.0 -0.043" rpy="0 0 0"/>
    <geometry>
      <mesh filename="file://$(find moi_arm_description)/meshes/Component2_1.stl" scale="0.001 0.001 0.001"/>
    </geometry>
  </collision>
</link>

<link name="Component3_1">
  <inertial>
    <origin xyz="-5.108764106198649e-11 -0.007982482847528932 0.002397358752411101" rpy="0 0 0"/>
    <mass value="0.02516998505835531"/>
    <inertia ixx="2e-06" iyy="4e-06" izz="5e-06" ixy="0.0" iyz="-0.0" ixz="0.0"/>
  </inertial>
  <visual>
    <origin xyz="0.0318 -0.008 -0.046" rpy="0 0 0"/>
    <geometry>
      <mesh filename="file://$(find moi_arm_description)/meshes/Component3_1.stl" scale="0.001 0.001 0.001"/>
    </geometry>
    <material name="silver"/>
  </visual>
  <collision>
    <origin xyz="0.0318 -0.008 -0.046" rpy="0 0 0"/>
    <geometry>
      <mesh filename="file://$(find moi_arm_description)/meshes/Component3_1.stl" scale="0.001 0.001 0.001"/>
    </geometry>
  </collision>
</link>

<link name="Component4_1">
  <inertial>
    <origin xyz="-5.108793249553045e-11 -0.007982482441365773 0.0023973587524110662" rpy="0 0 0"/>
    <mass value="0.02516998505835531"/>
    <inertia ixx="2e-06" iyy="4e-06" izz="5e-06" ixy="0.0" iyz="-0.0" ixz="0.0"/>
  </inertial>
  <visual>
    <origin xyz="-0.0318 -0.008 -0.046" rpy="0 0 0"/>
    <geometry>
      <mesh filename="file://$(find moi_arm_description)/meshes/Component4_1.stl" scale="0.001 0.001 0.001"/>
    </geometry>
    <material name="silver"/>
  </visual>
  <collision>
    <origin xyz="-0.0318 -0.008 -0.046" rpy="0 0 0"/>
    <geometry>
      <mesh filename="file://$(find moi_arm_description)/meshes/Component4_1.stl" scale="0.001 0.001 0.001"/>
    </geometry>
  </collision>
</link>

<link name="Component5_1">
  <inertial>
    <origin xyz="0.0005767749991517357 2.0306988590679254e-10 5.249550794061975e-13" rpy="0 0 0"/>
    <mass value="0.013145620261468437"/>
    <inertia ixx="1e-06" iyy="0.0" izz="0.0" ixy="-0.0" iyz="-0.0" ixz="0.0"/>
  </inertial>
  <visual>
    <origin xyz="-0.04975 -0.0 -0.0875" rpy="0 0 0"/>
    <geometry>
      <mesh filename="file://$(find moi_arm_description)/meshes/Component5_1.stl" scale="0.001 0.001 0.001"/>
    </geometry>
    <material name="silver"/>
  </visual>
  <collision>
    <origin xyz="-0.04975 -0.0 -0.0875" rpy="0 0 0"/>
    <geometry>
      <mesh filename="file://$(find moi_arm_description)/meshes/Component5_1.stl" scale="0.001 0.001 0.001"/>
    </geometry>
  </collision>
</link>

<link name="Component7_1">
  <inertial>
    <origin xyz="-0.001811963186310439 -0.00800002657181841 0.02115293589470097" rpy="0 0 0"/>
    <mass value="0.061219272040330903"/>
    <inertia ixx="1.4e-05" iyy="1e-05" izz="4e-06" ixy="0.0" iyz="0.0" ixz="0.0"/>
  </inertial>
  <visual>
    <origin xyz="-0.0478 -0.008 -0.0515" rpy="0 0 0"/>
    <geometry>
      <mesh filename="file://$(find moi_arm_description)/meshes/Component7_1.stl" scale="0.001 0.001 0.001"/>
    </geometry>
    <material name="silver"/>
  </visual>
  <collision>
    <origin xyz="-0.0478 -0.008 -0.0515" rpy="0 0 0"/>
    <geometry>
      <mesh filename="file://$(find moi_arm_description)/meshes/Component7_1.stl" scale="0.001 0.001 0.001"/>
    </geometry>
  </collision>
</link>

<link name="Component8_1">
  <inertial>
    <origin xyz="-0.002777924827504729 -0.009249999796888161 -0.022456634580485635" rpy="0 0 0"/>
    <mass value="0.051461187075064724"/>
    <inertia ixx="1.4e-05" iyy="1e-05" izz="4e-06" ixy="0.0" iyz="-0.0" ixz="-0.0"/>
  </inertial>
  <visual>
    <origin xyz="-0.0208 -0.00925 -0.0965" rpy="0 0 0"/>
    <geometry>
      <mesh filename="file://$(find moi_arm_description)/meshes/Component8_1.stl" scale="0.001 0.001 0.001"/>
    </geometry>
    <material name="silver"/>
  </visual>
  <collision>
    <origin xyz="-0.0208 -0.00925 -0.0965" rpy="0 0 0"/>
    <geometry>
      <mesh filename="file://$(find moi_arm_description)/meshes/Component8_1.stl" scale="0.001 0.001 0.001"/>
    </geometry>
  </collision>
</link>

<link name="Component6_1">
  <inertial>
    <origin xyz="-0.011000000051089809 0.009250000203081518 -0.021533510873839742" rpy="0 0 0"/>
    <mass value="0.20992105246147483"/>
    <inertia ixx="5e-05" iyy="4.7e-05" izz="2e-05" ixy="0.0" iyz="-0.0" ixz="0.0"/>
  </inertial>
  <visual>
    <origin xyz="-0.0428 0.00925 -0.0965" rpy="0 0 0"/>
    <geometry>
      <mesh filename="file://$(find moi_arm_description)/meshes/Component6_1.stl" scale="0.001 0.001 0.001"/>
    </geometry>
    <material name="silver"/>
  </visual>
  <collision>
    <origin xyz="-0.0428 0.00925 -0.0965" rpy="0 0 0"/>
    <geometry>
      <mesh filename="file://$(find moi_arm_description)/meshes/Component6_1.stl" scale="0.001 0.001 0.001"/>
    </geometry>
  </collision>
</link>

<link name="Component5_2">
  <inertial>
    <origin xyz="-0.000576775101334262 -2.0306992198904084e-10 5.230954558399503e-13" rpy="0 0 0"/>
    <mass value="0.013145620261468437"/>
    <inertia ixx="1e-06" iyy="0.0" izz="0.0" ixy="-0.0" iyz="0.0" ixz="-0.0"/>
  </inertial>
  <visual>
    <origin xyz="0.04975 0.0 -0.0875" rpy="0 0 0"/>
    <geometry>
      <mesh filename="file://$(find moi_arm_description)/meshes/Component5_2.stl" scale="0.001 0.001 0.001"/>
    </geometry>
    <material name="silver"/>
  </visual>
  <collision>
    <origin xyz="0.04975 0.0 -0.0875" rpy="0 0 0"/>
    <geometry>
      <mesh filename="file://$(find moi_arm_description)/meshes/Component5_2.stl" scale="0.001 0.001 0.001"/>
    </geometry>
  </collision>
</link>

<link name="Component6_2">
  <inertial>
    <origin xyz="0.010999999948906665 0.009249999796918516 -0.021533510873841685" rpy="0 0 0"/>
    <mass value="0.20992105246147483"/>
    <inertia ixx="5e-05" iyy="4.7e-05" izz="2e-05" ixy="-0.0" iyz="0.0" ixz="0.0"/>
  </inertial>
  <visual>
    <origin xyz="0.0428 0.00925 -0.0965" rpy="0 0 0"/>
    <geometry>
      <mesh filename="file://$(find moi_arm_description)/meshes/Component6_2.stl" scale="0.001 0.001 0.001"/>
    </geometry>
    <material name="silver"/>
  </visual>
  <collision>
    <origin xyz="0.0428 0.00925 -0.0965" rpy="0 0 0"/>
    <geometry>
      <mesh filename="file://$(find moi_arm_description)/meshes/Component6_2.stl" scale="0.001 0.001 0.001"/>
    </geometry>
  </collision>
</link>

<link name="Component8_2">
  <inertial>
    <origin xyz="0.0027779247253222235 0.009249999796888243 -0.022456634580487425" rpy="0 0 0"/>
    <mass value="0.051461187075064724"/>
    <inertia ixx="1.4e-05" iyy="1e-05" izz="4e-06" ixy="0.0" iyz="0.0" ixz="0.0"/>
  </inertial>
  <visual>
    <origin xyz="0.0208 0.00925 -0.0965" rpy="0 0 0"/>
    <geometry>
      <mesh filename="file://$(find moi_arm_description)/meshes/Component8_2.stl" scale="0.001 0.001 0.001"/>
    </geometry>
    <material name="silver"/>
  </visual>
  <collision>
    <origin xyz="0.0208 0.00925 -0.0965" rpy="0 0 0"/>
    <geometry>
      <mesh filename="file://$(find moi_arm_description)/meshes/Component8_2.stl" scale="0.001 0.001 0.001"/>
    </geometry>
  </collision>
</link>

<link name="Component7_2">
  <inertial>
    <origin xyz="0.0018119630841314932 0.00800002657181839 0.021152935894701345" rpy="0 0 0"/>
    <mass value="0.061219272040330903"/>
    <inertia ixx="1.4e-05" iyy="1e-05" izz="4e-06" ixy="0.0" iyz="-0.0" ixz="-0.0"/>
  </inertial>
  <visual>
    <origin xyz="0.0478 0.008 -0.0515" rpy="0 0 0"/>
    <geometry>
      <mesh filename="file://$(find moi_arm_description)/meshes/Component7_2.stl" scale="0.001 0.001 0.001"/>
    </geometry>
    <material name="silver"/>
  </visual>
  <collision>
    <origin xyz="0.0478 0.008 -0.0515" rpy="0 0 0"/>
    <geometry>
      <mesh filename="file://$(find moi_arm_description)/meshes/Component7_2.stl" scale="0.001 0.001 0.001"/>
    </geometry>
  </collision>
</link>

<link name="Component9_1">
  <inertial>
    <origin xyz="-0.05300000011434975 6.865823318272569e-07 0.03104840421136143" rpy="0 0 0"/>
    <mass value="0.7282309507071387"/>
    <inertia ixx="0.000224" iyy="0.000822" izz="0.000727" ixy="-0.0" iyz="-0.0" ixz="0.0"/>
  </inertial>
  <visual>
    <origin xyz="-0.05275 -0.0 -0.0875" rpy="0 0 0"/>
    <geometry>
      <mesh filename="file://$(find moi_arm_description)/meshes/Component9_1.stl" scale="0.001 0.001 0.001"/>
    </geometry>
    <material name="silver"/>
  </visual>
  <collision>
    <origin xyz="-0.05275 -0.0 -0.0875" rpy="0 0 0"/>
    <geometry>
      <mesh filename="file://$(find moi_arm_description)/meshes/Component9_1.stl" scale="0.001 0.001 0.001"/>
    </geometry>
  </collision>
</link>

<joint name="Revolute 1" type="continuous">
  <origin xyz="0.0 0.0 0.043" rpy="0 0 0"/>
  <parent link="base_link"/>
  <child link="Component2_1"/>
  <axis xyz="0.0 0.0 1.0"/>
</joint>

<joint name="Rigid 2" type="fixed">
  <origin xyz="-0.0318 0.008 0.003" rpy="0 0 0"/>
  <parent link="Component2_1"/>
  <child link="Component3_1"/>
</joint>

<joint name="Rigid 3" type="fixed">
  <origin xyz="0.0318 0.008 0.003" rpy="0 0 0"/>
  <parent link="Component2_1"/>
  <child link="Component4_1"/>
</joint>

<joint name="Revolute 6" type="continuous">
  <origin xyz="0.00195 -0.008 0.036" rpy="0 0 0"/>
  <parent link="Component7_1"/>
  <child link="Component5_1"/>
  <axis xyz="1.0 -0.0 0.0"/>
</joint>

<joint name="Rigid 7" type="fixed">
  <origin xyz="0.016 0.0 0.0055" rpy="0 0 0"/>
  <parent link="Component4_1"/>
  <child link="Component7_1"/>
</joint>

<joint name="Rigid 8" type="fixed">
  <origin xyz="-0.022 0.0185 0.0" rpy="0 0 0"/>
  <parent link="Component6_1"/>
  <child link="Component8_1"/>
</joint>

<joint name="Rigid 9" type="fixed">
  <origin xyz="-0.005 -0.01725 0.045" rpy="0 0 0"/>
  <parent link="Component7_1"/>
  <child link="Component6_1"/>
</joint>

<joint name="Revolute 10" type="continuous">
  <origin xyz="-0.00195 0.008 0.036" rpy="0 0 0"/>
  <parent link="Component7_2"/>
  <child link="Component5_2"/>
  <axis xyz="-1.0 -0.0 0.0"/>
</joint>

<joint name="Rigid 11" type="fixed">
  <origin xyz="0.005 -0.00125 0.045" rpy="0 0 0"/>
  <parent link="Component7_2"/>
  <child link="Component6_2"/>
</joint>

<joint name="Rigid 12" type="fixed">
  <origin xyz="0.022 0.0 0.0" rpy="0 0 0"/>
  <parent link="Component6_2"/>
  <child link="Component8_2"/>
</joint>

<joint name="Rigid 13" type="fixed">
  <origin xyz="-0.016 -0.016 0.0055" rpy="0 0 0"/>
  <parent link="Component3_1"/>
  <child link="Component7_2"/>
</joint>

<joint name="Rigid 14" type="fixed">
  <origin xyz="0.003 0.0 0.0" rpy="0 0 0"/>
  <parent link="Component5_1"/>
  <child link="Component9_1"/>
</joint>

</robot>
