<?xml version="1.0" ?>
<robot name="Assemble_URDF_WS" xmlns:xacro="http://www.ros.org/wiki/xacro">

<xacro:include filename="$(find Assemble_URDF_WS_description)/urdf/materials.xacro" />
<xacro:include filename="$(find Assemble_URDF_WS_description)/urdf/Assemble_URDF_WS.trans" />
<xacro:include filename="$(find Assemble_URDF_WS_description)/urdf/Assemble_URDF_WS.gazebo" />
<link name="base_link">
  <inertial>
    <origin xyz="-2.3204052621237496e-08 -9.341746626578682e-05 0.007097721551323412" rpy="0 0 0"/>
    <mass value="1.1963019403514967"/>
    <inertia ixx="0.003058" iyy="0.003068" izz="0.005691" ixy="0.0" iyz="-1e-06" ixz="-0.0"/>
  </inertial>
  <visual>
    <origin xyz="0 0 0" rpy="0 0 0"/>
    <geometry>
      <mesh filename="package://Assemble_URDF_WS_description/meshes/base_link.stl" scale="0.001 0.001 0.001"/>
    </geometry>
    <material name="silver"/>
  </visual>
  <collision>
    <origin xyz="0 0 0" rpy="0 0 0"/>
    <geometry>
      <mesh filename="package://Assemble_URDF_WS_description/meshes/base_link.stl" scale="0.001 0.001 0.001"/>
    </geometry>
  </collision>
</link>

<link name="Component2_1">
  <inertial>
    <origin xyz="-1.723794702839714e-07 -0.0006862862107224133 0.0014991079387778813" rpy="0 0 0"/>
    <mass value="0.2779523828869321"/>
    <inertia ixx="0.000265" iyy="0.000272" izz="0.000536" ixy="0.0" iyz="0.0" ixz="0.0"/>
  </inertial>
  <visual>
    <origin xyz="-0.0 -0.0 -0.043" rpy="0 0 0"/>
    <geometry>
      <mesh filename="package://Assemble_URDF_WS_description/meshes/Component2_1.stl" scale="0.001 0.001 0.001"/>
    </geometry>
    <material name="silver"/>
  </visual>
  <collision>
    <origin xyz="-0.0 -0.0 -0.043" rpy="0 0 0"/>
    <geometry>
      <mesh filename="package://Assemble_URDF_WS_description/meshes/Component2_1.stl" scale="0.001 0.001 0.001"/>
    </geometry>
  </collision>
</link>

<joint name="Revolute 1" type="continuous">
  <origin xyz="0.0 0.0 0.043" rpy="0 0 0"/>
  <parent link="base_link"/>
  <child link="Component2_1"/>
  <axis xyz="0.0 0.0 1.0"/>
</joint>

</robot>
