<?xml version="1.0" ?>
<robot name="mycobot" xmlns:xacro="http://www.ros.org/wiki/xacro">

<xacro:include filename="$(find mycobot_description)/urdf/materials.xacro" />
<xacro:include filename="$(find mycobot_description)/urdf/mycobot.trans" />
<xacro:include filename="$(find mycobot_description)/urdf/mycobot.gazebo" />
<link name="base_link">
  <inertial>
    <origin xyz="-1.3994637957346424e-08 -0.013751224256395762 0.04886454507234413" rpy="0 0 0"/>
    <mass value="12.899764355948896"/>
    <inertia ixx="0.033823" iyy="0.028162" izz="0.035033" ixy="0.0" iyz="-0.000755" ixz="0.0"/>
  </inertial>
  <visual>
    <origin xyz="0 0 0" rpy="0 0 0"/>
    <geometry>
      <mesh filename="file://$(find mycobot_description)/meshes/base_link.stl" scale="0.001 0.001 0.001"/>
    </geometry>
    <material name="silver"/>
  </visual>
  <collision>
    <origin xyz="0 0 0" rpy="0 0 0"/>
    <geometry>
      <mesh filename="file://$(find mycobot_description)/meshes/base_link.stl" scale="0.001 0.001 0.001"/>
    </geometry>
  </collision>
</link>

<link name="link1_1">
  <inertial>
    <origin xyz="0.006896766224730428 4.7445558334983536e-17 0.055490186869056476" rpy="0 0 0"/>
    <mass value="3.4735206294395446"/>
    <inertia ixx="0.004461" iyy="0.004757" izz="0.002424" ixy="-0.0" iyz="0.0" ixz="-0.000777"/>
  </inertial>
  <visual>
    <origin xyz="-0.0 -0.0 -0.11" rpy="0 0 0"/>
    <geometry>
      <mesh filename="file://$(find mycobot_description)/meshes/link1_1.stl" scale="0.001 0.001 0.001"/>
    </geometry>
    <material name="silver"/>
  </visual>
  <collision>
    <origin xyz="-0.0 -0.0 -0.11" rpy="0 0 0"/>
    <geometry>
      <mesh filename="file://$(find mycobot_description)/meshes/link1_1.stl" scale="0.001 0.001 0.001"/>
    </geometry>
  </collision>
</link>

<link name="link2_1">
  <inertial>
    <origin xyz="0.03690658575567249 -1.0444649911926371e-16 0.06800000000000012" rpy="0 0 0"/>
    <mass value="5.91988968680626"/>
    <inertia ixx="0.0188" iyy="0.019335" izz="0.004161" ixy="0.0" iyz="0.0" ixz="0.0"/>
  </inertial>
  <visual>
    <origin xyz="-0.045 -0.0 -0.195" rpy="0 0 0"/>
    <geometry>
      <mesh filename="file://$(find mycobot_description)/meshes/link2_1.stl" scale="0.001 0.001 0.001"/>
    </geometry>
    <material name="silver"/>
  </visual>
  <collision>
    <origin xyz="-0.045 -0.0 -0.195" rpy="0 0 0"/>
    <geometry>
      <mesh filename="file://$(find mycobot_description)/meshes/link2_1.stl" scale="0.001 0.001 0.001"/>
    </geometry>
  </collision>
</link>

<link name="link3_1">
  <inertial>
    <origin xyz="-0.035022688252992054 -8.56731250465993e-16 0.049500000000000155" rpy="0 0 0"/>
    <mass value="4.802107093668197"/>
    <inertia ixx="0.01014" iyy="0.010584" izz="0.003386" ixy="-0.0" iyz="0.0" ixz="-0.0"/>
  </inertial>
  <visual>
    <origin xyz="-0.045 0.0 -0.331" rpy="0 0 0"/>
    <geometry>
      <mesh filename="file://$(find mycobot_description)/meshes/link3_1.stl" scale="0.001 0.001 0.001"/>
    </geometry>
    <material name="silver"/>
  </visual>
  <collision>
    <origin xyz="-0.045 0.0 -0.331" rpy="0 0 0"/>
    <geometry>
      <mesh filename="file://$(find mycobot_description)/meshes/link3_1.stl" scale="0.001 0.001 0.001"/>
    </geometry>
  </collision>
</link>

<link name="link4_1">
  <inertial>
    <origin xyz="0.03442387286919234 -1.62263567395975e-15 0.010576127130807855" rpy="0 0 0"/>
    <mass value="2.265107015236222"/>
    <inertia ixx="0.001595" iyy="0.001803" izz="0.001595" ixy="0.0" iyz="0.0" ixz="-0.000324"/>
  </inertial>
  <visual>
    <origin xyz="-0.045 0.0 -0.43" rpy="0 0 0"/>
    <geometry>
      <mesh filename="file://$(find mycobot_description)/meshes/link4_1.stl" scale="0.001 0.001 0.001"/>
    </geometry>
    <material name="silver"/>
  </visual>
  <collision>
    <origin xyz="-0.045 0.0 -0.43" rpy="0 0 0"/>
    <geometry>
      <mesh filename="file://$(find mycobot_description)/meshes/link4_1.stl" scale="0.001 0.001 0.001"/>
    </geometry>
  </collision>
</link>

<link name="link5_1">
  <inertial>
    <origin xyz="4.163336342344337e-17 -2.2870367877634065e-15 0.04211669650613381" rpy="0 0 0"/>
    <mass value="3.029827579494103"/>
    <inertia ixx="0.0025" iyy="0.002976" izz="0.002441" ixy="0.0" iyz="0.0" ixz="0.0"/>
  </inertial>
  <visual>
    <origin xyz="-0.09 0.0 -0.475" rpy="0 0 0"/>
    <geometry>
      <mesh filename="file://$(find mycobot_description)/meshes/link5_1.stl" scale="0.001 0.001 0.001"/>
    </geometry>
    <material name="silver"/>
  </visual>
  <collision>
    <origin xyz="-0.09 0.0 -0.475" rpy="0 0 0"/>
    <geometry>
      <mesh filename="file://$(find mycobot_description)/meshes/link5_1.stl" scale="0.001 0.001 0.001"/>
    </geometry>
  </collision>
</link>

<link name="link6_1">
  <inertial>
    <origin xyz="0.010000000000000009 -2.29263991248323e-15 0.0" rpy="0 0 0"/>
    <mass value="0.6042068071016569"/>
    <inertia ixx="0.00037" iyy="0.000205" izz="0.000205" ixy="0.0" iyz="0.0" ixz="-0.0"/>
  </inertial>
  <visual>
    <origin xyz="-0.13 0.0 -0.525" rpy="0 0 0"/>
    <geometry>
      <mesh filename="file://$(find mycobot_description)/meshes/link6_1.stl" scale="0.001 0.001 0.001"/>
    </geometry>
    <material name="silver"/>
  </visual>
  <collision>
    <origin xyz="-0.13 0.0 -0.525" rpy="0 0 0"/>
    <geometry>
      <mesh filename="file://$(find mycobot_description)/meshes/link6_1.stl" scale="0.001 0.001 0.001"/>
    </geometry>
  </collision>
</link>

<link name="gripper_base_1">
  <inertial>
    <origin xyz="0.0355664843149987 -0.0001756055492085692 0.008326821944589002" rpy="0 0 0"/>
    <mass value="0.5510932173775136"/>
    <inertia ixx="0.000508" iyy="0.00049" izz="0.000702" ixy="0.0" iyz="0.0" ixz="-0.000104"/>
  </inertial>
  <visual>
    <origin xyz="-0.15 0.0 -0.525" rpy="0 0 0"/>
    <geometry>
      <mesh filename="file://$(find mycobot_description)/meshes/gripper_base_1.stl" scale="0.001 0.001 0.001"/>
    </geometry>
    <material name="silver"/>
  </visual>
  <collision>
    <origin xyz="-0.15 0.0 -0.525" rpy="0 0 0"/>
    <geometry>
      <mesh filename="file://$(find mycobot_description)/meshes/gripper_base_1.stl" scale="0.001 0.001 0.001"/>
    </geometry>
  </collision>
</link>

<link name="gripper_right3_1">
  <inertial>
    <origin xyz="0.015989567569339613 0.012966960169895517 0.0035542407438502455" rpy="0 0 0"/>
    <mass value="0.09058559783383817"/>
    <inertia ixx="1.8e-05" iyy="3.3e-05" izz="5e-05" ixy="-1.8e-05" iyz="-0.0" ixz="-0.0"/>
  </inertial>
  <visual>
    <origin xyz="-0.21039 -0.01822 -0.528642" rpy="0 0 0"/>
    <geometry>
      <mesh filename="file://$(find mycobot_description)/meshes/gripper_right3_1.stl" scale="0.001 0.001 0.001"/>
    </geometry>
    <material name="silver"/>
  </visual>
  <collision>
    <origin xyz="-0.21039 -0.01822 -0.528642" rpy="0 0 0"/>
    <geometry>
      <mesh filename="file://$(find mycobot_description)/meshes/gripper_right3_1.stl" scale="0.001 0.001 0.001"/>
    </geometry>
  </collision>
</link>

<link name="gripper_right1_1">
  <inertial>
    <origin xyz="0.011064466442332721 0.005257573311972401 0.00355996955743465" rpy="0 0 0"/>
    <mass value="0.09298578687165746"/>
    <inertia ixx="1e-05" iyy="3.5e-05" izz="4.2e-05" ixy="1.3e-05" iyz="0.0" ixz="-0.0"/>
  </inertial>
  <visual>
    <origin xyz="-0.261438 -0.051225 -0.52874" rpy="0 0 0"/>
    <geometry>
      <mesh filename="file://$(find mycobot_description)/meshes/gripper_right1_1.stl" scale="0.001 0.001 0.001"/>
    </geometry>
    <material name="silver"/>
  </visual>
  <collision>
    <origin xyz="-0.261438 -0.051225 -0.52874" rpy="0 0 0"/>
    <geometry>
      <mesh filename="file://$(find mycobot_description)/meshes/gripper_right1_1.stl" scale="0.001 0.001 0.001"/>
    </geometry>
  </collision>
</link>

<link name="gripper_left3_1">
  <inertial>
    <origin xyz="0.0159904266297618 -0.012967523057109649 0.0034753903195801072" rpy="0 0 0"/>
    <mass value="0.09059526730883281"/>
    <inertia ixx="1.8e-05" iyy="3.3e-05" izz="5e-05" ixy="1.8e-05" iyz="0.0" ixz="-0.0"/>
  </inertial>
  <visual>
    <origin xyz="-0.21039 0.01846 -0.528642" rpy="0 0 0"/>
    <geometry>
      <mesh filename="file://$(find mycobot_description)/meshes/gripper_left3_1.stl" scale="0.001 0.001 0.001"/>
    </geometry>
    <material name="silver"/>
  </visual>
  <collision>
    <origin xyz="-0.21039 0.01846 -0.528642" rpy="0 0 0"/>
    <geometry>
      <mesh filename="file://$(find mycobot_description)/meshes/gripper_left3_1.stl" scale="0.001 0.001 0.001"/>
    </geometry>
  </collision>
</link>

<link name="gripper_left1_1">
  <inertial>
    <origin xyz="0.011053309239177689 -0.0052536917643599065 0.003636608039289002" rpy="0 0 0"/>
    <mass value="0.09307370524687981"/>
    <inertia ixx="1e-05" iyy="3.5e-05" izz="4.2e-05" ixy="-1.3e-05" iyz="0.0" ixz="0.0"/>
  </inertial>
  <visual>
    <origin xyz="-0.261438 0.051465 -0.528642" rpy="0 0 0"/>
    <geometry>
      <mesh filename="file://$(find mycobot_description)/meshes/gripper_left1_1.stl" scale="0.001 0.001 0.001"/>
    </geometry>
    <material name="silver"/>
  </visual>
  <collision>
    <origin xyz="-0.261438 0.051465 -0.528642" rpy="0 0 0"/>
    <geometry>
      <mesh filename="file://$(find mycobot_description)/meshes/gripper_left1_1.stl" scale="0.001 0.001 0.001"/>
    </geometry>
  </collision>
</link>


<!-- joint -->

<joint name="joint1" type="revolute">
  <origin xyz="0.0 0.0 0.11" rpy="0 0 0"/>
  <parent link="base_link"/>
  <child link="link1_1"/>
  <axis xyz="0.0 0.0 1.0"/>
  <limit upper="2.792527" lower="-2.792527" effort="100" velocity="100"/>
</joint>

<joint name="joint2" type="revolute">
  <origin xyz="0.045 0.0 0.085" rpy="0 0 0"/>
  <parent link="link1_1"/>
  <child link="link2_1"/>
  <axis xyz="1.0 0.0 0.0"/>
  <limit upper="2.792527" lower="-2.792527" effort="100" velocity="100"/>
</joint>

<joint name="joint3" type="revolute">
  <origin xyz="0.0 -0.0 0.136" rpy="0 0 0"/>
  <parent link="link2_1"/>
  <child link="link3_1"/>
  <axis xyz="-1.0 -0.0 -0.0"/>
  <limit upper="2.792527" lower="-2.792527" effort="100" velocity="100"/>
</joint>

<joint name="joint4" type="revolute">
  <origin xyz="0.0 0.0 0.099" rpy="0 0 0"/>
  <parent link="link3_1"/>
  <child link="link4_1"/>
  <axis xyz="1.0 -0.0 -0.0"/>
  <limit upper="2.792527" lower="-2.792527" effort="100" velocity="100"/>
</joint>

<joint name="joint5" type="revolute">
  <origin xyz="0.045 0.0 0.045" rpy="0 0 0"/>
  <parent link="link4_1"/>
  <child link="link5_1"/>
  <axis xyz="-0.0 -0.0 1.0"/>
  <limit upper="2.792527" lower="-2.792527" effort="100" velocity="100"/>
</joint>

<joint name="joint6" type="revolute">
  <origin xyz="0.04 0.0 0.05" rpy="0 0 0"/>
  <parent link="link5_1"/>
  <child link="link6_1"/>
  <axis xyz="1.0 0.0 0.0"/>
  <limit upper="2.792527" lower="-2.792527" effort="100" velocity="100"/>
</joint>

<joint name="gripper_base_to_link6" type="fixed">
  <origin xyz="0.02 0.0 0.0" rpy="0 0 0"/>
  <parent link="link6_1"/>
  <child link="gripper_base_1"/>
</joint>

<joint name="right3_to_base" type="revolute">
  <origin xyz="0.06039 0.01822 0.003642" rpy="0 0 0"/>
  <parent link="gripper_base_1"/>
  <child link="gripper_right3_1"/>
  <axis xyz="0.0 0.0 -1.0"/>
  <limit upper="0.698132" lower="0.0" effort="100" velocity="100"/>
</joint>

<joint name="right1_to_right3" type="revolute">
  <origin xyz="0.051048 0.033005 9.8e-05" rpy="0 0 0"/>
  <parent link="gripper_right3_1"/>
  <child link="gripper_right1_1"/>
  <axis xyz="-0.0 -0.0 -1.0"/>
  <limit upper="0.0" lower="-0.698132" effort="100" velocity="100"/>
</joint>

<joint name="left3_to_base" type="revolute">
  <origin xyz="0.06039 -0.01846 0.003642" rpy="0 0 0"/>
  <parent link="gripper_base_1"/>
  <child link="gripper_left3_1"/>
  <axis xyz="0.0 0.0 -1.0"/>
  <limit upper="0.0" lower="-0.698132" effort="100" velocity="100"/>
</joint>

<joint name="left1_to_left3" type="revolute">
  <origin xyz="0.051048 -0.033005 0.0" rpy="0 0 0"/>
  <parent link="gripper_left3_1"/>
  <child link="gripper_left1_1"/>
  <axis xyz="-0.0 -0.0 -1.0"/>
  <limit upper="0.698132" lower="0.0" effort="100" velocity="100"/>
</joint>

</robot>
