<?xml version="1.0" ?>
<robot name="mycobot" xmlns:xacro="http://www.ros.org/wiki/xacro">

<xacro:include filename="$(find mycobot_description)/urdf/materials.xacro" />
<xacro:include filename="$(find mycobot_description)/urdf/mycobot.trans" />
<xacro:include filename="$(find mycobot_description)/urdf/mycobot.gazebo" />
<link name="base_link">
  <inertial>
    <origin xyz="-1.3994637957346424e-08 0.046320428630226694 0.053625500753973876" rpy="0 0 0"/>
    <mass value="12.899764355948896"/>
    <inertia ixx="0.033823" iyy="0.028162" izz="0.035033" ixy="0.0" iyz="-0.000755" ixz="0.0"/>
  </inertial>
  <visual>
    <origin xyz="0 0 0" rpy="0 0 0"/>
    <geometry>
      <mesh filename="file://$(find mycobot_description)/meshes/base_link.stl" scale="0.001 0.001 0.001"/>
    </geometry>
    <material name="silver"/>
  </visual>
  <collision>
    <origin xyz="0 0 0" rpy="0 0 0"/>
    <geometry>
      <mesh filename="file://$(find mycobot_description)/meshes/base_link.stl" scale="0.001 0.001 0.001"/>
    </geometry>
  </collision>
</link>

<link name="link1_1">
  <inertial>
    <origin xyz="1.7818903264329774e-17 -0.006897113338107677 0.05549014255068621" rpy="0 0 0"/>
    <mass value="3.4735206294395446"/>
    <inertia ixx="0.004757" iyy="0.004461" izz="0.002424" ixy="-0.0" iyz="0.000777" ixz="0.0"/>
  </inertial>
  <visual>
    <origin xyz="0.0 -0.060072 -0.114761" rpy="0 0 0"/>
    <geometry>
      <mesh filename="file://$(find mycobot_description)/meshes/link1_1.stl" scale="0.001 0.001 0.001"/>
    </geometry>
    <material name="silver"/>
  </visual>
  <collision>
    <origin xyz="0.0 -0.060072 -0.114761" rpy="0 0 0"/>
    <geometry>
      <mesh filename="file://$(find mycobot_description)/meshes/link1_1.stl" scale="0.001 0.001 0.001"/>
    </geometry>
  </collision>
</link>

<link name="link2_1">
  <inertial>
    <origin xyz="3.6106292522153246e-16 -0.03690693286904952 0.06799995568162978" rpy="0 0 0"/>
    <mass value="5.91988968680626"/>
    <inertia ixx="0.019335" iyy="0.0188" izz="0.004161" ixy="-0.0" iyz="-0.0" ixz="-0.0"/>
  </inertial>
  <visual>
    <origin xyz="-0.0 -0.015072 -0.199761" rpy="0 0 0"/>
    <geometry>
      <mesh filename="file://$(find mycobot_description)/meshes/link2_1.stl" scale="0.001 0.001 0.001"/>
    </geometry>
    <material name="silver"/>
  </visual>
  <collision>
    <origin xyz="-0.0 -0.015072 -0.199761" rpy="0 0 0"/>
    <geometry>
      <mesh filename="file://$(find mycobot_description)/meshes/link2_1.stl" scale="0.001 0.001 0.001"/>
    </geometry>
  </collision>
</link>

<link name="link3_1">
  <inertial>
    <origin xyz="4.97742590851401e-16 0.035022341139615054 0.04949995568162946" rpy="0 0 0"/>
    <mass value="4.802107093668197"/>
    <inertia ixx="0.010584" iyy="0.01014" izz="0.003386" ixy="-0.0" iyz="-0.0" ixz="-0.0"/>
  </inertial>
  <visual>
    <origin xyz="-0.0 -0.015072 -0.335761" rpy="0 0 0"/>
    <geometry>
      <mesh filename="file://$(find mycobot_description)/meshes/link3_1.stl" scale="0.001 0.001 0.001"/>
    </geometry>
    <material name="silver"/>
  </visual>
  <collision>
    <origin xyz="-0.0 -0.015072 -0.335761" rpy="0 0 0"/>
    <geometry>
      <mesh filename="file://$(find mycobot_description)/meshes/link3_1.stl" scale="0.001 0.001 0.001"/>
    </geometry>
  </collision>
</link>

<link name="link4_1">
  <inertial>
    <origin xyz="-0.010576127130807278 -0.0344242199825693 -4.431837047347287e-08" rpy="0 0 0"/>
    <mass value="2.265107015236222"/>
    <inertia ixx="0.001595" iyy="0.001595" izz="0.001803" ixy="-0.000324" iyz="0.0" ixz="0.0"/>
  </inertial>
  <visual>
    <origin xyz="-0.0 -0.015072 -0.434761" rpy="0 0 0"/>
    <geometry>
      <mesh filename="file://$(find mycobot_description)/meshes/link4_1.stl" scale="0.001 0.001 0.001"/>
    </geometry>
    <material name="silver"/>
  </visual>
  <collision>
    <origin xyz="-0.0 -0.015072 -0.434761" rpy="0 0 0"/>
    <geometry>
      <mesh filename="file://$(find mycobot_description)/meshes/link4_1.stl" scale="0.001 0.001 0.001"/>
    </geometry>
  </collision>
</link>

<link name="link5_1">
  <inertial>
    <origin xyz="-0.04211669650613323 -3.4711337686468835e-07 -4.431837019591711e-08" rpy="0 0 0"/>
    <mass value="3.029827579494103"/>
    <inertia ixx="0.002441" iyy="0.002976" izz="0.0025" ixy="-0.0" iyz="0.0" ixz="-0.0"/>
  </inertial>
  <visual>
    <origin xyz="0.045 0.029928 -0.434761" rpy="0 0 0"/>
    <geometry>
      <mesh filename="file://$(find mycobot_description)/meshes/link5_1.stl" scale="0.001 0.001 0.001"/>
    </geometry>
    <material name="silver"/>
  </visual>
  <collision>
    <origin xyz="0.045 0.029928 -0.434761" rpy="0 0 0"/>
    <geometry>
      <mesh filename="file://$(find mycobot_description)/meshes/link5_1.stl" scale="0.001 0.001 0.001"/>
    </geometry>
  </collision>
</link>

<link name="link6_1">
  <inertial>
    <origin xyz="1.0130785099704553e-15 -3.4711337656284647e-07 0.009999955681629924" rpy="0 0 0"/>
    <mass value="0.6042068071016569"/>
    <inertia ixx="0.000205" iyy="0.000205" izz="0.00037" ixy="0.0" iyz="0.0" ixz="0.0"/>
  </inertial>
  <visual>
    <origin xyz="0.095 0.029928 -0.474761" rpy="0 0 0"/>
    <geometry>
      <mesh filename="file://$(find mycobot_description)/meshes/link6_1.stl" scale="0.001 0.001 0.001"/>
    </geometry>
    <material name="silver"/>
  </visual>
  <collision>
    <origin xyz="0.095 0.029928 -0.474761" rpy="0 0 0"/>
    <geometry>
      <mesh filename="file://$(find mycobot_description)/meshes/link6_1.stl" scale="0.001 0.001 0.001"/>
    </geometry>
  </collision>
</link>

<link name="gripper_left1_1">
  <inertial>
    <origin xyz="-0.0001366249032619532 -0.005254043045734361 0.011053276993410743" rpy="0 0 0"/>
    <mass value="0.09307370524691048"/>
    <inertia ixx="4.2e-05" iyy="3.5e-05" izz="1e-05" ixy="-0.0" iyz="-1.3e-05" ixz="-0.0"/>
  </inertial>
  <visual>
    <origin xyz="0.102142 0.081393 -0.613499" rpy="0 0 0"/>
    <geometry>
      <mesh filename="file://$(find mycobot_description)/meshes/gripper_left1_1.stl" scale="0.001 0.001 0.001"/>
    </geometry>
    <material name="silver"/>
  </visual>
  <collision>
    <origin xyz="0.102142 0.081393 -0.613499" rpy="0 0 0"/>
    <geometry>
      <mesh filename="file://$(find mycobot_description)/meshes/gripper_left1_1.stl" scale="0.001 0.001 0.001"/>
    </geometry>
  </collision>
</link>

<link name="gripper_right1_1">
  <inertial>
    <origin xyz="-0.003559993355084029 0.0052572280801808785 0.01106444201439416" rpy="0 0 0"/>
    <mass value="0.09298578687164809"/>
    <inertia ixx="4.2e-05" iyy="3.5e-05" izz="1e-05" ixy="-0.0" iyz="1.3e-05" ixz="0.0"/>
  </inertial>
  <visual>
    <origin xyz="0.09874 -0.021297 -0.613499" rpy="0 0 0"/>
    <geometry>
      <mesh filename="file://$(find mycobot_description)/meshes/gripper_right1_1.stl" scale="0.001 0.001 0.001"/>
    </geometry>
    <material name="silver"/>
  </visual>
  <collision>
    <origin xyz="0.09874 -0.021297 -0.613499" rpy="0 0 0"/>
    <geometry>
      <mesh filename="file://$(find mycobot_description)/meshes/gripper_right1_1.stl" scale="0.001 0.001 0.001"/>
    </geometry>
  </collision>
</link>

<link name="gripper_left3_1">
  <inertial>
    <origin xyz="-0.0034754158555415915 -0.012967874127836669 0.015990398580496223" rpy="0 0 0"/>
    <mass value="0.09059526730883062"/>
    <inertia ixx="5e-05" iyy="3.3e-05" izz="1.8e-05" ixy="-0.0" iyz="1.8e-05" ixz="0.0"/>
  </inertial>
  <visual>
    <origin xyz="0.098642 0.048388 -0.562451" rpy="0 0 0"/>
    <geometry>
      <mesh filename="file://$(find mycobot_description)/meshes/gripper_left3_1.stl" scale="0.001 0.001 0.001"/>
    </geometry>
    <material name="silver"/>
  </visual>
  <collision>
    <origin xyz="0.098642 0.048388 -0.562451" rpy="0 0 0"/>
    <geometry>
      <mesh filename="file://$(find mycobot_description)/meshes/gripper_left3_1.stl" scale="0.001 0.001 0.001"/>
    </geometry>
  </collision>
</link>

<link name="gripper_right3_1">
  <inertial>
    <origin xyz="-0.003554270079364527 0.012966613242614462 0.015989544526951893" rpy="0 0 0"/>
    <mass value="0.09058559783383588"/>
    <inertia ixx="5e-05" iyy="3.3e-05" izz="1.8e-05" ixy="0.0" iyz="-1.8e-05" ixz="0.0"/>
  </inertial>
  <visual>
    <origin xyz="0.098642 0.011708 -0.562451" rpy="0 0 0"/>
    <geometry>
      <mesh filename="file://$(find mycobot_description)/meshes/gripper_right3_1.stl" scale="0.001 0.001 0.001"/>
    </geometry>
    <material name="silver"/>
  </visual>
  <collision>
    <origin xyz="0.098642 0.011708 -0.562451" rpy="0 0 0"/>
    <geometry>
      <mesh filename="file://$(find mycobot_description)/meshes/gripper_right3_1.stl" scale="0.001 0.001 0.001"/>
    </geometry>
  </collision>
</link>

<link name="gripper_right2_1">
  <inertial>
    <origin xyz="0.00039513624853279583 0.020889826569867473 0.029939946177009458" rpy="0 0 0"/>
    <mass value="0.052277285993114625"/>
    <inertia ixx="2e-05" iyy="1.6e-05" izz="6e-06" ixy="1e-06" iyz="-8e-06" ixz="1e-06"/>
  </inertial>
  <visual>
    <origin xyz="0.091652 -0.014364 -0.540136" rpy="0 0 0"/>
    <geometry>
      <mesh filename="file://$(find mycobot_description)/meshes/gripper_right2_1.stl" scale="0.001 0.001 0.001"/>
    </geometry>
    <material name="silver"/>
  </visual>
  <collision>
    <origin xyz="0.091652 -0.014364 -0.540136" rpy="0 0 0"/>
    <geometry>
      <mesh filename="file://$(find mycobot_description)/meshes/gripper_right2_1.stl" scale="0.001 0.001 0.001"/>
    </geometry>
  </collision>
</link>

<link name="gripper_left2_1">
  <inertial>
    <origin xyz="-0.0008827491284652406 -0.022109126086089753 0.031838470444806144" rpy="0 0 0"/>
    <mass value="0.05612369952823852"/>
    <inertia ixx="2.1e-05" iyy="1.7e-05" izz="6e-06" ixy="-1e-06" iyz="8e-06" ixz="2e-06"/>
  </inertial>
  <visual>
    <origin xyz="0.091152 0.07442 -0.540136" rpy="0 0 0"/>
    <geometry>
      <mesh filename="file://$(find mycobot_description)/meshes/gripper_left2_1.stl" scale="0.001 0.001 0.001"/>
    </geometry>
    <material name="silver"/>
  </visual>
  <collision>
    <origin xyz="0.091152 0.07442 -0.540136" rpy="0 0 0"/>
    <geometry>
      <mesh filename="file://$(find mycobot_description)/meshes/gripper_left2_1.stl" scale="0.001 0.001 0.001"/>
    </geometry>
  </collision>
</link>

<link name="Intel_Realsense_D435_1">
  <inertial>
    <origin xyz="4.8416324475247796e-05 1.5146157620500589e-06 0.012170147496942119" rpy="0 0 0"/>
    <mass value="0.37837987585794863"/>
    <inertia ixx="0.00024" iyy="3.5e-05" izz="0.000238" ixy="-0.0" iyz="0.0" ixz="-0.0"/>
  </inertial>
  <visual>
    <origin xyz="0.1715 0.029928 -0.515261" rpy="0 0 0"/>
    <geometry>
      <mesh filename="file://$(find mycobot_description)/meshes/Intel_Realsense_D435_1.stl" scale="0.001 0.001 0.001"/>
    </geometry>
    <material name="silver"/>
  </visual>
  <collision>
    <origin xyz="0.1715 0.029928 -0.515261" rpy="0 0 0"/>
    <geometry>
      <mesh filename="file://$(find mycobot_description)/meshes/Intel_Realsense_D435_1.stl" scale="0.001 0.001 0.001"/>
    </geometry>
  </collision>
</link>

<link name="camera_lens_1">
  <inertial>
    <origin xyz="5.828670879282072e-16 -3.471133768022383e-07 0.002499955681630084" rpy="0 0 0"/>
    <mass value="0.005587442390099658"/>
    <inertia ixx="0.0" iyy="0.0" izz="0.0" ixy="-0.0" iyz="-0.0" ixz="-0.0"/>
  </inertial>
  <visual>
    <origin xyz="0.1715 0.029928 -0.510261" rpy="0 0 0"/>
    <geometry>
      <mesh filename="file://$(find mycobot_description)/meshes/camera_lens_1.stl" scale="0.001 0.001 0.001"/>
    </geometry>
    <material name="silver"/>
  </visual>
  <collision>
    <origin xyz="0.1715 0.029928 -0.510261" rpy="0 0 0"/>
    <geometry>
      <mesh filename="file://$(find mycobot_description)/meshes/camera_lens_1.stl" scale="0.001 0.001 0.001"/>
    </geometry>
  </collision>
</link>

<link name="camera_base_1">
  <inertial>
    <origin xyz="-0.05015355610844302 -3.4709671254545826e-07 0.0077187807175594925" rpy="0 0 0"/>
    <mass value="0.8317896891157319"/>
    <inertia ixx="0.000358" iyy="0.001054" izz="0.001357" ixy="-0.0" iyz="0.0" ixz="7.9e-05"/>
  </inertial>
  <visual>
    <origin xyz="0.095 0.029928 -0.494761" rpy="0 0 0"/>
    <geometry>
      <mesh filename="file://$(find mycobot_description)/meshes/camera_base_1.stl" scale="0.001 0.001 0.001"/>
    </geometry>
    <material name="silver"/>
  </visual>
  <collision>
    <origin xyz="0.095 0.029928 -0.494761" rpy="0 0 0"/>
    <geometry>
      <mesh filename="file://$(find mycobot_description)/meshes/camera_base_1.stl" scale="0.001 0.001 0.001"/>
    </geometry>
  </collision>
</link>

<link name="gripper_base_1">
  <inertial>
    <origin xyz="-0.00832560984189655 -0.00017587337145155008 0.035565756605193344" rpy="0 0 0"/>
    <mass value="0.5510932173751233"/>
    <inertia ixx="0.000703" iyy="0.00049" izz="0.000509" ixy="-0.0" iyz="0.0" ixz="0.000104"/>
  </inertial>
  <visual>
    <origin xyz="0.095 0.029928 -0.502061" rpy="0 0 0"/>
    <geometry>
      <mesh filename="file://$(find mycobot_description)/meshes/gripper_base_1.stl" scale="0.001 0.001 0.001"/>
    </geometry>
    <material name="silver"/>
  </visual>
  <collision>
    <origin xyz="0.095 0.029928 -0.502061" rpy="0 0 0"/>
    <geometry>
      <mesh filename="file://$(find mycobot_description)/meshes/gripper_base_1.stl" scale="0.001 0.001 0.001"/>
    </geometry>
  </collision>
</link>

<joint name="joint2_to_joint1" type="revolute">
  <origin xyz="0.0 0.060072 0.114761" rpy="0 0 0"/>
  <parent link="base_link"/>
  <child link="link1_1"/>
  <axis xyz="-0.0 0.0 1.0"/>
  <limit upper="6.283185" lower="0.0" effort="100" velocity="100"/>
</joint>

<joint name="joint3_to_joint2" type="continuous">
  <origin xyz="0.0 -0.045 0.085" rpy="0 0 0"/>
  <parent link="link1_1"/>
  <child link="link2_1"/>
  <axis xyz="-0.0 -1.0 0.0"/>
</joint>

<joint name="joint4_to_joint3" type="continuous">
  <origin xyz="0.0 0.0 0.136" rpy="0 0 0"/>
  <parent link="link2_1"/>
  <child link="link3_1"/>
  <axis xyz="0.0 1.0 -0.0"/>
</joint>

<joint name="joint5_to_joint4" type="continuous">
  <origin xyz="0.0 0.0 0.099" rpy="0 0 0"/>
  <parent link="link3_1"/>
  <child link="link4_1"/>
  <axis xyz="-0.0 -1.0 0.0"/>
</joint>

<joint name="joint6_to_joint5" type="continuous">
  <origin xyz="-0.045 -0.045 0.0" rpy="0 0 0"/>
  <parent link="link4_1"/>
  <child link="link5_1"/>
  <axis xyz="-1.0 0.0 0.0"/>
</joint>

<joint name="joint6output_to_joint6" type="continuous">
  <origin xyz="-0.05 0.0 0.04" rpy="0 0 0"/>
  <parent link="link5_1"/>
  <child link="link6_1"/>
  <axis xyz="0.0 0.0 1.0"/>
</joint>

<joint name="gripper_left3_to_gripper_left1" type="revolute">
  <origin xyz="-0.0035 -0.033005 0.051048" rpy="0 0 0"/>
  <parent link="gripper_left3_1"/>
  <child link="gripper_left1_1"/>
  <axis xyz="-1.0 0.0 0.0"/>
  <limit upper="0.0" lower="-0.698132" effort="100" velocity="100"/>
</joint>

<joint name="gripper_right3_to_gripper_right1" type="revolute">
  <origin xyz="-9.8e-05 0.033005 0.051048" rpy="0 0 0"/>
  <parent link="gripper_right3_1"/>
  <child link="gripper_right1_1"/>
  <axis xyz="1.0 0.0 -0.0"/>
  <limit upper="0.698132" lower="0.0" effort="100" velocity="100"/>
</joint>

<joint name="gripper_base_to_gripper_left3" type="revolute">
  <origin xyz="-0.003642 -0.01846 0.06039" rpy="0 0 0"/>
  <parent link="gripper_base_1"/>
  <child link="gripper_left3_1"/>
  <axis xyz="1.0 0.0 -0.0"/>
  <limit upper="0.0" lower="-0.698132" effort="100" velocity="100"/>
</joint>

<joint name="gripper_controller" type="revolute">
  <origin xyz="-0.003642 0.01822 0.06039" rpy="0 0 0"/>
  <parent link="gripper_base_1"/>
  <child link="gripper_right3_1"/>
  <axis xyz="1.0 0.0 -0.0"/>
  <limit upper="0.698132" lower="0.0" effort="100" velocity="100"/>
</joint>

<joint name="gripper_base_to_gripper_right2" type="revolute">
  <origin xyz="0.003348 0.044292 0.038075" rpy="0 0 0"/>
  <parent link="gripper_base_1"/>
  <child link="gripper_right2_1"/>
  <axis xyz="1.0 0.0 -0.0"/>
  <limit upper="0.698132" lower="0.0" effort="100" velocity="100"/>
</joint>

<joint name="gripper_base_to_gripper_left2" type="revolute">
  <origin xyz="0.003848 -0.044492 0.038075" rpy="0 0 0"/>
  <parent link="gripper_base_1"/>
  <child link="gripper_left2_1"/>
  <axis xyz="-1.0 -0.0 0.0"/>
  <limit upper="0.698132" lower="0.0" effort="100" velocity="100"/>
</joint>

<joint name="lens_to_D435" type="fixed">
  <origin xyz="0.0 0.0 0.005" rpy="0 0 0"/>
  <parent link="camera_lens_1"/>
  <child link="Intel_Realsense_D435_1"/>
</joint>

<joint name="camera_base_to_lens" type="fixed">
  <origin xyz="-0.0765 0.0 0.0155" rpy="0 0 0"/>
  <parent link="camera_base_1"/>
  <child link="camera_lens_1"/>
</joint>

<joint name="link6_to_camera_base" type="fixed">
  <origin xyz="0.0 0.0 0.02" rpy="0 0 0"/>
  <parent link="link6_1"/>
  <child link="camera_base_1"/>
</joint>

<joint name="camera_base_to_gripper_base" type="fixed">
  <origin xyz="0.0 0.0 0.0073" rpy="0 0 0"/>
  <parent link="camera_base_1"/>
  <child link="gripper_base_1"/>
</joint>

</robot>
