<?xml version="1.0" ?>
<robot name="mycobot320" xmlns:xacro="http://www.ros.org/wiki/xacro">

<xacro:include filename="$(find mycobot320_description)/urdf/materials.xacro" />
<xacro:include filename="$(find mycobot320_description)/urdf/mycobot320.trans" />
<xacro:include filename="$(find mycobot320_description)/urdf/mycobot320.gazebo" />
<link name="base_link">
  <inertial>
    <origin xyz="-1.3994637957346424e-08 0.046320428630226694 0.053625500753973876" rpy="0 0 0"/>
    <mass value="12.899764355948896"/>
    <inertia ixx="0.033823" iyy="0.028162" izz="0.035033" ixy="0.0" iyz="-0.000755" ixz="0.0"/>
  </inertial>
  <visual>
    <origin xyz="0 0 0" rpy="0 0 0"/>
    <geometry>
      <mesh filename="file://$(find mycobot320_description)/meshes/base_link.stl" scale="0.001 0.001 0.001"/>
    </geometry>
    <material name="silver"/>
  </visual>
  <collision>
    <origin xyz="0 0 0" rpy="0 0 0"/>
    <geometry>
      <mesh filename="file://$(find mycobot320_description)/meshes/base_link.stl" scale="0.001 0.001 0.001"/>
    </geometry>
  </collision>
</link>

<link name="link1_1">
  <inertial>
    <origin xyz="0.0068967662247303866 -3.47113377312247e-07 0.055490142550686156" rpy="0 0 0"/>
    <mass value="3.4735206294395446"/>
    <inertia ixx="0.004461" iyy="0.004757" izz="0.002424" ixy="0.0" iyz="0.0" ixz="-0.000777"/>
  </inertial>
  <visual>
    <origin xyz="0.0 -0.060072 -0.114761" rpy="0 0 0"/>
    <geometry>
      <mesh filename="file://$(find mycobot320_description)/meshes/link1_1.stl" scale="0.001 0.001 0.001"/>
    </geometry>
    <material name="silver"/>
  </visual>
  <collision>
    <origin xyz="0.0 -0.060072 -0.114761" rpy="0 0 0"/>
    <geometry>
      <mesh filename="file://$(find mycobot320_description)/meshes/link1_1.stl" scale="0.001 0.001 0.001"/>
    </geometry>
  </collision>
</link>

<link name="link2_1">
  <inertial>
    <origin xyz="0.036906585755672516 -3.4711337715265245e-07 0.06799995568162967" rpy="0 0 0"/>
    <mass value="5.91988968680626"/>
    <inertia ixx="0.0188" iyy="0.019335" izz="0.004161" ixy="0.0" iyz="-0.0" ixz="0.0"/>
  </inertial>
  <visual>
    <origin xyz="-0.045 -0.060072 -0.199761" rpy="0 0 0"/>
    <geometry>
      <mesh filename="file://$(find mycobot320_description)/meshes/link2_1.stl" scale="0.001 0.001 0.001"/>
    </geometry>
    <material name="silver"/>
  </visual>
  <collision>
    <origin xyz="-0.045 -0.060072 -0.199761" rpy="0 0 0"/>
    <geometry>
      <mesh filename="file://$(find mycobot320_description)/meshes/link2_1.stl" scale="0.001 0.001 0.001"/>
    </geometry>
  </collision>
</link>

<link name="link3_1">
  <inertial>
    <origin xyz="-0.03502268825299208 3.0162871079368603e-05 0.04949994627901161" rpy="0 0 0"/>
    <mass value="4.802107093668197"/>
    <inertia ixx="0.01014" iyy="0.010584" izz="0.003386" ixy="0.0" iyz="-4e-06" ixz="0.0"/>
  </inertial>
  <visual>
    <origin xyz="-0.045 -0.060072 -0.335761" rpy="0 0 0"/>
    <geometry>
      <mesh filename="file://$(find mycobot320_description)/meshes/link3_1.stl" scale="0.001 0.001 0.001"/>
    </geometry>
    <material name="silver"/>
  </visual>
  <collision>
    <origin xyz="-0.045 -0.060072 -0.335761" rpy="0 0 0"/>
    <geometry>
      <mesh filename="file://$(find mycobot320_description)/meshes/link3_1.stl" scale="0.001 0.001 0.001"/>
    </geometry>
  </collision>
</link>

<link name="link4_1">
  <inertial>
    <origin xyz="0.034423872869192323 6.191592391645295e-06 0.010576061998245623" rpy="0 0 0"/>
    <mass value="2.265107015236222"/>
    <inertia ixx="0.001595" iyy="0.001803" izz="0.001595" ixy="-0.0" iyz="-0.0" ixz="-0.000324"/>
  </inertial>
  <visual>
    <origin xyz="-0.045 -0.060133 -0.434761" rpy="0 0 0"/>
    <geometry>
      <mesh filename="file://$(find mycobot320_description)/meshes/link4_1.stl" scale="0.001 0.001 0.001"/>
    </geometry>
    <material name="silver"/>
  </visual>
  <collision>
    <origin xyz="-0.045 -0.060133 -0.434761" rpy="0 0 0"/>
    <geometry>
      <mesh filename="file://$(find mycobot320_description)/meshes/link4_1.stl" scale="0.001 0.001 0.001"/>
    </geometry>
  </collision>
</link>

<link name="link5_1">
  <inertial>
    <origin xyz="5.551115123125783e-17 2.6368392026507315e-05 0.04211661683454615" rpy="0 0 0"/>
    <mass value="3.029827579494103"/>
    <inertia ixx="0.0025" iyy="0.002976" izz="0.002441" ixy="0.0" iyz="-0.0" ixz="0.0"/>
  </inertial>
  <visual>
    <origin xyz="-0.09 -0.06016 -0.479761" rpy="0 0 0"/>
    <geometry>
      <mesh filename="file://$(find mycobot320_description)/meshes/link5_1.stl" scale="0.001 0.001 0.001"/>
    </geometry>
    <material name="silver"/>
  </visual>
  <collision>
    <origin xyz="-0.09 -0.06016 -0.479761" rpy="0 0 0"/>
    <geometry>
      <mesh filename="file://$(find mycobot320_description)/meshes/link5_1.stl" scale="0.001 0.001 0.001"/>
    </geometry>
  </collision>
</link>

<link name="link6_1">
  <inertial>
    <origin xyz="0.010000000000000203 2.2737115904641891e-07 -8.116903615906779e-08" rpy="0 0 0"/>
    <mass value="0.6042068071016569"/>
    <inertia ixx="0.00037" iyy="0.000205" izz="0.000205" ixy="0.0" iyz="0.0" ixz="0.0"/>
  </inertial>
  <visual>
    <origin xyz="-0.13 -0.060191 -0.529761" rpy="0 0 0"/>
    <geometry>
      <mesh filename="file://$(find mycobot320_description)/meshes/link6_1.stl" scale="0.001 0.001 0.001"/>
    </geometry>
    <material name="silver"/>
  </visual>
  <collision>
    <origin xyz="-0.13 -0.060191 -0.529761" rpy="0 0 0"/>
    <geometry>
      <mesh filename="file://$(find mycobot320_description)/meshes/link6_1.stl" scale="0.001 0.001 0.001"/>
    </geometry>
  </collision>
</link>

<link name="gripper_right2_1">
  <inertial>
    <origin xyz="0.033798632816854496 0.022462244408999882 0.0023600870145860098" rpy="0 0 0"/>
    <mass value="0.05940572970223047"/>
    <inertia ixx="6e-06" iyy="1.8e-05" izz="2.1e-05" ixy="-7e-06" iyz="-1e-06" ixz="-2e-06"/>
  </inertial>
  <visual>
    <origin xyz="-0.188135 -0.10458 -0.524876" rpy="0 0 0"/>
    <geometry>
      <mesh filename="file://$(find mycobot320_description)/meshes/gripper_right2_1.stl" scale="0.001 0.001 0.001"/>
    </geometry>
    <material name="silver"/>
  </visual>
  <collision>
    <origin xyz="-0.188135 -0.10458 -0.524876" rpy="0 0 0"/>
    <geometry>
      <mesh filename="file://$(find mycobot320_description)/meshes/gripper_right2_1.stl" scale="0.001 0.001 0.001"/>
    </geometry>
  </collision>
</link>

<link name="gripper_right3_1">
  <inertial>
    <origin xyz="0.015740982452355612 0.012145444586910983 -0.0033499396529519387" rpy="0 0 0"/>
    <mass value="0.08857210300231054"/>
    <inertia ixx="1.6e-05" iyy="3.3e-05" izz="4.8e-05" ixy="-1.6e-05" iyz="-0.0" ixz="-0.0"/>
  </inertial>
  <visual>
    <origin xyz="-0.2105 -0.078518 -0.540192" rpy="0 0 0"/>
    <geometry>
      <mesh filename="file://$(find mycobot320_description)/meshes/gripper_right3_1.stl" scale="0.001 0.001 0.001"/>
    </geometry>
    <material name="silver"/>
  </visual>
  <collision>
    <origin xyz="-0.2105 -0.078518 -0.540192" rpy="0 0 0"/>
    <geometry>
      <mesh filename="file://$(find mycobot320_description)/meshes/gripper_right3_1.stl" scale="0.001 0.001 0.001"/>
    </geometry>
  </collision>
</link>

<link name="gripper_left3_1">
  <inertial>
    <origin xyz="0.015692604770214558 -0.01214986348116125 -0.003642405326841902" rpy="0 0 0"/>
    <mass value="0.08842063664845465"/>
    <inertia ixx="1.6e-05" iyy="3.3e-05" izz="4.8e-05" ixy="1.6e-05" iyz="-0.0" ixz="0.0"/>
  </inertial>
  <visual>
    <origin xyz="-0.2105 -0.041878 -0.540214" rpy="0 0 0"/>
    <geometry>
      <mesh filename="file://$(find mycobot320_description)/meshes/gripper_left3_1.stl" scale="0.001 0.001 0.001"/>
    </geometry>
    <material name="silver"/>
  </visual>
  <collision>
    <origin xyz="-0.2105 -0.041878 -0.540214" rpy="0 0 0"/>
    <geometry>
      <mesh filename="file://$(find mycobot320_description)/meshes/gripper_left3_1.stl" scale="0.001 0.001 0.001"/>
    </geometry>
  </collision>
</link>

<link name="gripper_left2_1">
  <inertial>
    <origin xyz="0.03246595180129472 -0.022600862626259908 -9.99896592168703e-06" rpy="0 0 0"/>
    <mass value="0.05597691822827368"/>
    <inertia ixx="6e-06" iyy="1.6e-05" izz="2e-05" ixy="7e-06" iyz="1e-06" ixz="-2e-06"/>
  </inertial>
  <visual>
    <origin xyz="-0.188135 -0.015798 -0.52743" rpy="0 0 0"/>
    <geometry>
      <mesh filename="file://$(find mycobot320_description)/meshes/gripper_left2_1.stl" scale="0.001 0.001 0.001"/>
    </geometry>
    <material name="silver"/>
  </visual>
  <collision>
    <origin xyz="-0.188135 -0.015798 -0.52743" rpy="0 0 0"/>
    <geometry>
      <mesh filename="file://$(find mycobot320_description)/meshes/gripper_left2_1.stl" scale="0.001 0.001 0.001"/>
    </geometry>
  </collision>
</link>

<link name="gripper_base_1">
  <inertial>
    <origin xyz="0.04130149101827388 5.6062904992743023e-05 -0.010030403559479262" rpy="0 0 0"/>
    <mass value="1.169410692896674"/>
    <inertia ixx="0.000963" iyy="0.000961" izz="0.001227" ixy="1e-06" iyz="0.0" ixz="6.1e-05"/>
  </inertial>
  <visual>
    <origin xyz="-0.15 -0.060191 -0.529761" rpy="0 0 0"/>
    <geometry>
      <mesh filename="file://$(find mycobot320_description)/meshes/gripper_base_1.stl" scale="0.001 0.001 0.001"/>
    </geometry>
    <material name="silver"/>
  </visual>
  <collision>
    <origin xyz="-0.15 -0.060191 -0.529761" rpy="0 0 0"/>
    <geometry>
      <mesh filename="file://$(find mycobot320_description)/meshes/gripper_base_1.stl" scale="0.001 0.001 0.001"/>
    </geometry>
  </collision>
</link>

<link name="gripper_left1_1">
  <inertial>
    <origin xyz="0.011567740835341844 -0.00512808706657175 0.003657274411978828" rpy="0 0 0"/>
    <mass value="0.09121097238098812"/>
    <inertia ixx="1e-05" iyy="3.3e-05" izz="4e-05" ixy="-1.3e-05" iyz="0.0" ixz="0.0"/>
  </inertial>
  <visual>
    <origin xyz="-0.261578 -0.010914 -0.532793" rpy="0 0 0"/>
    <geometry>
      <mesh filename="file://$(find mycobot320_description)/meshes/gripper_left1_1.stl" scale="0.001 0.001 0.001"/>
    </geometry>
    <material name="silver"/>
  </visual>
  <collision>
    <origin xyz="-0.261578 -0.010914 -0.532793" rpy="0 0 0"/>
    <geometry>
      <mesh filename="file://$(find mycobot320_description)/meshes/gripper_left1_1.stl" scale="0.001 0.001 0.001"/>
    </geometry>
  </collision>
</link>

<link name="gripper_right1_1">
  <inertial>
    <origin xyz="0.011567729805010085 0.00512811259080212 -0.0036581710499368203" rpy="0 0 0"/>
    <mass value="0.09121095459991281"/>
    <inertia ixx="1e-05" iyy="3.3e-05" izz="4e-05" ixy="1.3e-05" iyz="0.0" ixz="-0.0"/>
  </inertial>
  <visual>
    <origin xyz="-0.261578 -0.109477 -0.540614" rpy="0 0 0"/>
    <geometry>
      <mesh filename="file://$(find mycobot320_description)/meshes/gripper_right1_1.stl" scale="0.001 0.001 0.001"/>
    </geometry>
    <material name="silver"/>
  </visual>
  <collision>
    <origin xyz="-0.261578 -0.109477 -0.540614" rpy="0 0 0"/>
    <geometry>
      <mesh filename="file://$(find mycobot320_description)/meshes/gripper_right1_1.stl" scale="0.001 0.001 0.001"/>
    </geometry>
  </collision>
</link>

<joint name="joint2_to_joint1" type="continuous">
  <origin xyz="0.0 0.060072 0.114761" rpy="0 0 0"/>
  <parent link="base_link"/>
  <child link="link1_1"/>
  <axis xyz="-0.0 0.0 1.0"/>
</joint>

<joint name="joint3_to_joint2" type="continuous">
  <origin xyz="0.045 0.0 0.085" rpy="0 0 0"/>
  <parent link="link1_1"/>
  <child link="link2_1"/>
  <axis xyz="1.0 0.0 0.0"/>
</joint>

<joint name="joint4_to_joint3" type="continuous">
  <origin xyz="0.0 0.0 0.136" rpy="0 0 0"/>
  <parent link="link2_1"/>
  <child link="link3_1"/>
  <axis xyz="-1.0 0.0 -0.0"/>
</joint>

<joint name="joint5_to_joint4" type="continuous">
  <origin xyz="0.0 6.1e-05 0.099" rpy="0 0 0"/>
  <parent link="link3_1"/>
  <child link="link4_1"/>
  <axis xyz="1.0 -0.0 0.0"/>
</joint>

<joint name="joint6_to_joint5" type="continuous">
  <origin xyz="0.045 2.7e-05 0.045" rpy="0 0 0"/>
  <parent link="link4_1"/>
  <child link="link5_1"/>
  <axis xyz="-0.0 0.000616 1.0"/>
</joint>

<joint name="joint6output_to_joint6" type="continuous">
  <origin xyz="0.04 3.1e-05 0.05" rpy="0 0 0"/>
  <parent link="link5_1"/>
  <child link="link6_1"/>
  <axis xyz="1.0 -0.0 0.0"/>
</joint>

<joint name="gripper_base_to_gripper_right2" type="revolute">
  <origin xyz="0.038135 0.044389 -0.004885" rpy="0 0 0"/>
  <parent link="gripper_base_1"/>
  <child link="gripper_right2_1"/>
  <axis xyz="-0.0 0.000616 1.0"/>
  <limit upper="0.698132" lower="0.0" effort="100" velocity="100"/>
</joint>

<joint name="gripper_controller" type="revolute">
  <origin xyz="0.0605 0.018327 0.010431" rpy="0 0 0"/>
  <parent link="gripper_base_1"/>
  <child link="gripper_right3_1"/>
  <axis xyz="-0.0 0.000616 1.0"/>
  <limit upper="0.698132" lower="0.0" effort="100" velocity="100"/>
</joint>

<joint name="gripper_base_to_gripper_left3" type="revolute">
  <origin xyz="0.0605 -0.018313 0.010453" rpy="0 0 0"/>
  <parent link="gripper_base_1"/>
  <child link="gripper_left3_1"/>
  <axis xyz="-0.0 0.000616 1.0"/>
  <limit upper="0.0" lower="-0.698132" effort="100" velocity="100"/>
</joint>

<joint name="gripper_base_to_gripper_left2" type="revolute">
  <origin xyz="0.038135 -0.044393 -0.002331" rpy="0 0 0"/>
  <parent link="gripper_base_1"/>
  <child link="gripper_left2_1"/>
  <axis xyz="-0.0 0.000616 1.0"/>
  <limit upper="0.0" lower="-0.698132" effort="100" velocity="100"/>
</joint>

<joint name="Rigid 47" type="fixed">
  <origin xyz="0.02 0.0 0.0" rpy="0 0 0"/>
  <parent link="link6_1"/>
  <child link="gripper_base_1"/>
</joint>

<joint name="Revolute 50" type="revolute">
  <origin xyz="0.051078 -0.030964 -0.007421" rpy="0 0 0"/>
  <parent link="gripper_left3_1"/>
  <child link="gripper_left1_1"/>
  <axis xyz="0.0 -0.000616 -1.0"/>
  <limit upper="0.698132" lower="0.0" effort="100" velocity="100"/>
</joint>

<joint name="Revolute 51" type="revolute">
  <origin xyz="0.051078 0.030959 0.000422" rpy="0 0 0"/>
  <parent link="gripper_right3_1"/>
  <child link="gripper_right1_1"/>
  <axis xyz="-0.0 0.000616 1.0"/>
  <limit upper="0.0" lower="-0.698132" effort="100" velocity="100"/>
</joint>

</robot>
