<?xml version="1.0" ?>
<robot name="Untitled" xmlns:xacro="http://www.ros.org/wiki/xacro">

<xacro:include filename="$(find Untitled_description)/urdf/materials.xacro" />
<xacro:include filename="$(find Untitled_description)/urdf/Untitled.trans" />
<xacro:include filename="$(find Untitled_description)/urdf/Untitled.gazebo" />
<link name="base_link">
  <inertial>
    <origin xyz="-1.3994637957346424e-08 -0.013751224256395767 0.04886454507234415" rpy="0 0 0"/>
    <mass value="12.899764355948896"/>
    <inertia ixx="0.033823" iyy="0.028162" izz="0.035033" ixy="0.0" iyz="-0.000755" ixz="0.0"/>
  </inertial>
  <visual>
    <origin xyz="0 0 0" rpy="0 0 0"/>
    <geometry>
      <mesh filename="file://$(find Untitled_description)/meshes/base_link.stl" scale="0.001 0.001 0.001"/>
    </geometry>
    <material name="silver"/>
  </visual>
  <collision>
    <origin xyz="0 0 0" rpy="0 0 0"/>
    <geometry>
      <mesh filename="file://$(find Untitled_description)/meshes/base_link.stl" scale="0.001 0.001 0.001"/>
    </geometry>
  </collision>
</link>

<link name="link1_1">
  <inertial>
    <origin xyz="0.006896766224730375 5.686419288763629e-16 0.055490186869056476" rpy="0 0 0"/>
    <mass value="3.4735206294395446"/>
    <inertia ixx="0.004461" iyy="0.004757" izz="0.002424" ixy="-0.0" iyz="-0.0" ixz="-0.000777"/>
  </inertial>
  <visual>
    <origin xyz="-0.0 -0.0 -0.11" rpy="0 0 0"/>
    <geometry>
      <mesh filename="file://$(find Untitled_description)/meshes/link1_1.stl" scale="0.001 0.001 0.001"/>
    </geometry>
    <material name="silver"/>
  </visual>
  <collision>
    <origin xyz="-0.0 -0.0 -0.11" rpy="0 0 0"/>
    <geometry>
      <mesh filename="file://$(find Untitled_description)/meshes/link1_1.stl" scale="0.001 0.001 0.001"/>
    </geometry>
  </collision>
</link>

<link name="gripper_base_1">
  <inertial>
    <origin xyz="0.03556644115575926 -0.0001756689512086883 0.008326791965623942" rpy="0 0 0"/>
    <mass value="0.5510952365655617"/>
    <inertia ixx="0.000508" iyy="0.00049" izz="0.000702" ixy="0.0" iyz="0.0" ixz="-0.000104"/>
  </inertial>
  <visual>
    <origin xyz="-0.045 -0.0 -0.195" rpy="0 0 0"/>
    <geometry>
      <mesh filename="file://$(find Untitled_description)/meshes/gripper_base_1.stl" scale="0.001 0.001 0.001"/>
    </geometry>
    <material name="silver"/>
  </visual>
  <collision>
    <origin xyz="-0.045 -0.0 -0.195" rpy="0 0 0"/>
    <geometry>
      <mesh filename="file://$(find Untitled_description)/meshes/gripper_base_1.stl" scale="0.001 0.001 0.001"/>
    </geometry>
  </collision>
</link>

<joint name="Revolute 1" type="revolute">
  <origin xyz="0.0 0.0 0.11" rpy="0 0 0"/>
  <parent link="base_link"/>
  <child link="link1_1"/>
  <axis xyz="0.0 0.0 1.0"/>
  <limit upper="6.283185" lower="0.0" effort="100" velocity="100"/>
</joint>

<joint name="Revolute 2" type="revolute">
  <origin xyz="0.045 0.0 0.085" rpy="0 0 0"/>
  <parent link="link1_1"/>
  <child link="gripper_base_1"/>
  <axis xyz="1.0 -0.0 0.0"/>
  <limit upper="6.283185" lower="0.0" effort="100" velocity="100"/>
</joint>

</robot>
