<?xml version="1.0" ?>
<robot name="mycobot320_4_1" xmlns:xacro="http://www.ros.org/wiki/xacro">

<xacro:include filename="$(find mycobot320_4_1_description)/urdf/materials.xacro" />
<xacro:include filename="$(find mycobot320_4_1_description)/urdf/mycobot320_4_1.trans" />
<xacro:include filename="$(find mycobot320_4_1_description)/urdf/mycobot320_4_1.gazebo" />
<link name="base_link">
  <inertial>
    <origin xyz="-1.3994637957346424e-08 0.046320428630226694 0.053625500753973876" rpy="0 0 0"/>
    <mass value="12.899764355948896"/>
    <inertia ixx="0.033823" iyy="0.028162" izz="0.035033" ixy="0.0" iyz="-0.000755" ixz="0.0"/>
  </inertial>
  <visual>
    <origin xyz="0 0 0" rpy="0 0 0"/>
    <geometry>
      <mesh filename="file://$(find mycobot320_4_1_description)/meshes/base_link.stl" scale="0.001 0.001 0.001"/>
    </geometry>
    <material name="silver"/>
  </visual>
  <collision>
    <origin xyz="0 0 0" rpy="0 0 0"/>
    <geometry>
      <mesh filename="file://$(find mycobot320_4_1_description)/meshes/base_link.stl" scale="0.001 0.001 0.001"/>
    </geometry>
  </collision>
</link>

<link name="link1_1">
  <inertial>
    <origin xyz="0.006896766224730391 -3.4711337727755254e-07 0.05549014255068621" rpy="0 0 0"/>
    <mass value="3.4735206294395446"/>
    <inertia ixx="0.004461" iyy="0.004757" izz="0.002424" ixy="0.0" iyz="0.0" ixz="-0.000777"/>
  </inertial>
  <visual>
    <origin xyz="0.0 -0.060072 -0.114761" rpy="0 0 0"/>
    <geometry>
      <mesh filename="file://$(find mycobot320_4_1_description)/meshes/link1_1.stl" scale="0.001 0.001 0.001"/>
    </geometry>
    <material name="silver"/>
  </visual>
  <collision>
    <origin xyz="0.0 -0.060072 -0.114761" rpy="0 0 0"/>
    <geometry>
      <mesh filename="file://$(find mycobot320_4_1_description)/meshes/link1_1.stl" scale="0.001 0.001 0.001"/>
    </geometry>
  </collision>
</link>

<link name="link2_1">
  <inertial>
    <origin xyz="0.03690658575567238 -3.4711337713183577e-07 0.06799995568162978" rpy="0 0 0"/>
    <mass value="5.91988968680626"/>
    <inertia ixx="0.0188" iyy="0.019335" izz="0.004161" ixy="0.0" iyz="0.0" ixz="0.0"/>
  </inertial>
  <visual>
    <origin xyz="-0.045 -0.060072 -0.199761" rpy="0 0 0"/>
    <geometry>
      <mesh filename="file://$(find mycobot320_4_1_description)/meshes/link2_1.stl" scale="0.001 0.001 0.001"/>
    </geometry>
    <material name="silver"/>
  </visual>
  <collision>
    <origin xyz="-0.045 -0.060072 -0.199761" rpy="0 0 0"/>
    <geometry>
      <mesh filename="file://$(find mycobot320_4_1_description)/meshes/link2_1.stl" scale="0.001 0.001 0.001"/>
    </geometry>
  </collision>
</link>

<link name="link3_1">
  <inertial>
    <origin xyz="-0.03502268825299208 -3.4711337702081346e-07 0.049499955681629404" rpy="0 0 0"/>
    <mass value="4.802107093668197"/>
    <inertia ixx="0.01014" iyy="0.010584" izz="0.003386" ixy="0.0" iyz="-0.0" ixz="0.0"/>
  </inertial>
  <visual>
    <origin xyz="-0.045 -0.060072 -0.335761" rpy="0 0 0"/>
    <geometry>
      <mesh filename="file://$(find mycobot320_4_1_description)/meshes/link3_1.stl" scale="0.001 0.001 0.001"/>
    </geometry>
    <material name="silver"/>
  </visual>
  <collision>
    <origin xyz="-0.045 -0.060072 -0.335761" rpy="0 0 0"/>
    <geometry>
      <mesh filename="file://$(find mycobot320_4_1_description)/meshes/link3_1.stl" scale="0.001 0.001 0.001"/>
    </geometry>
  </collision>
</link>

<link name="link4_1">
  <inertial>
    <origin xyz="0.03442387286919234 -3.4711337690979116e-07 0.010576082812437049" rpy="0 0 0"/>
    <mass value="2.265107015236222"/>
    <inertia ixx="0.001595" iyy="0.001803" izz="0.001595" ixy="0.0" iyz="0.0" ixz="-0.000324"/>
  </inertial>
  <visual>
    <origin xyz="-0.045 -0.060072 -0.434761" rpy="0 0 0"/>
    <geometry>
      <mesh filename="file://$(find mycobot320_4_1_description)/meshes/link4_1.stl" scale="0.001 0.001 0.001"/>
    </geometry>
    <material name="silver"/>
  </visual>
  <collision>
    <origin xyz="-0.045 -0.060072 -0.434761" rpy="0 0 0"/>
    <geometry>
      <mesh filename="file://$(find mycobot320_4_1_description)/meshes/link4_1.stl" scale="0.001 0.001 0.001"/>
    </geometry>
  </collision>
</link>

<link name="link5_1">
  <inertial>
    <origin xyz="6.938893903907228e-17 -3.4711337680570775e-07 0.04211665218776295" rpy="0 0 0"/>
    <mass value="3.029827579494103"/>
    <inertia ixx="0.0025" iyy="0.002976" izz="0.002441" ixy="0.0" iyz="-0.0" ixz="-0.0"/>
  </inertial>
  <visual>
    <origin xyz="-0.09 -0.060072 -0.479761" rpy="0 0 0"/>
    <geometry>
      <mesh filename="file://$(find mycobot320_4_1_description)/meshes/link5_1.stl" scale="0.001 0.001 0.001"/>
    </geometry>
    <material name="silver"/>
  </visual>
  <collision>
    <origin xyz="-0.09 -0.060072 -0.479761" rpy="0 0 0"/>
    <geometry>
      <mesh filename="file://$(find mycobot320_4_1_description)/meshes/link5_1.stl" scale="0.001 0.001 0.001"/>
    </geometry>
  </collision>
</link>

<link name="link6_1">
  <inertial>
    <origin xyz="0.010000000000000092 -3.471133767779522e-07 -4.4318370751028624e-08" rpy="0 0 0"/>
    <mass value="0.6042068071016569"/>
    <inertia ixx="0.00037" iyy="0.000205" izz="0.000205" ixy="0.0" iyz="0.0" ixz="0.0"/>
  </inertial>
  <visual>
    <origin xyz="-0.13 -0.060072 -0.529761" rpy="0 0 0"/>
    <geometry>
      <mesh filename="file://$(find mycobot320_4_1_description)/meshes/link6_1.stl" scale="0.001 0.001 0.001"/>
    </geometry>
    <material name="silver"/>
  </visual>
  <collision>
    <origin xyz="-0.13 -0.060072 -0.529761" rpy="0 0 0"/>
    <geometry>
      <mesh filename="file://$(find mycobot320_4_1_description)/meshes/link6_1.stl" scale="0.001 0.001 0.001"/>
    </geometry>
  </collision>
</link>

<link name="gripper_base_1">
  <inertial>
    <origin xyz="0.041306726001161226 0.010039101961235683 0.00013392992011007632" rpy="0 0 0"/>
    <mass value="1.1675247554260415"/>
    <inertia ixx="0.000959" iyy="0.001223" izz="0.000961" ixy="-6.1e-05" iyz="0.0" ixz="1e-06"/>
  </inertial>
  <visual>
    <origin xyz="-0.15 -0.060072 -0.529761" rpy="0 0 0"/>
    <geometry>
      <mesh filename="file://$(find mycobot320_4_1_description)/meshes/gripper_base_1.stl" scale="0.001 0.001 0.001"/>
    </geometry>
    <material name="silver"/>
  </visual>
  <collision>
    <origin xyz="-0.15 -0.060072 -0.529761" rpy="0 0 0"/>
    <geometry>
      <mesh filename="file://$(find mycobot320_4_1_description)/meshes/gripper_base_1.stl" scale="0.001 0.001 0.001"/>
    </geometry>
  </collision>
</link>

<link name="gripper_right3_1">
  <inertial>
    <origin xyz="0.01682206601696873 0.00335582736569906 -0.0021746647091124283" rpy="0 0 0"/>
    <mass value="0.10050498552342498"/>
    <inertia ixx="9e-06" iyy="5.8e-05" izz="5e-05" ixy="0.0" iyz="-0.0" ixz="3e-06"/>
  </inertial>
  <visual>
    <origin xyz="-0.2105 -0.04963 -0.548081" rpy="0 0 0"/>
    <geometry>
      <mesh filename="file://$(find mycobot320_4_1_description)/meshes/gripper_right3_1.stl" scale="0.001 0.001 0.001"/>
    </geometry>
    <material name="silver"/>
  </visual>
  <collision>
    <origin xyz="-0.2105 -0.04963 -0.548081" rpy="0 0 0"/>
    <geometry>
      <mesh filename="file://$(find mycobot320_4_1_description)/meshes/gripper_right3_1.stl" scale="0.001 0.001 0.001"/>
    </geometry>
  </collision>
</link>

<link name="gripper_right1_1">
  <inertial>
    <origin xyz="0.011330865088985731 0.00360442986900944 0.0053353465910587206" rpy="0 0 0"/>
    <mass value="0.09174561050455735"/>
    <inertia ixx="1e-05" iyy="4.1e-05" izz="3.4e-05" ixy="-0.0" iyz="0.0" ixz="1.3e-05"/>
  </inertial>
  <visual>
    <origin xyz="-0.269528 -0.049488 -0.538964" rpy="0 0 0"/>
    <geometry>
      <mesh filename="file://$(find mycobot320_4_1_description)/meshes/gripper_right1_1.stl" scale="0.001 0.001 0.001"/>
    </geometry>
    <material name="silver"/>
  </visual>
  <collision>
    <origin xyz="-0.269528 -0.049488 -0.538964" rpy="0 0 0"/>
    <geometry>
      <mesh filename="file://$(find mycobot320_4_1_description)/meshes/gripper_right1_1.stl" scale="0.001 0.001 0.001"/>
    </geometry>
  </collision>
</link>

<link name="gripper_right2_1">
  <inertial>
    <origin xyz="0.03926434688841765 -0.00014562201615665044 -0.00442944319501648" rpy="0 0 0"/>
    <mass value="0.05677395700664818"/>
    <inertia ixx="3e-06" iyy="2e-05" izz="1.9e-05" ixy="2e-06" iyz="-0.0" ixz="4e-06"/>
  </inertial>
  <visual>
    <origin xyz="-0.188135 -0.06243 -0.574153" rpy="0 0 0"/>
    <geometry>
      <mesh filename="file://$(find mycobot320_4_1_description)/meshes/gripper_right2_1.stl" scale="0.001 0.001 0.001"/>
    </geometry>
    <material name="silver"/>
  </visual>
  <collision>
    <origin xyz="-0.188135 -0.06243 -0.574153" rpy="0 0 0"/>
    <geometry>
      <mesh filename="file://$(find mycobot320_4_1_description)/meshes/gripper_right2_1.stl" scale="0.001 0.001 0.001"/>
    </geometry>
  </collision>
</link>

<joint name="joint2_to_joint1" type="continuous">
  <origin xyz="0.0 0.060072 0.114761" rpy="0 0 0"/>
  <parent link="base_link"/>
  <child link="link1_1"/>
  <axis xyz="-0.0 0.0 1.0"/>
</joint>

<joint name="joint3_to_joint2" type="continuous">
  <origin xyz="0.045 0.0 0.085" rpy="0 0 0"/>
  <parent link="link1_1"/>
  <child link="link2_1"/>
  <axis xyz="1.0 -0.0 0.0"/>
</joint>

<joint name="joint4_to_joint3" type="continuous">
  <origin xyz="0.0 0.0 0.136" rpy="0 0 0"/>
  <parent link="link2_1"/>
  <child link="link3_1"/>
  <axis xyz="-1.0 0.0 -0.0"/>
</joint>

<joint name="joint5_to_joint4" type="continuous">
  <origin xyz="0.0 0.0 0.099" rpy="0 0 0"/>
  <parent link="link3_1"/>
  <child link="link4_1"/>
  <axis xyz="1.0 0.0 0.0"/>
</joint>

<joint name="joint6_to_joint5" type="continuous">
  <origin xyz="0.045 0.0 0.045" rpy="0 0 0"/>
  <parent link="link4_1"/>
  <child link="link5_1"/>
  <axis xyz="0.0 0.0 1.0"/>
</joint>

<joint name="joint6output_to_joint6" type="continuous">
  <origin xyz="0.04 0.0 0.05" rpy="0 0 0"/>
  <parent link="link5_1"/>
  <child link="link6_1"/>
  <axis xyz="1.0 -0.0 0.0"/>
</joint>

<joint name="joint6output_to_gripper_base" type="fixed">
  <origin xyz="0.02 0.0 0.0" rpy="0 0 0"/>
  <parent link="link6_1"/>
  <child link="gripper_base_1"/>
</joint>

<joint name="gripper_controller" type="revolute">
  <origin xyz="0.0605 -0.010442 0.01832" rpy="0 0 0"/>
  <parent link="gripper_base_1"/>
  <child link="gripper_right3_1"/>
  <axis xyz="-0.0 -1.0 0.0"/>
  <limit upper="0.698132" lower="0.0" effort="100" velocity="100"/>
  <mimic joint="gripper_controller" multiplier="1.0" offset="0" />
</joint>

<joint name="gripper_right3_to_gripper_right1" type="continuous">
  <origin xyz="0.059028 -0.000142 -0.009117" rpy="0 0 0"/>
  <parent link="gripper_right3_1"/>
  <child link="gripper_right1_1"/>
  <axis xyz="0.0 -1.0 0.0"/>
  <mimic joint="gripper_controller" multiplier="1.0" offset="0" />
</joint>

<joint name="gripper_base_to_gripper_right2" type="continuous">
  <origin xyz="0.038135 0.002358 0.044392" rpy="0 0 0"/>
  <parent link="gripper_base_1"/>
  <child link="gripper_right2_1"/>
  <axis xyz="0.0 1.0 -0.0"/>
  <mimic joint="gripper_controller" multiplier="-1.0" offset="0" />
</joint>

</robot>
